Workbook

Sheet Start Here
A1: Annual Planning Workbook
A3: How to fill it in (in this order)
A4: 1. Settings | B4: Plan year, focus factor, holidays, and the dropdown lists (roles, statuses, categories).
A5: 2. Objectives | B5: 3–5 objectives for the year with a measurable key result each.
A6: 3. Projects | B6: One row per initiative: objective, priority, size, dates, owners. Effort & labor cost auto-fill.
A7: 4. Team | B7: Everyone supplying capacity, incl. contractors and Open Req placeholders with start dates.
A8: 5. Allocation | B8: Person × project × month as a fraction of their time. This is the heart of resource planning.
A9: 6. Milestones / RAID | B9: Committed dates, decision gates, risks and dependencies.
A10: 7. Review | B10: Dashboard → gaps & over-allocation; Capacity → who's red; Roadmap → sequencing.
A12: Colour legend
A13: Yellow cell, blue text | B13: Input — type here.
A14: Grey cell | B14: Formula — don't overwrite.
A15: Green text | B15: Pulled from another tab.
A17: Planning tips
A18: Plan to ~85% not 100% | B18: The focus factor reserves time for support, meetings and unplanned work.
A19: Use Open Req rows | B19: Plan the work first; the role gap on the Dashboard becomes your hiring ask.
A20: Rank, don't just tag | B20: If demand > capacity, cut from the bottom of P3/P4 — make the trade-off visible in the meeting.
A21: Quarterly re-plan | B21: Re-forecast Allocation each quarter; keep the yearly view as the baseline copy.
A23: Power BI
A24: Data source | B24: Get Data → Excel → pick tables tblProjects, tblTeam, tblAllocation, tblMilestones, tblRAID, tblObjectives.
A25: Allocation months | B25: In Power Query select Jan–Dec on tblAllocation → Unpivot Columns → gives Month/Allocation rows.
A26: Blank rows | B26: Filter each table on its ID/Name column ≠ blank (template rows are pre-built).
A27: Relationships | B27: tblProjects[ID] → tblAllocation[Project ID], tblMilestones, tblRAID; tblTeam[Name] → tblAllocation[Resource].
A29: Sample data | B29: All rows are illustrative examples — overwrite or delete them (keep the formula columns).

Sheet Dashboard
A1: Plan Summary
A2: ="Plan year "&Settings!B3&" • all effort in FTE-months (1 = one person for one month)" -> Plan year 2027 • all effort in FTE-months (1 = one person for one month)
A4: Active projects | B4: P1 projects | C4: Demand (FTE-mo) | D4: Staffed capacity | E4: Open-req capacity | F4: Gap (staffed − demand) | G4: People >100% in any month | H4: Open high risks | I4: Total budget
A5: =COUNTIFS(Projects!A5:A54,"<>",Projects!K5:K54,"<>Cancelled") -> 3 | B5: =COUNTIFS(Projects!E5:E54,"P1",Projects!K5:K54,"<>Cancelled") -> 1 | C5: =SUM(Allocation!Q5:Q204) -> 52.2 | D5: =SUMIFS(Capacity!P70:P129,Capacity!C70:C129,"<>Open Req") -> 49.312212 | E5: =SUMIFS(Capacity!P70:P129,Capacity!C70:C129,"Open Req") -> 7.1964827 | F5: =D5-C5 -> -2.8877877 | G5: =COUNTIF(Capacity!P6:P65,">1.0001") -> 6 | H5: =COUNTIFS(RAID!H5:H104,"High",RAID!L5:L104,"<>Closed") -> 0 | I5: =SUM(Projects!P5:P54) -> 706800
A7: Capacity vs demand by month
A8: Month | B8: Staffed capacity | C8: Open-req capacity | D8: Demand | E8: Gap (staffed − demand) | F8: Team utilization
A9: =Settings!A8 -> 46388 | B9: =SUMIFS(Capacity!D$70:D$129,Capacity!$C$70:$C$129,"<>Open Req") -> 4.0868421 | C9: =SUMIFS(Capacity!D$70:D$129,Capacity!$C$70:$C$129,"Open Req") -> 0 | D9: =SUM(Allocation!E$5:E$204) -> 3.7 | E9: =B9-D9 -> 0.38684211 | F9: =IF(B9+C9=0,"",D9/(B9+C9)) -> 0.90534449
A10: =Settings!A9 -> 46419 | B10: =SUMIFS(Capacity!E$70:E$129,Capacity!$C$70:$C$129,"<>Open Req") -> 4.0868421 | C10: =SUMIFS(Capacity!E$70:E$129,Capacity!$C$70:$C$129,"Open Req") -> 0 | D10: =SUM(Allocation!F$5:F$204) -> 3.7 | E10: =B10-D10 -> 0.38684211 | F10: =IF(B10+C10=0,"",D10/(B10+C10)) -> 0.90534449
A11: =Settings!A10 -> 46447 | B11: =SUMIFS(Capacity!F$70:F$129,Capacity!$C$70:$C$129,"<>Open Req") -> 4.1227273 | C11: =SUMIFS(Capacity!F$70:F$129,Capacity!$C$70:$C$129,"Open Req") -> 0 | D11: =SUM(Allocation!G$5:G$204) -> 4.6 | E11: =B11-D11 -> -0.47727273 | F11: =IF(B11+C11=0,"",D11/(B11+C11)) -> 1.1157663
A12: =Settings!A11 -> 46478 | B12: =SUMIFS(Capacity!G$70:G$129,Capacity!$C$70:$C$129,"<>Open Req") -> 4.1227273 | C12: =SUMIFS(Capacity!G$70:G$129,Capacity!$C$70:$C$129,"Open Req") -> 0.80170455 | D12: =SUM(Allocation!H$5:H$204) -> 5.4 | E12: =B12-D12 -> -1.2772727 | F12: =IF(B12+C12=0,"",D12/(B12+C12)) -> 1.0965732
A13: =Settings!A12 -> 46508 | B13: =SUMIFS(Capacity!H$70:H$129,Capacity!$C$70:$C$129,"<>Open Req") -> 4.1 | C13: =SUMIFS(Capacity!H$70:H$129,Capacity!$C$70:$C$129,"Open Req") -> 0.796875 | D13: =SUM(Allocation!I$5:I$204) -> 4.8 | E13: =B13-D13 -> -0.7 | F13: =IF(B13+C13=0,"",D13/(B13+C13)) -> 0.98021698
A14: =Settings!A13 -> 46539 | B14: =SUMIFS(Capacity!I$70:I$129,Capacity!$C$70:$C$129,"<>Open Req") -> 4.1119048 | C14: =SUMIFS(Capacity!I$70:I$129,Capacity!$C$70:$C$129,"Open Req") -> 0.79940476 | D14: =SUM(Allocation!J$5:J$204) -> 4.8 | E14: =B14-D14 -> -0.68809524 | F14: =IF(B14+C14=0,"",D14/(B14+C14)) -> 0.97733608
A15: =Settings!A14 -> 46569 | B15: =SUMIFS(Capacity!J$70:J$129,Capacity!$C$70:$C$129,"<>Open Req") -> 4.1119048 | C15: =SUMIFS(Capacity!J$70:J$129,Capacity!$C$70:$C$129,"Open Req") -> 0.79940476 | D15: =SUM(Allocation!K$5:K$204) -> 4.8 | E15: =B15-D15 -> -0.68809524 | F15: =IF(B15+C15=0,"",D15/(B15+C15)) -> 0.97733608
A16: =Settings!A15 -> 46600 | B16: =SUMIFS(Capacity!K$70:K$129,Capacity!$C$70:$C$129,"<>Open Req") -> 4.1227273 | C16: =SUMIFS(Capacity!K$70:K$129,Capacity!$C$70:$C$129,"Open Req") -> 0.80170455 | D16: =SUM(Allocation!L$5:L$204) -> 4.8 | E16: =B16-D16 -> -0.67727273 | F16: =IF(B16+C16=0,"",D16/(B16+C16)) -> 0.97473174
A17: =Settings!A16 -> 46631 | B17: =SUMIFS(Capacity!L$70:L$129,Capacity!$C$70:$C$129,"<>Open Req") -> 4.1119048 | C17: =SUMIFS(Capacity!L$70:L$129,Capacity!$C$70:$C$129,"Open Req") -> 0.79940476 | D17: =SUM(Allocation!M$5:M$204) -> 3.9 | E17: =B17-D17 -> 0.21190476 | F17: =IF(B17+C17=0,"",D17/(B17+C17)) -> 0.79408557
A18: =Settings!A17 -> 46661 | B18: =SUMIFS(Capacity!M$70:M$129,Capacity!$C$70:$C$129,"<>Open Req") -> 4.1119048 | C18: =SUMIFS(Capacity!M$70:M$129,Capacity!$C$70:$C$129,"Open Req") -> 0.79940476 | D18: =SUM(Allocation!N$5:N$204) -> 3.9 | E18: =B18-D18 -> 0.21190476 | F18: =IF(B18+C18=0,"",D18/(B18+C18)) -> 0.79408557
A19: =Settings!A18 -> 46692 | B19: =SUMIFS(Capacity!N$70:N$129,Capacity!$C$70:$C$129,"<>Open Req") -> 4.1 | C19: =SUMIFS(Capacity!N$70:N$129,Capacity!$C$70:$C$129,"Open Req") -> 0.796875 | D19: =SUM(Allocation!O$5:O$204) -> 3.9 | E19: =B19-D19 -> 0.2 | F19: =IF(B19+C19=0,"",D19/(B19+C19)) -> 0.79642629
A20: =Settings!A19 -> 46722 | B20: =SUMIFS(Capacity!O$70:O$129,Capacity!$C$70:$C$129,"<>Open Req") -> 4.1227273 | C20: =SUMIFS(Capacity!O$70:O$129,Capacity!$C$70:$C$129,"Open Req") -> 0.80170455 | D20: =SUM(Allocation!P$5:P$204) -> 3.9 | E20: =B20-D20 -> 0.22272727 | F20: =IF(B20+C20=0,"",D20/(B20+C20)) -> 0.79196954
A21: Total | B21: =SUM(B9:B20) -> 49.312212 | C21: =SUM(C9:C20) -> 7.1964827 | D21: =SUM(D9:D20) -> 52.2 | E21: =SUM(E9:E20) -> -2.8877877 | F21: =IF(B21+C21=0,"",D21/(B21+C21)) -> 0.92375165
A24: Supply vs demand by role (annual FTE-months)
A25: Role | B25: Staffed supply | C25: Open-req supply | D25: Demand | E25: Gap (staffed − demand)
A26: =IF(Settings!N8="","",Settings!N8) -> Engineering Manager | B26: =IF(A26="","",SUMIFS(Capacity!$P$70:$P$129,Capacity!$B$70:$B$129,A26,Capacity!$C$70:$C$129,"<>Open Req")) -> 0 | C26: =IF(A26="","",SUMIFS(Capacity!$P$70:$P$129,Capacity!$B$70:$B$129,A26,Capacity!$C$70:$C$129,"Open Req")) -> 0 | D26: =IF(A26="","",SUMIFS(Allocation!$Q$5:$Q$204,Allocation!$B$5:$B$204,A26)) -> 0 | E26: =IF(A26="","",B26-D26) -> 0
A27: =IF(Settings!N9="","",Settings!N9) -> Tech Lead | B27: =IF(A27="","",SUMIFS(Capacity!$P$70:$P$129,Capacity!$B$70:$B$129,A27,Capacity!$C$70:$C$129,"<>Open Req")) -> 8.8299233 | C27: =IF(A27="","",SUMIFS(Capacity!$P$70:$P$129,Capacity!$B$70:$B$129,A27,Capacity!$C$70:$C$129,"Open Req")) -> 0 | D27: =IF(A27="","",SUMIFS(Allocation!$Q$5:$Q$204,Allocation!$B$5:$B$204,A27)) -> 9.2 | E27: =IF(A27="","",B27-D27) -> -0.37007671
A28: =IF(Settings!N10="","",Settings!N10) -> Architect | B28: =IF(A28="","",SUMIFS(Capacity!$P$70:$P$129,Capacity!$B$70:$B$129,A28,Capacity!$C$70:$C$129,"<>Open Req")) -> 0 | C28: =IF(A28="","",SUMIFS(Capacity!$P$70:$P$129,Capacity!$B$70:$B$129,A28,Capacity!$C$70:$C$129,"Open Req")) -> 0 | D28: =IF(A28="","",SUMIFS(Allocation!$Q$5:$Q$204,Allocation!$B$5:$B$204,A28)) -> 0 | E28: =IF(A28="","",B28-D28) -> 0
A29: =IF(Settings!N11="","",Settings!N11) -> Backend Developer | B29: =IF(A29="","",SUMIFS(Capacity!$P$70:$P$129,Capacity!$B$70:$B$129,A29,Capacity!$C$70:$C$129,"<>Open Req")) -> 9.3817935 | C29: =IF(A29="","",SUMIFS(Capacity!$P$70:$P$129,Capacity!$B$70:$B$129,A29,Capacity!$C$70:$C$129,"Open Req")) -> 0 | D29: =IF(A29="","",SUMIFS(Allocation!$Q$5:$Q$204,Allocation!$B$5:$B$204,A29)) -> 8.4 | E29: =IF(A29="","",B29-D29) -> 0.9817935
A30: =IF(Settings!N12="","",Settings!N12) -> Frontend Developer | B30: =IF(A30="","",SUMIFS(Capacity!$P$70:$P$129,Capacity!$B$70:$B$129,A30,Capacity!$C$70:$C$129,"<>Open Req")) -> 10.366832 | C30: =IF(A30="","",SUMIFS(Capacity!$P$70:$P$129,Capacity!$B$70:$B$129,A30,Capacity!$C$70:$C$129,"Open Req")) -> 7.1964827 | D30: =IF(A30="","",SUMIFS(Allocation!$Q$5:$Q$204,Allocation!$B$5:$B$204,A30)) -> 18 | E30: =IF(A30="","",B30-D30) -> -7.6331681
A31: =IF(Settings!N13="","",Settings!N13) -> Full-stack Developer | B31: =IF(A31="","",SUMIFS(Capacity!$P$70:$P$129,Capacity!$B$70:$B$129,A31,Capacity!$C$70:$C$129,"<>Open Req")) -> 10.366832 | C31: =IF(A31="","",SUMIFS(Capacity!$P$70:$P$129,Capacity!$B$70:$B$129,A31,Capacity!$C$70:$C$129,"Open Req")) -> 0 | D31: =IF(A31="","",SUMIFS(Allocation!$Q$5:$Q$204,Allocation!$B$5:$B$204,A31)) -> 7.6 | E31: =IF(A31="","",B31-D31) -> 2.7668319
A32: =IF(Settings!N14="","",Settings!N14) -> QA / SDET | B32: =IF(A32="","",SUMIFS(Capacity!$P$70:$P$129,Capacity!$B$70:$B$129,A32,Capacity!$C$70:$C$129,"<>Open Req")) -> 10.366832 | C32: =IF(A32="","",SUMIFS(Capacity!$P$70:$P$129,Capacity!$B$70:$B$129,A32,Capacity!$C$70:$C$129,"Open Req")) -> 0 | D32: =IF(A32="","",SUMIFS(Allocation!$Q$5:$Q$204,Allocation!$B$5:$B$204,A32)) -> 9 | E32: =IF(A32="","",B32-D32) -> 1.3668319
A33: =IF(Settings!N15="","",Settings!N15) -> DevOps / SRE | B33: =IF(A33="","",SUMIFS(Capacity!$P$70:$P$129,Capacity!$B$70:$B$129,A33,Capacity!$C$70:$C$129,"<>Open Req")) -> 0 | C33: =IF(A33="","",SUMIFS(Capacity!$P$70:$P$129,Capacity!$B$70:$B$129,A33,Capacity!$C$70:$C$129,"Open Req")) -> 0 | D33: =IF(A33="","",SUMIFS(Allocation!$Q$5:$Q$204,Allocation!$B$5:$B$204,A33)) -> 0 | E33: =IF(A33="","",B33-D33) -> 0
A34: =IF(Settings!N16="","",Settings!N16) -> Business Analyst | B34: =IF(A34="","",SUMIFS(Capacity!$P$70:$P$129,Capacity!$B$70:$B$129,A34,Capacity!$C$70:$C$129,"<>Open Req")) -> 0 | C34: =IF(A34="","",SUMIFS(Capacity!$P$70:$P$129,Capacity!$B$70:$B$129,A34,Capacity!$C$70:$C$129,"Open Req")) -> 0 | D34: =IF(A34="","",SUMIFS(Allocation!$Q$5:$Q$204,Allocation!$B$5:$B$204,A34)) -> 0 | E34: =IF(A34="","",B34-D34) -> 0
A35: =IF(Settings!N17="","",Settings!N17) -> Product Owner | B35: =IF(A35="","",SUMIFS(Capacity!$P$70:$P$129,Capacity!$B$70:$B$129,A35,Capacity!$C$70:$C$129,"<>Open Req")) -> 0 | C35: =IF(A35="","",SUMIFS(Capacity!$P$70:$P$129,Capacity!$B$70:$B$129,A35,Capacity!$C$70:$C$129,"Open Req")) -> 0 | D35: =IF(A35="","",SUMIFS(Allocation!$Q$5:$Q$204,Allocation!$B$5:$B$204,A35)) -> 0 | E35: =IF(A35="","",B35-D35) -> 0
A36: =IF(Settings!N18="","",Settings!N18) -> Scrum Master | B36: =IF(A36="","",SUMIFS(Capacity!$P$70:$P$129,Capacity!$B$70:$B$129,A36,Capacity!$C$70:$C$129,"<>Open Req")) -> 0 | C36: =IF(A36="","",SUMIFS(Capacity!$P$70:$P$129,Capacity!$B$70:$B$129,A36,Capacity!$C$70:$C$129,"Open Req")) -> 0 | D36: =IF(A36="","",SUMIFS(Allocation!$Q$5:$Q$204,Allocation!$B$5:$B$204,A36)) -> 0 | E36: =IF(A36="","",B36-D36) -> 0
A37: =IF(Settings!N19="","",Settings!N19) -> UX Designer | B37: =IF(A37="","",SUMIFS(Capacity!$P$70:$P$129,Capacity!$B$70:$B$129,A37,Capacity!$C$70:$C$129,"<>Open Req")) -> 0 | C37: =IF(A37="","",SUMIFS(Capacity!$P$70:$P$129,Capacity!$B$70:$B$129,A37,Capacity!$C$70:$C$129,"Open Req")) -> 0 | D37: =IF(A37="","",SUMIFS(Allocation!$Q$5:$Q$204,Allocation!$B$5:$B$204,A37)) -> 0 | E37: =IF(A37="","",B37-D37) -> 0
A40: Portfolio mix by category
A41: Category | B41: # Projects | C41: FTE-months | D41: % of demand | F41: Status | G41: # Projects
A42: =Settings!J8 -> Run / KTLO | B42: =COUNTIFS(Projects!$D$5:$D$54,A42,Projects!$K$5:$K$54,"<>Cancelled") -> 1 | C42: =SUMIFS(Projects!$M$5:$M$54,Projects!$D$5:$D$54,A42) -> 2.4 | D42: =IF($C$5=0,"",C42/$C$5) -> 0.045977011 | F42: =Settings!H8 -> Proposed | G42: =COUNTIFS(Projects!$K$5:$K$54,F42,Projects!$A$5:$A$54,"<>") -> 1
A43: =Settings!J9 -> Grow | B43: =COUNTIFS(Projects!$D$5:$D$54,A43,Projects!$K$5:$K$54,"<>Cancelled") -> 1 | C43: =SUMIFS(Projects!$M$5:$M$54,Projects!$D$5:$D$54,A43) -> 5.4 | D43: =IF($C$5=0,"",C43/$C$5) -> 0.10344828 | F43: =Settings!H9 -> Approved | G43: =COUNTIFS(Projects!$K$5:$K$54,F43,Projects!$A$5:$A$54,"<>") -> 1
A44: =Settings!J10 -> Transform | B44: =COUNTIFS(Projects!$D$5:$D$54,A44,Projects!$K$5:$K$54,"<>Cancelled") -> 1 | C44: =SUMIFS(Projects!$M$5:$M$54,Projects!$D$5:$D$54,A44) -> 44.4 | D44: =IF($C$5=0,"",C44/$C$5) -> 0.85057471 | F44: =Settings!H10 -> In Progress | G44: =COUNTIFS(Projects!$K$5:$K$54,F44,Projects!$A$5:$A$54,"<>") -> 1
A45: =Settings!J11 -> Compliance / Risk | B45: =COUNTIFS(Projects!$D$5:$D$54,A45,Projects!$K$5:$K$54,"<>Cancelled") -> 0 | C45: =SUMIFS(Projects!$M$5:$M$54,Projects!$D$5:$D$54,A45) -> 0 | D45: =IF($C$5=0,"",C45/$C$5) -> 0 | F45: =Settings!H11 -> On Hold | G45: =COUNTIFS(Projects!$K$5:$K$54,F45,Projects!$A$5:$A$54,"<>") -> 0
A46: =Settings!J12 -> Tech Debt | B46: =COUNTIFS(Projects!$D$5:$D$54,A46,Projects!$K$5:$K$54,"<>Cancelled") -> 0 | C46: =SUMIFS(Projects!$M$5:$M$54,Projects!$D$5:$D$54,A46) -> 0 | D46: =IF($C$5=0,"",C46/$C$5) -> 0 | F46: =Settings!H12 -> Done | G46: =COUNTIFS(Projects!$K$5:$K$54,F46,Projects!$A$5:$A$54,"<>") -> 0
...

Sheet Objectives
A1: Objectives & Key Results
A2: What the year is for. Every project should ladder up to one objective.
A4: Obj ID | B4: Objective | C4: Key Result | D4: Target | E4: Owner | F4: # Projects | G4: Planned FTE-months
A5: O1 | B5: Modernize legacy platforms | C5: Legacy JSP/Struts screens retired | D5: 60% | E5: Siva | F5: =IF(A5="","",COUNTIF(Projects!$C$5:$C$54,A5)) -> 1 | G5: =IF(A5="","",SUMIFS(Projects!$M$5:$M$54,Projects!$C$5:$C$54,A5)) -> 44.4
A6: O2 | B6: Improve reliability & operational visibility | C6: Reduction in P1/P2 incidents YoY | D6: 30% | E6: Siva | F6: =IF(A6="","",COUNTIF(Projects!$C$5:$C$54,A6)) -> 2 | G6: =IF(A6="","",SUMIFS(Projects!$M$5:$M$54,Projects!$C$5:$C$54,A6)) -> 7.8
A7: O3 | B7: Deliver priority business features | C7: Roadmap commitments shipped on time | D7: 90% | F7: =IF(A7="","",COUNTIF(Projects!$C$5:$C$54,A7)) -> 0 | G7: =IF(A7="","",SUMIFS(Projects!$M$5:$M$54,Projects!$C$5:$C$54,A7)) -> 0
F8: =IF(A8="","",COUNTIF(Projects!$C$5:$C$54,A8)) | G8: =IF(A8="","",SUMIFS(Projects!$M$5:$M$54,Projects!$C$5:$C$54,A8))
F9: =IF(A9="","",COUNTIF(Projects!$C$5:$C$54,A9)) | G9: =IF(A9="","",SUMIFS(Projects!$M$5:$M$54,Projects!$C$5:$C$54,A9))
F10: =IF(A10="","",COUNTIF(Projects!$C$5:$C$54,A10)) | G10: =IF(A10="","",SUMIFS(Projects!$M$5:$M$54,Projects!$C$5:$C$54,A10))
F11: =IF(A11="","",COUNTIF(Projects!$C$5:$C$54,A11)) | G11: =IF(A11="","",SUMIFS(Projects!$M$5:$M$54,Projects!$C$5:$C$54,A11))
F12: =IF(A12="","",COUNTIF(Projects!$C$5:$C$54,A12)) | G12: =IF(A12="","",SUMIFS(Projects!$M$5:$M$54,Projects!$C$5:$C$54,A12))
F13: =IF(A13="","",COUNTIF(Projects!$C$5:$C$54,A13)) | G13: =IF(A13="","",SUMIFS(Projects!$M$5:$M$54,Projects!$C$5:$C$54,A13))
F14: =IF(A14="","",COUNTIF(Projects!$C$5:$C$54,A14)) | G14: =IF(A14="","",SUMIFS(Projects!$M$5:$M$54,Projects!$C$5:$C$54,A14))
F15: =IF(A15="","",COUNTIF(Projects!$C$5:$C$54,A15)) | G15: =IF(A15="","",SUMIFS(Projects!$M$5:$M$54,Projects!$C$5:$C$54,A15))
F16: =IF(A16="","",COUNTIF(Projects!$C$5:$C$54,A16)) | G16: =IF(A16="","",SUMIFS(Projects!$M$5:$M$54,Projects!$C$5:$C$54,A16))
F17: =IF(A17="","",COUNTIF(Projects!$C$5:$C$54,A17)) | G17: =IF(A17="","",SUMIFS(Projects!$M$5:$M$54,Projects!$C$5:$C$54,A17))
F18: =IF(A18="","",COUNTIF(Projects!$C$5:$C$54,A18)) | G18: =IF(A18="","",SUMIFS(Projects!$M$5:$M$54,Projects!$C$5:$C$54,A18))
F19: =IF(A19="","",COUNTIF(Projects!$C$5:$C$54,A19)) | G19: =IF(A19="","",SUMIFS(Projects!$M$5:$M$54,Projects!$C$5:$C$54,A19))
... F24: =IF(A24="","",COUNTIF(Projects!$C$5:$C$54,A24)) | G24: =IF(A24="","",SUMIFS(Projects!$M$5:$M$54,Projects!$C$5:$C$54,A24))

Sheet Projects
A1: Project Portfolio
A2: One row per project. Effort and labor cost fill in automatically from the Allocation tab. Sample rows — overwrite.
A4: ID | B4: Project | C4: Objective ID | D4: Category | E4: Priority | F4: Size | G4: Business Owner | H4: Tech Lead | I4: Start | J4: End | K4: Status | L4: RAG | M4: Planned FTE-months | N4: Labor cost | O4: Non-labor budget | P4: Total budget | Q4: Key dependencies | R4: Success measure / notes
A5: P001 | B5: RepApp Angular migration (strangler fig) | C5: O1 | D5: Transform | E5: P1 | F5: XL | H5: Tech Lead 1 | I5: 46391 | J5: 46738 | K5: In Progress | L5: Green | M5: =IF(A5="","",SUMIFS(Allocation!$Q$5:$Q$204,Allocation!$C$5:$C$204,A5)) -> 44.4 | N5: =IF(A5="","",SUMIFS(Allocation!$S$5:$S$204,Allocation!$C$5:$C$204,A5)) -> 580800 | O5: 0 | P5: =IF(A5="","",N5+O5) -> 580800 | Q5: Contractor continuity; TBH Angular dev by Apr | R5: Phase 1–2 screens live; JSP decommission decision by Nov
A6: P002 | B6: Application portfolio dashboard | C6: O2 | D6: Run / KTLO | E6: P2 | F6: M | G6: Manager peer group | H6: Tech Lead 1 | I6: 46398 | J6: 46507 | K6: Approved | L6: Amber | M6: =IF(A6="","",SUMIFS(Allocation!$Q$5:$Q$204,Allocation!$C$5:$C$204,A6)) -> 2.4 | N6: =IF(A6="","",SUMIFS(Allocation!$S$5:$S$204,Allocation!$C$5:$C$204,A6)) -> 34400 | O6: 5000 | P6: =IF(A6="","",N6+O6) -> 39400 | Q6: SNOW + Jira API access | R6: Dashboard adopted by peer managers
A7: P003 | B7: Observability & alerting uplift | C7: O2 | D7: Grow | E7: P2 | F7: M | H7: Java Dev 1 | I7: 46447 | J7: 46630 | K7: Proposed | L7: Green | M7: =IF(A7="","",SUMIFS(Allocation!$Q$5:$Q$204,Allocation!$C$5:$C$204,A7)) -> 5.4 | N7: =IF(A7="","",SUMIFS(Allocation!$S$5:$S$204,Allocation!$C$5:$C$204,A7)) -> 66600 | O7: 20000 | P7: =IF(A7="","",N7+O7) -> 86600 | Q7: Platform team logging standards | R7: Alert baseline in prod; MTTR down
M8: =IF(A8="","",SUMIFS(Allocation!$Q$5:$Q$204,Allocation!$C$5:$C$204,A8)) | N8: =IF(A8="","",SUMIFS(Allocation!$S$5:$S$204,Allocation!$C$5:$C$204,A8)) | P8: =IF(A8="","",N8+O8)
M9: =IF(A9="","",SUMIFS(Allocation!$Q$5:$Q$204,Allocation!$C$5:$C$204,A9)) | N9: =IF(A9="","",SUMIFS(Allocation!$S$5:$S$204,Allocation!$C$5:$C$204,A9)) | P9: =IF(A9="","",N9+O9)
M10: =IF(A10="","",SUMIFS(Allocation!$Q$5:$Q$204,Allocation!$C$5:$C$204,A10)) | N10: =IF(A10="","",SUMIFS(Allocation!$S$5:$S$204,Allocation!$C$5:$C$204,A10)) | P10: =IF(A10="","",N10+O10)
M11: =IF(A11="","",SUMIFS(Allocation!$Q$5:$Q$204,Allocation!$C$5:$C$204,A11)) | N11: =IF(A11="","",SUMIFS(Allocation!$S$5:$S$204,Allocation!$C$5:$C$204,A11)) | P11: =IF(A11="","",N11+O11)
M12: =IF(A12="","",SUMIFS(Allocation!$Q$5:$Q$204,Allocation!$C$5:$C$204,A12)) | N12: =IF(A12="","",SUMIFS(Allocation!$S$5:$S$204,Allocation!$C$5:$C$204,A12)) | P12: =IF(A12="","",N12+O12)
M13: =IF(A13="","",SUMIFS(Allocation!$Q$5:$Q$204,Allocation!$C$5:$C$204,A13)) | N13: =IF(A13="","",SUMIFS(Allocation!$S$5:$S$204,Allocation!$C$5:$C$204,A13)) | P13: =IF(A13="","",N13+O13)
M14: =IF(A14="","",SUMIFS(Allocation!$Q$5:$Q$204,Allocation!$C$5:$C$204,A14)) | N14: =IF(A14="","",SUMIFS(Allocation!$S$5:$S$204,Allocation!$C$5:$C$204,A14)) | P14: =IF(A14="","",N14+O14)
M15: =IF(A15="","",SUMIFS(Allocation!$Q$5:$Q$204,Allocation!$C$5:$C$204,A15)) | N15: =IF(A15="","",SUMIFS(Allocation!$S$5:$S$204,Allocation!$C$5:$C$204,A15)) | P15: =IF(A15="","",N15+O15)
M16: =IF(A16="","",SUMIFS(Allocation!$Q$5:$Q$204,Allocation!$C$5:$C$204,A16)) | N16: =IF(A16="","",SUMIFS(Allocation!$S$5:$S$204,Allocation!$C$5:$C$204,A16)) | P16: =IF(A16="","",N16+O16)
M17: =IF(A17="","",SUMIFS(Allocation!$Q$5:$Q$204,Allocation!$C$5:$C$204,A17)) | N17: =IF(A17="","",SUMIFS(Allocation!$S$5:$S$204,Allocation!$C$5:$C$204,A17)) | P17: =IF(A17="","",N17+O17)
M18: =IF(A18="","",SUMIFS(Allocation!$Q$5:$Q$204,Allocation!$C$5:$C$204,A18)) | N18: =IF(A18="","",SUMIFS(Allocation!$S$5:$S$204,Allocation!$C$5:$C$204,A18)) | P18: =IF(A18="","",N18+O18)
M19: =IF(A19="","",SUMIFS(Allocation!$Q$5:$Q$204,Allocation!$C$5:$C$204,A19)) | N19: =IF(A19="","",SUMIFS(Allocation!$S$5:$S$204,Allocation!$C$5:$C$204,A19)) | P19: =IF(A19="","",N19+O19)
... M54: =IF(A54="","",SUMIFS(Allocation!$Q$5:$Q$204,Allocation!$C$5:$C$204,A54)) | N54: =IF(A54="","",SUMIFS(Allocation!$S$5:$S$204,Allocation!$C$5:$C$204,A54)) | P54: =IF(A54="","",N54+O54)

Sheet Roadmap
A1: Annual Roadmap
A2: Bars come from project Start/End dates; ◆ = milestone in that month. Sorted as entered on Projects.
G4: =Settings!$C$8 -> Q1 | H4: =Settings!$C$9 -> Q1 | I4: =Settings!$C$10 -> Q1 | J4: =Settings!$C$11 -> Q2 | K4: =Settings!$C$12 -> Q2 | L4: =Settings!$C$13 -> Q2 | M4: =Settings!$C$14 -> Q3 | N4: =Settings!$C$15 -> Q3 | O4: =Settings!$C$16 -> Q3 | P4: =Settings!$C$17 -> Q4 | Q4: =Settings!$C$18 -> Q4 | R4: =Settings!$C$19 -> Q4
A5: ID | B5: Project | C5: Priority | D5: Status | E5: Start | F5: End | G5: =Settings!$A$8 -> 46388 | H5: =Settings!$A$9 -> 46419 | I5: =Settings!$A$10 -> 46447 | J5: =Settings!$A$11 -> 46478 | K5: =Settings!$A$12 -> 46508 | L5: =Settings!$A$13 -> 46539 | M5: =Settings!$A$14 -> 46569 | N5: =Settings!$A$15 -> 46600 | O5: =Settings!$A$16 -> 46631 | P5: =Settings!$A$17 -> 46661 | Q5: =Settings!$A$18 -> 46692 | R5: =Settings!$A$19 -> 46722
A6: =IF(Projects!$A5="","",Projects!$A5) -> P001 | B6: =IF(Projects!$A5="","",Projects!$B5) -> RepApp Angular migration (strangler fig) | C6: =IF(Projects!$A5="","",Projects!$E5) -> P1 | D6: =IF(Projects!$A5="","",Projects!$K5) -> In Progress | E6: =IF(Projects!$A5="","",Projects!$I5) -> 46391 | F6: =IF(Projects!$A5="","",Projects!$J5) -> 46738 | G6: =IF($A6="","",IF(COUNTIFS(Milestones!$A$5:$A$104,$A6,Milestones!$D$5:$D$104,">="&G$5,Milestones!$D$5:$D$104,"<="&EOMONTH(G$5,0))>0,"◆","")) | H6: =IF($A6="","",IF(COUNTIFS(Milestones!$A$5:$A$104,$A6,Milestones!$D$5:$D$104,">="&H$5,Milestones!$D$5:$D$104,"<="&EOMONTH(H$5,0))>0,"◆","")) | I6: =IF($A6="","",IF(COUNTIFS(Milestones!$A$5:$A$104,$A6,Milestones!$D$5:$D$104,">="&I$5,Milestones!$D$5:$D$104,"<="&EOMONTH(I$5,0))>0,"◆","")) -> ◆ | J6: =IF($A6="","",IF(COUNTIFS(Milestones!$A$5:$A$104,$A6,Milestones!$D$5:$D$104,">="&J$5,Milestones!$D$5:$D$104,"<="&EOMONTH(J$5,0))>0,"◆","")) | K6: =IF($A6="","",IF(COUNTIFS(Milestones!$A$5:$A$104,$A6,Milestones!$D$5:$D$104,">="&K$5,Milestones!$D$5:$D$104,"<="&EOMONTH(K$5,0))>0,"◆","")) | L6: =IF($A6="","",IF(COUNTIFS(Milestones!$A$5:$A$104,$A6,Milestones!$D$5:$D$104,">="&L$5,Milestones!$D$5:$D$104,"<="&EOMONTH(L$5,0))>0,"◆","")) | M6: =IF($A6="","",IF(COUNTIFS(Milestones!$A$5:$A$104,$A6,Milestones!$D$5:$D$104,">="&M$5,Milestones!$D$5:$D$104,"<="&EOMONTH(M$5,0))>0,"◆","")) -> ◆ | N6: =IF($A6="","",IF(COUNTIFS(Milestones!$A$5:$A$104,$A6,Milestones!$D$5:$D$104,">="&N$5,Milestones!$D$5:$D$104,"<="&EOMONTH(N$5,0))>0,"◆","")) | ... R6: =IF($A6="","",IF(COUNTIFS(Milestones!$A$5:$A$104,$A6,Milestones!$D$5:$D$104,">="&R$5,Milestones!$D$5:$D$104,"<="&EOMONTH(R$5,0))>0,"◆",""))
A7: =IF(Projects!$A6="","",Projects!$A6) -> P002 | B7: =IF(Projects!$A6="","",Projects!$B6) -> Application portfolio dashboard | C7: =IF(Projects!$A6="","",Projects!$E6) -> P2 | D7: =IF(Projects!$A6="","",Projects!$K6) -> Approved | E7: =IF(Projects!$A6="","",Projects!$I6) -> 46398 | F7: =IF(Projects!$A6="","",Projects!$J6) -> 46507 | G7: =IF($A7="","",IF(COUNTIFS(Milestones!$A$5:$A$104,$A7,Milestones!$D$5:$D$104,">="&G$5,Milestones!$D$5:$D$104,"<="&EOMONTH(G$5,0))>0,"◆","")) | H7: =IF($A7="","",IF(COUNTIFS(Milestones!$A$5:$A$104,$A7,Milestones!$D$5:$D$104,">="&H$5,Milestones!$D$5:$D$104,"<="&EOMONTH(H$5,0))>0,"◆","")) | I7: =IF($A7="","",IF(COUNTIFS(Milestones!$A$5:$A$104,$A7,Milestones!$D$5:$D$104,">="&I$5,Milestones!$D$5:$D$104,"<="&EOMONTH(I$5,0))>0,"◆","")) -> ◆ | J7: =IF($A7="","",IF(COUNTIFS(Milestones!$A$5:$A$104,$A7,Milestones!$D$5:$D$104,">="&J$5,Milestones!$D$5:$D$104,"<="&EOMONTH(J$5,0))>0,"◆","")) | K7: =IF($A7="","",IF(COUNTIFS(Milestones!$A$5:$A$104,$A7,Milestones!$D$5:$D$104,">="&K$5,Milestones!$D$5:$D$104,"<="&EOMONTH(K$5,0))>0,"◆","")) | L7: =IF($A7="","",IF(COUNTIFS(Milestones!$A$5:$A$104,$A7,Milestones!$D$5:$D$104,">="&L$5,Milestones!$D$5:$D$104,"<="&EOMONTH(L$5,0))>0,"◆","")) | M7: =IF($A7="","",IF(COUNTIFS(Milestones!$A$5:$A$104,$A7,Milestones!$D$5:$D$104,">="&M$5,Milestones!$D$5:$D$104,"<="&EOMONTH(M$5,0))>0,"◆","")) | N7: =IF($A7="","",IF(COUNTIFS(Milestones!$A$5:$A$104,$A7,Milestones!$D$5:$D$104,">="&N$5,Milestones!$D$5:$D$104,"<="&EOMONTH(N$5,0))>0,"◆","")) | ... R7: =IF($A7="","",IF(COUNTIFS(Milestones!$A$5:$A$104,$A7,Milestones!$D$5:$D$104,">="&R$5,Milestones!$D$5:$D$104,"<="&EOMONTH(R$5,0))>0,"◆",""))
A8: =IF(Projects!$A7="","",Projects!$A7) -> P003 | B8: =IF(Projects!$A7="","",Projects!$B7) -> Observability & alerting uplift | C8: =IF(Projects!$A7="","",Projects!$E7) -> P2 | D8: =IF(Projects!$A7="","",Projects!$K7) -> Proposed | E8: =IF(Projects!$A7="","",Projects!$I7) -> 46447 | F8: =IF(Projects!$A7="","",Projects!$J7) -> 46630 | G8: =IF($A8="","",IF(COUNTIFS(Milestones!$A$5:$A$104,$A8,Milestones!$D$5:$D$104,">="&G$5,Milestones!$D$5:$D$104,"<="&EOMONTH(G$5,0))>0,"◆","")) | H8: =IF($A8="","",IF(COUNTIFS(Milestones!$A$5:$A$104,$A8,Milestones!$D$5:$D$104,">="&H$5,Milestones!$D$5:$D$104,"<="&EOMONTH(H$5,0))>0,"◆","")) | I8: =IF($A8="","",IF(COUNTIFS(Milestones!$A$5:$A$104,$A8,Milestones!$D$5:$D$104,">="&I$5,Milestones!$D$5:$D$104,"<="&EOMONTH(I$5,0))>0,"◆","")) | J8: =IF($A8="","",IF(COUNTIFS(Milestones!$A$5:$A$104,$A8,Milestones!$D$5:$D$104,">="&J$5,Milestones!$D$5:$D$104,"<="&EOMONTH(J$5,0))>0,"◆","")) | K8: =IF($A8="","",IF(COUNTIFS(Milestones!$A$5:$A$104,$A8,Milestones!$D$5:$D$104,">="&K$5,Milestones!$D$5:$D$104,"<="&EOMONTH(K$5,0))>0,"◆","")) | L8: =IF($A8="","",IF(COUNTIFS(Milestones!$A$5:$A$104,$A8,Milestones!$D$5:$D$104,">="&L$5,Milestones!$D$5:$D$104,"<="&EOMONTH(L$5,0))>0,"◆","")) -> ◆ | M8: =IF($A8="","",IF(COUNTIFS(Milestones!$A$5:$A$104,$A8,Milestones!$D$5:$D$104,">="&M$5,Milestones!$D$5:$D$104,"<="&EOMONTH(M$5,0))>0,"◆","")) | N8: =IF($A8="","",IF(COUNTIFS(Milestones!$A$5:$A$104,$A8,Milestones!$D$5:$D$104,">="&N$5,Milestones!$D$5:$D$104,"<="&EOMONTH(N$5,0))>0,"◆","")) | ... R8: =IF($A8="","",IF(COUNTIFS(Milestones!$A$5:$A$104,$A8,Milestones!$D$5:$D$104,">="&R$5,Milestones!$D$5:$D$104,"<="&EOMONTH(R$5,0))>0,"◆",""))
A9: =IF(Projects!$A8="","",Projects!$A8) | B9: =IF(Projects!$A8="","",Projects!$B8) | C9: =IF(Projects!$A8="","",Projects!$E8) | D9: =IF(Projects!$A8="","",Projects!$K8) | E9: =IF(Projects!$A8="","",Projects!$I8) | F9: =IF(Projects!$A8="","",Projects!$J8) | G9: =IF($A9="","",IF(COUNTIFS(Milestones!$A$5:$A$104,$A9,Milestones!$D$5:$D$104,">="&G$5,Milestones!$D$5:$D$104,"<="&EOMONTH(G$5,0))>0,"◆","")) | H9: =IF($A9="","",IF(COUNTIFS(Milestones!$A$5:$A$104,$A9,Milestones!$D$5:$D$104,">="&H$5,Milestones!$D$5:$D$104,"<="&EOMONTH(H$5,0))>0,"◆","")) | I9: =IF($A9="","",IF(COUNTIFS(Milestones!$A$5:$A$104,$A9,Milestones!$D$5:$D$104,">="&I$5,Milestones!$D$5:$D$104,"<="&EOMONTH(I$5,0))>0,"◆","")) | J9: =IF($A9="","",IF(COUNTIFS(Milestones!$A$5:$A$104,$A9,Milestones!$D$5:$D$104,">="&J$5,Milestones!$D$5:$D$104,"<="&EOMONTH(J$5,0))>0,"◆","")) | K9: =IF($A9="","",IF(COUNTIFS(Milestones!$A$5:$A$104,$A9,Milestones!$D$5:$D$104,">="&K$5,Milestones!$D$5:$D$104,"<="&EOMONTH(K$5,0))>0,"◆","")) | L9: =IF($A9="","",IF(COUNTIFS(Milestones!$A$5:$A$104,$A9,Milestones!$D$5:$D$104,">="&L$5,Milestones!$D$5:$D$104,"<="&EOMONTH(L$5,0))>0,"◆","")) | M9: =IF($A9="","",IF(COUNTIFS(Milestones!$A$5:$A$104,$A9,Milestones!$D$5:$D$104,">="&M$5,Milestones!$D$5:$D$104,"<="&EOMONTH(M$5,0))>0,"◆","")) | N9: =IF($A9="","",IF(COUNTIFS(Milestones!$A$5:$A$104,$A9,Milestones!$D$5:$D$104,">="&N$5,Milestones!$D$5:$D$104,"<="&EOMONTH(N$5,0))>0,"◆","")) | ... R9: =IF($A9="","",IF(COUNTIFS(Milestones!$A$5:$A$104,$A9,Milestones!$D$5:$D$104,">="&R$5,Milestones!$D$5:$D$104,"<="&EOMONTH(R$5,0))>0,"◆",""))
A10: =IF(Projects!$A9="","",Projects!$A9) | B10: =IF(Projects!$A9="","",Projects!$B9) | C10: =IF(Projects!$A9="","",Projects!$E9) | D10: =IF(Projects!$A9="","",Projects!$K9) | E10: =IF(Projects!$A9="","",Projects!$I9) | F10: =IF(Projects!$A9="","",Projects!$J9) | G10: =IF($A10="","",IF(COUNTIFS(Milestones!$A$5:$A$104,$A10,Milestones!$D$5:$D$104,">="&G$5,Milestones!$D$5:$D$104,"<="&EOMONTH(G$5,0))>0,"◆","")) | H10: =IF($A10="","",IF(COUNTIFS(Milestones!$A$5:$A$104,$A10,Milestones!$D$5:$D$104,">="&H$5,Milestones!$D$5:$D$104,"<="&EOMONTH(H$5,0))>0,"◆","")) | I10: =IF($A10="","",IF(COUNTIFS(Milestones!$A$5:$A$104,$A10,Milestones!$D$5:$D$104,">="&I$5,Milestones!$D$5:$D$104,"<="&EOMONTH(I$5,0))>0,"◆","")) | J10: =IF($A10="","",IF(COUNTIFS(Milestones!$A$5:$A$104,$A10,Milestones!$D$5:$D$104,">="&J$5,Milestones!$D$5:$D$104,"<="&EOMONTH(J$5,0))>0,"◆","")) | K10: =IF($A10="","",IF(COUNTIFS(Milestones!$A$5:$A$104,$A10,Milestones!$D$5:$D$104,">="&K$5,Milestones!$D$5:$D$104,"<="&EOMONTH(K$5,0))>0,"◆","")) | L10: =IF($A10="","",IF(COUNTIFS(Milestones!$A$5:$A$104,$A10,Milestones!$D$5:$D$104,">="&L$5,Milestones!$D$5:$D$104,"<="&EOMONTH(L$5,0))>0,"◆","")) | M10: =IF($A10="","",IF(COUNTIFS(Milestones!$A$5:$A$104,$A10,Milestones!$D$5:$D$104,">="&M$5,Milestones!$D$5:$D$104,"<="&EOMONTH(M$5,0))>0,"◆","")) | N10: =IF($A10="","",IF(COUNTIFS(Milestones!$A$5:$A$104,$A10,Milestones!$D$5:$D$104,">="&N$5,Milestones!$D$5:$D$104,"<="&EOMONTH(N$5,0))>0,"◆","")) | ... R10: =IF($A10="","",IF(COUNTIFS(Milestones!$A$5:$A$104,$A10,Milestones!$D$5:$D$104,">="&R$5,Milestones!$D$5:$D$104,"<="&EOMONTH(R$5,0))>0,"◆",""))
A11: =IF(Projects!$A10="","",Projects!$A10) | B11: =IF(Projects!$A10="","",Projects!$B10) | C11: =IF(Projects!$A10="","",Projects!$E10) | D11: =IF(Projects!$A10="","",Projects!$K10) | E11: =IF(Projects!$A10="","",Projects!$I10) | F11: =IF(Projects!$A10="","",Projects!$J10) | G11: =IF($A11="","",IF(COUNTIFS(Milestones!$A$5:$A$104,$A11,Milestones!$D$5:$D$104,">="&G$5,Milestones!$D$5:$D$104,"<="&EOMONTH(G$5,0))>0,"◆","")) | H11: =IF($A11="","",IF(COUNTIFS(Milestones!$A$5:$A$104,$A11,Milestones!$D$5:$D$104,">="&H$5,Milestones!$D$5:$D$104,"<="&EOMONTH(H$5,0))>0,"◆","")) | I11: =IF($A11="","",IF(COUNTIFS(Milestones!$A$5:$A$104,$A11,Milestones!$D$5:$D$104,">="&I$5,Milestones!$D$5:$D$104,"<="&EOMONTH(I$5,0))>0,"◆","")) | J11: =IF($A11="","",IF(COUNTIFS(Milestones!$A$5:$A$104,$A11,Milestones!$D$5:$D$104,">="&J$5,Milestones!$D$5:$D$104,"<="&EOMONTH(J$5,0))>0,"◆","")) | K11: =IF($A11="","",IF(COUNTIFS(Milestones!$A$5:$A$104,$A11,Milestones!$D$5:$D$104,">="&K$5,Milestones!$D$5:$D$104,"<="&EOMONTH(K$5,0))>0,"◆","")) | L11: =IF($A11="","",IF(COUNTIFS(Milestones!$A$5:$A$104,$A11,Milestones!$D$5:$D$104,">="&L$5,Milestones!$D$5:$D$104,"<="&EOMONTH(L$5,0))>0,"◆","")) | M11: =IF($A11="","",IF(COUNTIFS(Milestones!$A$5:$A$104,$A11,Milestones!$D$5:$D$104,">="&M$5,Milestones!$D$5:$D$104,"<="&EOMONTH(M$5,0))>0,"◆","")) | N11: =IF($A11="","",IF(COUNTIFS(Milestones!$A$5:$A$104,$A11,Milestones!$D$5:$D$104,">="&N$5,Milestones!$D$5:$D$104,"<="&EOMONTH(N$5,0))>0,"◆","")) | ... R11: =IF($A11="","",IF(COUNTIFS(Milestones!$A$5:$A$104,$A11,Milestones!$D$5:$D$104,">="&R$5,Milestones!$D$5:$D$104,"<="&EOMONTH(R$5,0))>0,"◆",""))
A12: =IF(Projects!$A11="","",Projects!$A11) | B12: =IF(Projects!$A11="","",Projects!$B11) | C12: =IF(Projects!$A11="","",Projects!$E11) | D12: =IF(Projects!$A11="","",Projects!$K11) | E12: =IF(Projects!$A11="","",Projects!$I11) | F12: =IF(Projects!$A11="","",Projects!$J11) | G12: =IF($A12="","",IF(COUNTIFS(Milestones!$A$5:$A$104,$A12,Milestones!$D$5:$D$104,">="&G$5,Milestones!$D$5:$D$104,"<="&EOMONTH(G$5,0))>0,"◆","")) | H12: =IF($A12="","",IF(COUNTIFS(Milestones!$A$5:$A$104,$A12,Milestones!$D$5:$D$104,">="&H$5,Milestones!$D$5:$D$104,"<="&EOMONTH(H$5,0))>0,"◆","")) | I12: =IF($A12="","",IF(COUNTIFS(Milestones!$A$5:$A$104,$A12,Milestones!$D$5:$D$104,">="&I$5,Milestones!$D$5:$D$104,"<="&EOMONTH(I$5,0))>0,"◆","")) | J12: =IF($A12="","",IF(COUNTIFS(Milestones!$A$5:$A$104,$A12,Milestones!$D$5:$D$104,">="&J$5,Milestones!$D$5:$D$104,"<="&EOMONTH(J$5,0))>0,"◆","")) | K12: =IF($A12="","",IF(COUNTIFS(Milestones!$A$5:$A$104,$A12,Milestones!$D$5:$D$104,">="&K$5,Milestones!$D$5:$D$104,"<="&EOMONTH(K$5,0))>0,"◆","")) | L12: =IF($A12="","",IF(COUNTIFS(Milestones!$A$5:$A$104,$A12,Milestones!$D$5:$D$104,">="&L$5,Milestones!$D$5:$D$104,"<="&EOMONTH(L$5,0))>0,"◆","")) | M12: =IF($A12="","",IF(COUNTIFS(Milestones!$A$5:$A$104,$A12,Milestones!$D$5:$D$104,">="&M$5,Milestones!$D$5:$D$104,"<="&EOMONTH(M$5,0))>0,"◆","")) | N12: =IF($A12="","",IF(COUNTIFS(Milestones!$A$5:$A$104,$A12,Milestones!$D$5:$D$104,">="&N$5,Milestones!$D$5:$D$104,"<="&EOMONTH(N$5,0))>0,"◆","")) | ... R12: =IF($A12="","",IF(COUNTIFS(Milestones!$A$5:$A$104,$A12,Milestones!$D$5:$D$104,">="&R$5,Milestones!$D$5:$D$104,"<="&EOMONTH(R$5,0))>0,"◆",""))
A13: =IF(Projects!$A12="","",Projects!$A12) | B13: =IF(Projects!$A12="","",Projects!$B12) | C13: =IF(Projects!$A12="","",Projects!$E12) | D13: =IF(Projects!$A12="","",Projects!$K12) | E13: =IF(Projects!$A12="","",Projects!$I12) | F13: =IF(Projects!$A12="","",Projects!$J12) | G13: =IF($A13="","",IF(COUNTIFS(Milestones!$A$5:$A$104,$A13,Milestones!$D$5:$D$104,">="&G$5,Milestones!$D$5:$D$104,"<="&EOMONTH(G$5,0))>0,"◆","")) | H13: =IF($A13="","",IF(COUNTIFS(Milestones!$A$5:$A$104,$A13,Milestones!$D$5:$D$104,">="&H$5,Milestones!$D$5:$D$104,"<="&EOMONTH(H$5,0))>0,"◆","")) | I13: =IF($A13="","",IF(COUNTIFS(Milestones!$A$5:$A$104,$A13,Milestones!$D$5:$D$104,">="&I$5,Milestones!$D$5:$D$104,"<="&EOMONTH(I$5,0))>0,"◆","")) | J13: =IF($A13="","",IF(COUNTIFS(Milestones!$A$5:$A$104,$A13,Milestones!$D$5:$D$104,">="&J$5,Milestones!$D$5:$D$104,"<="&EOMONTH(J$5,0))>0,"◆","")) | K13: =IF($A13="","",IF(COUNTIFS(Milestones!$A$5:$A$104,$A13,Milestones!$D$5:$D$104,">="&K$5,Milestones!$D$5:$D$104,"<="&EOMONTH(K$5,0))>0,"◆","")) | L13: =IF($A13="","",IF(COUNTIFS(Milestones!$A$5:$A$104,$A13,Milestones!$D$5:$D$104,">="&L$5,Milestones!$D$5:$D$104,"<="&EOMONTH(L$5,0))>0,"◆","")) | M13: =IF($A13="","",IF(COUNTIFS(Milestones!$A$5:$A$104,$A13,Milestones!$D$5:$D$104,">="&M$5,Milestones!$D$5:$D$104,"<="&EOMONTH(M$5,0))>0,"◆","")) | N13: =IF($A13="","",IF(COUNTIFS(Milestones!$A$5:$A$104,$A13,Milestones!$D$5:$D$104,">="&N$5,Milestones!$D$5:$D$104,"<="&EOMONTH(N$5,0))>0,"◆","")) | ... R13: =IF($A13="","",IF(COUNTIFS(Milestones!$A$5:$A$104,$A13,Milestones!$D$5:$D$104,">="&R$5,Milestones!$D$5:$D$104,"<="&EOMONTH(R$5,0))>0,"◆",""))
A14: =IF(Projects!$A13="","",Projects!$A13) | B14: =IF(Projects!$A13="","",Projects!$B13) | C14: =IF(Projects!$A13="","",Projects!$E13) | D14: =IF(Projects!$A13="","",Projects!$K13) | E14: =IF(Projects!$A13="","",Projects!$I13) | F14: =IF(Projects!$A13="","",Projects!$J13) | G14: =IF($A14="","",IF(COUNTIFS(Milestones!$A$5:$A$104,$A14,Milestones!$D$5:$D$104,">="&G$5,Milestones!$D$5:$D$104,"<="&EOMONTH(G$5,0))>0,"◆","")) | H14: =IF($A14="","",IF(COUNTIFS(Milestones!$A$5:$A$104,$A14,Milestones!$D$5:$D$104,">="&H$5,Milestones!$D$5:$D$104,"<="&EOMONTH(H$5,0))>0,"◆","")) | I14: =IF($A14="","",IF(COUNTIFS(Milestones!$A$5:$A$104,$A14,Milestones!$D$5:$D$104,">="&I$5,Milestones!$D$5:$D$104,"<="&EOMONTH(I$5,0))>0,"◆","")) | J14: =IF($A14="","",IF(COUNTIFS(Milestones!$A$5:$A$104,$A14,Milestones!$D$5:$D$104,">="&J$5,Milestones!$D$5:$D$104,"<="&EOMONTH(J$5,0))>0,"◆","")) | K14: =IF($A14="","",IF(COUNTIFS(Milestones!$A$5:$A$104,$A14,Milestones!$D$5:$D$104,">="&K$5,Milestones!$D$5:$D$104,"<="&EOMONTH(K$5,0))>0,"◆","")) | L14: =IF($A14="","",IF(COUNTIFS(Milestones!$A$5:$A$104,$A14,Milestones!$D$5:$D$104,">="&L$5,Milestones!$D$5:$D$104,"<="&EOMONTH(L$5,0))>0,"◆","")) | M14: =IF($A14="","",IF(COUNTIFS(Milestones!$A$5:$A$104,$A14,Milestones!$D$5:$D$104,">="&M$5,Milestones!$D$5:$D$104,"<="&EOMONTH(M$5,0))>0,"◆","")) | N14: =IF($A14="","",IF(COUNTIFS(Milestones!$A$5:$A$104,$A14,Milestones!$D$5:$D$104,">="&N$5,Milestones!$D$5:$D$104,"<="&EOMONTH(N$5,0))>0,"◆","")) | ... R14: =IF($A14="","",IF(COUNTIFS(Milestones!$A$5:$A$104,$A14,Milestones!$D$5:$D$104,">="&R$5,Milestones!$D$5:$D$104,"<="&EOMONTH(R$5,0))>0,"◆",""))
A15: =IF(Projects!$A14="","",Projects!$A14) | B15: =IF(Projects!$A14="","",Projects!$B14) | C15: =IF(Projects!$A14="","",Projects!$E14) | D15: =IF(Projects!$A14="","",Projects!$K14) | E15: =IF(Projects!$A14="","",Projects!$I14) | F15: =IF(Projects!$A14="","",Projects!$J14) | G15: =IF($A15="","",IF(COUNTIFS(Milestones!$A$5:$A$104,$A15,Milestones!$D$5:$D$104,">="&G$5,Milestones!$D$5:$D$104,"<="&EOMONTH(G$5,0))>0,"◆","")) | H15: =IF($A15="","",IF(COUNTIFS(Milestones!$A$5:$A$104,$A15,Milestones!$D$5:$D$104,">="&H$5,Milestones!$D$5:$D$104,"<="&EOMONTH(H$5,0))>0,"◆","")) | I15: =IF($A15="","",IF(COUNTIFS(Milestones!$A$5:$A$104,$A15,Milestones!$D$5:$D$104,">="&I$5,Milestones!$D$5:$D$104,"<="&EOMONTH(I$5,0))>0,"◆","")) | J15: =IF($A15="","",IF(COUNTIFS(Milestones!$A$5:$A$104,$A15,Milestones!$D$5:$D$104,">="&J$5,Milestones!$D$5:$D$104,"<="&EOMONTH(J$5,0))>0,"◆","")) | K15: =IF($A15="","",IF(COUNTIFS(Milestones!$A$5:$A$104,$A15,Milestones!$D$5:$D$104,">="&K$5,Milestones!$D$5:$D$104,"<="&EOMONTH(K$5,0))>0,"◆","")) | L15: =IF($A15="","",IF(COUNTIFS(Milestones!$A$5:$A$104,$A15,Milestones!$D$5:$D$104,">="&L$5,Milestones!$D$5:$D$104,"<="&EOMONTH(L$5,0))>0,"◆","")) | M15: =IF($A15="","",IF(COUNTIFS(Milestones!$A$5:$A$104,$A15,Milestones!$D$5:$D$104,">="&M$5,Milestones!$D$5:$D$104,"<="&EOMONTH(M$5,0))>0,"◆","")) | N15: =IF($A15="","",IF(COUNTIFS(Milestones!$A$5:$A$104,$A15,Milestones!$D$5:$D$104,">="&N$5,Milestones!$D$5:$D$104,"<="&EOMONTH(N$5,0))>0,"◆","")) | ... R15: =IF($A15="","",IF(COUNTIFS(Milestones!$A$5:$A$104,$A15,Milestones!$D$5:$D$104,">="&R$5,Milestones!$D$5:$D$104,"<="&EOMONTH(R$5,0))>0,"◆",""))
A16: =IF(Projects!$A15="","",Projects!$A15) | B16: =IF(Projects!$A15="","",Projects!$B15) | C16: =IF(Projects!$A15="","",Projects!$E15) | D16: =IF(Projects!$A15="","",Projects!$K15) | E16: =IF(Projects!$A15="","",Projects!$I15) | F16: =IF(Projects!$A15="","",Projects!$J15) | G16: =IF($A16="","",IF(COUNTIFS(Milestones!$A$5:$A$104,$A16,Milestones!$D$5:$D$104,">="&G$5,Milestones!$D$5:$D$104,"<="&EOMONTH(G$5,0))>0,"◆","")) | H16: =IF($A16="","",IF(COUNTIFS(Milestones!$A$5:$A$104,$A16,Milestones!$D$5:$D$104,">="&H$5,Milestones!$D$5:$D$104,"<="&EOMONTH(H$5,0))>0,"◆","")) | I16: =IF($A16="","",IF(COUNTIFS(Milestones!$A$5:$A$104,$A16,Milestones!$D$5:$D$104,">="&I$5,Milestones!$D$5:$D$104,"<="&EOMONTH(I$5,0))>0,"◆","")) | J16: =IF($A16="","",IF(COUNTIFS(Milestones!$A$5:$A$104,$A16,Milestones!$D$5:$D$104,">="&J$5,Milestones!$D$5:$D$104,"<="&EOMONTH(J$5,0))>0,"◆","")) | K16: =IF($A16="","",IF(COUNTIFS(Milestones!$A$5:$A$104,$A16,Milestones!$D$5:$D$104,">="&K$5,Milestones!$D$5:$D$104,"<="&EOMONTH(K$5,0))>0,"◆","")) | L16: =IF($A16="","",IF(COUNTIFS(Milestones!$A$5:$A$104,$A16,Milestones!$D$5:$D$104,">="&L$5,Milestones!$D$5:$D$104,"<="&EOMONTH(L$5,0))>0,"◆","")) | M16: =IF($A16="","",IF(COUNTIFS(Milestones!$A$5:$A$104,$A16,Milestones!$D$5:$D$104,">="&M$5,Milestones!$D$5:$D$104,"<="&EOMONTH(M$5,0))>0,"◆","")) | N16: =IF($A16="","",IF(COUNTIFS(Milestones!$A$5:$A$104,$A16,Milestones!$D$5:$D$104,">="&N$5,Milestones!$D$5:$D$104,"<="&EOMONTH(N$5,0))>0,"◆","")) | ... R16: =IF($A16="","",IF(COUNTIFS(Milestones!$A$5:$A$104,$A16,Milestones!$D$5:$D$104,">="&R$5,Milestones!$D$5:$D$104,"<="&EOMONTH(R$5,0))>0,"◆",""))
A17: =IF(Projects!$A16="","",Projects!$A16) | B17: =IF(Projects!$A16="","",Projects!$B16) | C17: =IF(Projects!$A16="","",Projects!$E16) | D17: =IF(Projects!$A16="","",Projects!$K16) | E17: =IF(Projects!$A16="","",Projects!$I16) | F17: =IF(Projects!$A16="","",Projects!$J16) | G17: =IF($A17="","",IF(COUNTIFS(Milestones!$A$5:$A$104,$A17,Milestones!$D$5:$D$104,">="&G$5,Milestones!$D$5:$D$104,"<="&EOMONTH(G$5,0))>0,"◆","")) | H17: =IF($A17="","",IF(COUNTIFS(Milestones!$A$5:$A$104,$A17,Milestones!$D$5:$D$104,">="&H$5,Milestones!$D$5:$D$104,"<="&EOMONTH(H$5,0))>0,"◆","")) | I17: =IF($A17="","",IF(COUNTIFS(Milestones!$A$5:$A$104,$A17,Milestones!$D$5:$D$104,">="&I$5,Milestones!$D$5:$D$104,"<="&EOMONTH(I$5,0))>0,"◆","")) | J17: =IF($A17="","",IF(COUNTIFS(Milestones!$A$5:$A$104,$A17,Milestones!$D$5:$D$104,">="&J$5,Milestones!$D$5:$D$104,"<="&EOMONTH(J$5,0))>0,"◆","")) | K17: =IF($A17="","",IF(COUNTIFS(Milestones!$A$5:$A$104,$A17,Milestones!$D$5:$D$104,">="&K$5,Milestones!$D$5:$D$104,"<="&EOMONTH(K$5,0))>0,"◆","")) | L17: =IF($A17="","",IF(COUNTIFS(Milestones!$A$5:$A$104,$A17,Milestones!$D$5:$D$104,">="&L$5,Milestones!$D$5:$D$104,"<="&EOMONTH(L$5,0))>0,"◆","")) | M17: =IF($A17="","",IF(COUNTIFS(Milestones!$A$5:$A$104,$A17,Milestones!$D$5:$D$104,">="&M$5,Milestones!$D$5:$D$104,"<="&EOMONTH(M$5,0))>0,"◆","")) | N17: =IF($A17="","",IF(COUNTIFS(Milestones!$A$5:$A$104,$A17,Milestones!$D$5:$D$104,">="&N$5,Milestones!$D$5:$D$104,"<="&EOMONTH(N$5,0))>0,"◆","")) | ... R17: =IF($A17="","",IF(COUNTIFS(Milestones!$A$5:$A$104,$A17,Milestones!$D$5:$D$104,">="&R$5,Milestones!$D$5:$D$104,"<="&EOMONTH(R$5,0))>0,"◆",""))
... A55: =IF(Projects!$A54="","",Projects!$A54) | B55: =IF(Projects!$A54="","",Projects!$B54) | C55: =IF(Projects!$A54="","",Projects!$E54) | D55: =IF(Projects!$A54="","",Projects!$K54) | E55: =IF(Projects!$A54="","",Projects!$I54) | F55: =IF(Projects!$A54="","",Projects!$J54) | G55: =IF($A55="","",IF(COUNTIFS(Milestones!$A$5:$A$104,$A55,Milestones!$D$5:$D$104,">="&G$5,Milestones!$D$5:$D$104,"<="&EOMONTH(G$5,0))>0,"◆","")) | H55: =IF($A55="","",IF(COUNTIFS(Milestones!$A$5:$A$104,$A55,Milestones!$D$5:$D$104,">="&H$5,Milestones!$D$5:$D$104,"<="&EOMONTH(H$5,0))>0,"◆","")) | I55: =IF($A55="","",IF(COUNTIFS(Milestones!$A$5:$A$104,$A55,Milestones!$D$5:$D$104,">="&I$5,Milestones!$D$5:$D$104,"<="&EOMONTH(I$5,0))>0,"◆","")) | J55: =IF($A55="","",IF(COUNTIFS(Milestones!$A$5:$A$104,$A55,Milestones!$D$5:$D$104,">="&J$5,Milestones!$D$5:$D$104,"<="&EOMONTH(J$5,0))>0,"◆","")) | K55: =IF($A55="","",IF(COUNTIFS(Milestones!$A$5:$A$104,$A55,Milestones!$D$5:$D$104,">="&K$5,Milestones!$D$5:$D$104,"<="&EOMONTH(K$5,0))>0,"◆","")) | L55: =IF($A55="","",IF(COUNTIFS(Milestones!$A$5:$A$104,$A55,Milestones!$D$5:$D$104,">="&L$5,Milestones!$D$5:$D$104,"<="&EOMONTH(L$5,0))>0,"◆","")) | M55: =IF($A55="","",IF(COUNTIFS(Milestones!$A$5:$A$104,$A55,Milestones!$D$5:$D$104,">="&M$5,Milestones!$D$5:$D$104,"<="&EOMONTH(M$5,0))>0,"◆","")) | N55: =IF($A55="","",IF(COUNTIFS(Milestones!$A$5:$A$104,$A55,Milestones!$D$5:$D$104,">="&N$5,Milestones!$D$5:$D$104,"<="&EOMONTH(N$5,0))>0,"◆","")) | ... R55: =IF($A55="","",IF(COUNTIFS(Milestones!$A$5:$A$104,$A55,Milestones!$D$5:$D$104,">="&R$5,Milestones!$D$5:$D$104,"<="&EOMONTH(R$5,0))>0,"◆",""))

Sheet Team
A1: Team & Resources
A2: Everyone who supplies capacity — FTEs, contractors, and open reqs (to show hiring need). Sample rows — overwrite.
A4: Name | B4: Role | C4: Type | D4: Vendor / Org | E4: Primary skills | F4: Location | G4: Availability % | H4: PTO days / yr | I4: Start date | J4: End date | K4: Monthly cost rate | L4: Annual capacity (FTE-mo) | M4: Annual allocated (FTE-mo) | N4: Utilization | P4: Notes
A5: Tech Lead 1 | B5: Tech Lead | C5: FTE | D5: Fidelity | E5: Java, Spring Boot, AWS | F5: Raleigh | G5: 0.8 | H5: 20 | K5: 15000 | L5: =IF(A5="","",Capacity!P70) -> 8.8299233 | M5: =IF(A5="","",Capacity!P134) -> 9.2 | N5: =IF(OR(A5="",L5=0),"",M5/L5) -> 1.0419117 | P5: • Availability % = time for project work (focus factor). Blank uses Settings default.
A6: Java Dev 1 | B6: Backend Developer | C6: FTE | D6: Fidelity | E6: Java, Kafka | F6: Raleigh | G6: 0.85 | H6: 20 | K6: 12000 | L6: =IF(A6="","",Capacity!P71) -> 9.3817935 | M6: =IF(A6="","",Capacity!P135) -> 8.4 | N6: =IF(OR(A6="",L6=0),"",M6/L6) -> 0.89535119 | P6: • Blank start/end = full plan year. Use them for new joiners and contractor roll-offs.
A7: Angular Dev 1 | B7: Frontend Developer | C7: Contractor | D7: InRhythm | E7: Angular, TypeScript | F7: Remote | G7: 0.9 | H7: 10 | K7: 14000 | L7: =IF(A7="","",Capacity!P72) -> 10.366832 | M7: =IF(A7="","",Capacity!P136) -> 10.8 | N7: =IF(OR(A7="",L7=0),"",M7/L7) -> 1.041784 | P7: • Monthly cost rate is a placeholder — use loaded/blended rates from Finance.
A8: Angular Dev 2 | B8: Full-stack Developer | C8: Contractor | D8: InRhythm | E8: Angular, Java | F8: Remote | G8: 0.9 | H8: 10 | K8: 14000 | L8: =IF(A8="","",Capacity!P73) -> 10.366832 | M8: =IF(A8="","",Capacity!P137) -> 7.6 | N8: =IF(OR(A8="",L8=0),"",M8/L8) -> 0.73310729 | P8: • Open Req rows let you plan work for people not hired yet.
A9: QA Engineer 1 | B9: QA / SDET | C9: Contractor | D9: InRhythm | E9: Playwright, API testing | F9: Remote | G9: 0.9 | H9: 10 | K9: 11000 | L9: =IF(A9="","",Capacity!P74) -> 10.366832 | M9: =IF(A9="","",Capacity!P138) -> 9 | N9: =IF(OR(A9="",L9=0),"",M9/L9) -> 0.86815337
A10: TBH Angular Dev | B10: Frontend Developer | C10: Open Req | D10: Fidelity | E10: Angular | F10: Raleigh | G10: 0.85 | H10: 15 | I10: 46478 | K10: 12000 | L10: =IF(A10="","",Capacity!P75) -> 7.1964827 | M10: =IF(A10="","",Capacity!P139) -> 7.2 | N10: =IF(OR(A10="",L10=0),"",M10/L10) -> 1.0004888
L11: =IF(A11="","",Capacity!P76) | M11: =IF(A11="","",Capacity!P140) | N11: =IF(OR(A11="",L11=0),"",M11/L11)
L12: =IF(A12="","",Capacity!P77) | M12: =IF(A12="","",Capacity!P141) | N12: =IF(OR(A12="",L12=0),"",M12/L12)
L13: =IF(A13="","",Capacity!P78) | M13: =IF(A13="","",Capacity!P142) | N13: =IF(OR(A13="",L13=0),"",M13/L13)
L14: =IF(A14="","",Capacity!P79) | M14: =IF(A14="","",Capacity!P143) | N14: =IF(OR(A14="",L14=0),"",M14/L14)
L15: =IF(A15="","",Capacity!P80) | M15: =IF(A15="","",Capacity!P144) | N15: =IF(OR(A15="",L15=0),"",M15/L15)
L16: =IF(A16="","",Capacity!P81) | M16: =IF(A16="","",Capacity!P145) | N16: =IF(OR(A16="",L16=0),"",M16/L16)
L17: =IF(A17="","",Capacity!P82) | M17: =IF(A17="","",Capacity!P146) | N17: =IF(OR(A17="",L17=0),"",M17/L17)
L18: =IF(A18="","",Capacity!P83) | M18: =IF(A18="","",Capacity!P147) | N18: =IF(OR(A18="",L18=0),"",M18/L18)
L19: =IF(A19="","",Capacity!P84) | M19: =IF(A19="","",Capacity!P148) | N19: =IF(OR(A19="",L19=0),"",M19/L19)
L20: =IF(A20="","",Capacity!P85) | M20: =IF(A20="","",Capacity!P149) | N20: =IF(OR(A20="",L20=0),"",M20/L20)
L21: =IF(A21="","",Capacity!P86) | M21: =IF(A21="","",Capacity!P150) | N21: =IF(OR(A21="",L21=0),"",M21/L21)
L22: =IF(A22="","",Capacity!P87) | M22: =IF(A22="","",Capacity!P151) | N22: =IF(OR(A22="",L22=0),"",M22/L22)
... L64: =IF(A64="","",Capacity!P129) | M64: =IF(A64="","",Capacity!P193) | N64: =IF(OR(A64="",L64=0),"",M64/L64)

Sheet Allocation
A1: Resource Allocation
A2: One row per person × project. Enter the share of that person's month (0.5 = 50%). Sample rows — overwrite.
A4: Resource | B4: Role | C4: Project ID | D4: Project | E4: Jan | F4: Feb | G4: Mar | H4: Apr | I4: May | J4: Jun | K4: Jul | L4: Aug | M4: Sep | N4: Oct | O4: Nov | P4: Dec | Q4: FTE-months | R4: Monthly rate | S4: Labor cost
A5: Tech Lead 1 | B5: =IF(A5="","",IFERROR(INDEX(Team!$B$5:$B$64,MATCH(A5,Team!$A$5:$A$64,0)),"Not in Team")) -> Tech Lead | C5: P001 | D5: =IF(C5="","",IFERROR(INDEX(Projects!$B$5:$B$54,MATCH(C5,Projects!$A$5:$A$54,0)),"Unknown ID")) -> RepApp Angular migration (strangler fig) | E5: 0.6 | F5: 0.6 | G5: 0.6 | H5: 0.6 | I5: 0.6 | J5: 0.6 | K5: 0.6 | L5: 0.6 | M5: 0.6 | N5: 0.6 | O5: 0.6 | P5: 0.6 | Q5: =IF(A5="","",SUM(E5:P5)) -> 7.2 | R5: =IF(A5="","",IFERROR(INDEX(Team!$K$5:$K$64,MATCH(A5,Team!$A$5:$A$64,0)),0)) -> 15000 | S5: =IF(A5="","",Q5*R5) -> 108000
A6: Tech Lead 1 | B6: =IF(A6="","",IFERROR(INDEX(Team!$B$5:$B$64,MATCH(A6,Team!$A$5:$A$64,0)),"Not in Team")) -> Tech Lead | C6: P002 | D6: =IF(C6="","",IFERROR(INDEX(Projects!$B$5:$B$54,MATCH(C6,Projects!$A$5:$A$54,0)),"Unknown ID")) -> Application portfolio dashboard | E6: 0.2 | F6: 0.2 | G6: 0.2 | H6: 0.2 | Q6: =IF(A6="","",SUM(E6:P6)) -> 0.8 | R6: =IF(A6="","",IFERROR(INDEX(Team!$K$5:$K$64,MATCH(A6,Team!$A$5:$A$64,0)),0)) -> 15000 | S6: =IF(A6="","",Q6*R6) -> 12000
A7: Tech Lead 1 | B7: =IF(A7="","",IFERROR(INDEX(Team!$B$5:$B$64,MATCH(A7,Team!$A$5:$A$64,0)),"Not in Team")) -> Tech Lead | C7: P003 | D7: =IF(C7="","",IFERROR(INDEX(Projects!$B$5:$B$54,MATCH(C7,Projects!$A$5:$A$54,0)),"Unknown ID")) -> Observability & alerting uplift | G7: 0.2 | H7: 0.2 | I7: 0.2 | J7: 0.2 | K7: 0.2 | L7: 0.2 | Q7: =IF(A7="","",SUM(E7:P7)) -> 1.2 | R7: =IF(A7="","",IFERROR(INDEX(Team!$K$5:$K$64,MATCH(A7,Team!$A$5:$A$64,0)),0)) -> 15000 | S7: =IF(A7="","",Q7*R7) -> 18000
A8: Java Dev 1 | B8: =IF(A8="","",IFERROR(INDEX(Team!$B$5:$B$64,MATCH(A8,Team!$A$5:$A$64,0)),"Not in Team")) -> Backend Developer | C8: P001 | D8: =IF(C8="","",IFERROR(INDEX(Projects!$B$5:$B$54,MATCH(C8,Projects!$A$5:$A$54,0)),"Unknown ID")) -> RepApp Angular migration (strangler fig) | E8: 0.5 | F8: 0.5 | G8: 0.5 | H8: 0.5 | I8: 0.5 | J8: 0.5 | K8: 0.5 | L8: 0.5 | M8: 0.5 | N8: 0.5 | O8: 0.5 | P8: 0.5 | Q8: =IF(A8="","",SUM(E8:P8)) -> 6 | R8: =IF(A8="","",IFERROR(INDEX(Team!$K$5:$K$64,MATCH(A8,Team!$A$5:$A$64,0)),0)) -> 12000 | S8: =IF(A8="","",Q8*R8) -> 72000
A9: Java Dev 1 | B9: =IF(A9="","",IFERROR(INDEX(Team!$B$5:$B$64,MATCH(A9,Team!$A$5:$A$64,0)),"Not in Team")) -> Backend Developer | C9: P003 | D9: =IF(C9="","",IFERROR(INDEX(Projects!$B$5:$B$54,MATCH(C9,Projects!$A$5:$A$54,0)),"Unknown ID")) -> Observability & alerting uplift | G9: 0.4 | H9: 0.4 | I9: 0.4 | J9: 0.4 | K9: 0.4 | L9: 0.4 | Q9: =IF(A9="","",SUM(E9:P9)) -> 2.4 | R9: =IF(A9="","",IFERROR(INDEX(Team!$K$5:$K$64,MATCH(A9,Team!$A$5:$A$64,0)),0)) -> 12000 | S9: =IF(A9="","",Q9*R9) -> 28800
A10: Angular Dev 1 | B10: =IF(A10="","",IFERROR(INDEX(Team!$B$5:$B$64,MATCH(A10,Team!$A$5:$A$64,0)),"Not in Team")) -> Frontend Developer | C10: P001 | D10: =IF(C10="","",IFERROR(INDEX(Projects!$B$5:$B$54,MATCH(C10,Projects!$A$5:$A$54,0)),"Unknown ID")) -> RepApp Angular migration (strangler fig) | E10: 0.9 | F10: 0.9 | G10: 0.9 | H10: 0.9 | I10: 0.9 | J10: 0.9 | K10: 0.9 | L10: 0.9 | M10: 0.9 | N10: 0.9 | O10: 0.9 | P10: 0.9 | Q10: =IF(A10="","",SUM(E10:P10)) -> 10.8 | R10: =IF(A10="","",IFERROR(INDEX(Team!$K$5:$K$64,MATCH(A10,Team!$A$5:$A$64,0)),0)) -> 14000 | S10: =IF(A10="","",Q10*R10) -> 151200
A11: Angular Dev 2 | B11: =IF(A11="","",IFERROR(INDEX(Team!$B$5:$B$64,MATCH(A11,Team!$A$5:$A$64,0)),"Not in Team")) -> Full-stack Developer | C11: P001 | D11: =IF(C11="","",IFERROR(INDEX(Projects!$B$5:$B$54,MATCH(C11,Projects!$A$5:$A$54,0)),"Unknown ID")) -> RepApp Angular migration (strangler fig) | E11: 0.5 | F11: 0.5 | G11: 0.5 | H11: 0.5 | I11: 0.5 | J11: 0.5 | K11: 0.5 | L11: 0.5 | M11: 0.5 | N11: 0.5 | O11: 0.5 | P11: 0.5 | Q11: =IF(A11="","",SUM(E11:P11)) -> 6 | R11: =IF(A11="","",IFERROR(INDEX(Team!$K$5:$K$64,MATCH(A11,Team!$A$5:$A$64,0)),0)) -> 14000 | S11: =IF(A11="","",Q11*R11) -> 84000
A12: Angular Dev 2 | B12: =IF(A12="","",IFERROR(INDEX(Team!$B$5:$B$64,MATCH(A12,Team!$A$5:$A$64,0)),"Not in Team")) -> Full-stack Developer | C12: P002 | D12: =IF(C12="","",IFERROR(INDEX(Projects!$B$5:$B$54,MATCH(C12,Projects!$A$5:$A$54,0)),"Unknown ID")) -> Application portfolio dashboard | E12: 0.4 | F12: 0.4 | G12: 0.4 | H12: 0.4 | Q12: =IF(A12="","",SUM(E12:P12)) -> 1.6 | R12: =IF(A12="","",IFERROR(INDEX(Team!$K$5:$K$64,MATCH(A12,Team!$A$5:$A$64,0)),0)) -> 14000 | S12: =IF(A12="","",Q12*R12) -> 22400
A13: QA Engineer 1 | B13: =IF(A13="","",IFERROR(INDEX(Team!$B$5:$B$64,MATCH(A13,Team!$A$5:$A$64,0)),"Not in Team")) -> QA / SDET | C13: P001 | D13: =IF(C13="","",IFERROR(INDEX(Projects!$B$5:$B$54,MATCH(C13,Projects!$A$5:$A$54,0)),"Unknown ID")) -> RepApp Angular migration (strangler fig) | E13: 0.6 | F13: 0.6 | G13: 0.6 | H13: 0.6 | I13: 0.6 | J13: 0.6 | K13: 0.6 | L13: 0.6 | M13: 0.6 | N13: 0.6 | O13: 0.6 | P13: 0.6 | Q13: =IF(A13="","",SUM(E13:P13)) -> 7.2 | R13: =IF(A13="","",IFERROR(INDEX(Team!$K$5:$K$64,MATCH(A13,Team!$A$5:$A$64,0)),0)) -> 11000 | S13: =IF(A13="","",Q13*R13) -> 79200
A14: QA Engineer 1 | B14: =IF(A14="","",IFERROR(INDEX(Team!$B$5:$B$64,MATCH(A14,Team!$A$5:$A$64,0)),"Not in Team")) -> QA / SDET | C14: P003 | D14: =IF(C14="","",IFERROR(INDEX(Projects!$B$5:$B$54,MATCH(C14,Projects!$A$5:$A$54,0)),"Unknown ID")) -> Observability & alerting uplift | G14: 0.3 | H14: 0.3 | I14: 0.3 | J14: 0.3 | K14: 0.3 | L14: 0.3 | Q14: =IF(A14="","",SUM(E14:P14)) -> 1.8 | R14: =IF(A14="","",IFERROR(INDEX(Team!$K$5:$K$64,MATCH(A14,Team!$A$5:$A$64,0)),0)) -> 11000 | S14: =IF(A14="","",Q14*R14) -> 19800
A15: TBH Angular Dev | B15: =IF(A15="","",IFERROR(INDEX(Team!$B$5:$B$64,MATCH(A15,Team!$A$5:$A$64,0)),"Not in Team")) -> Frontend Developer | C15: P001 | D15: =IF(C15="","",IFERROR(INDEX(Projects!$B$5:$B$54,MATCH(C15,Projects!$A$5:$A$54,0)),"Unknown ID")) -> RepApp Angular migration (strangler fig) | H15: 0.8 | I15: 0.8 | J15: 0.8 | K15: 0.8 | L15: 0.8 | M15: 0.8 | N15: 0.8 | O15: 0.8 | P15: 0.8 | Q15: =IF(A15="","",SUM(E15:P15)) -> 7.2 | R15: =IF(A15="","",IFERROR(INDEX(Team!$K$5:$K$64,MATCH(A15,Team!$A$5:$A$64,0)),0)) -> 12000 | S15: =IF(A15="","",Q15*R15) -> 86400
B16: =IF(A16="","",IFERROR(INDEX(Team!$B$5:$B$64,MATCH(A16,Team!$A$5:$A$64,0)),"Not in Team")) | D16: =IF(C16="","",IFERROR(INDEX(Projects!$B$5:$B$54,MATCH(C16,Projects!$A$5:$A$54,0)),"Unknown ID")) | Q16: =IF(A16="","",SUM(E16:P16)) | R16: =IF(A16="","",IFERROR(INDEX(Team!$K$5:$K$64,MATCH(A16,Team!$A$5:$A$64,0)),0)) | S16: =IF(A16="","",Q16*R16)
B17: =IF(A17="","",IFERROR(INDEX(Team!$B$5:$B$64,MATCH(A17,Team!$A$5:$A$64,0)),"Not in Team")) | D17: =IF(C17="","",IFERROR(INDEX(Projects!$B$5:$B$54,MATCH(C17,Projects!$A$5:$A$54,0)),"Unknown ID")) | Q17: =IF(A17="","",SUM(E17:P17)) | R17: =IF(A17="","",IFERROR(INDEX(Team!$K$5:$K$64,MATCH(A17,Team!$A$5:$A$64,0)),0)) | S17: =IF(A17="","",Q17*R17)
B18: =IF(A18="","",IFERROR(INDEX(Team!$B$5:$B$64,MATCH(A18,Team!$A$5:$A$64,0)),"Not in Team")) | D18: =IF(C18="","",IFERROR(INDEX(Projects!$B$5:$B$54,MATCH(C18,Projects!$A$5:$A$54,0)),"Unknown ID")) | Q18: =IF(A18="","",SUM(E18:P18)) | R18: =IF(A18="","",IFERROR(INDEX(Team!$K$5:$K$64,MATCH(A18,Team!$A$5:$A$64,0)),0)) | S18: =IF(A18="","",Q18*R18)
B19: =IF(A19="","",IFERROR(INDEX(Team!$B$5:$B$64,MATCH(A19,Team!$A$5:$A$64,0)),"Not in Team")) | D19: =IF(C19="","",IFERROR(INDEX(Projects!$B$5:$B$54,MATCH(C19,Projects!$A$5:$A$54,0)),"Unknown ID")) | Q19: =IF(A19="","",SUM(E19:P19)) | R19: =IF(A19="","",IFERROR(INDEX(Team!$K$5:$K$64,MATCH(A19,Team!$A$5:$A$64,0)),0)) | S19: =IF(A19="","",Q19*R19)
B20: =IF(A20="","",IFERROR(INDEX(Team!$B$5:$B$64,MATCH(A20,Team!$A$5:$A$64,0)),"Not in Team")) | D20: =IF(C20="","",IFERROR(INDEX(Projects!$B$5:$B$54,MATCH(C20,Projects!$A$5:$A$54,0)),"Unknown ID")) | Q20: =IF(A20="","",SUM(E20:P20)) | R20: =IF(A20="","",IFERROR(INDEX(Team!$K$5:$K$64,MATCH(A20,Team!$A$5:$A$64,0)),0)) | S20: =IF(A20="","",Q20*R20)
B21: =IF(A21="","",IFERROR(INDEX(Team!$B$5:$B$64,MATCH(A21,Team!$A$5:$A$64,0)),"Not in Team")) | D21: =IF(C21="","",IFERROR(INDEX(Projects!$B$5:$B$54,MATCH(C21,Projects!$A$5:$A$54,0)),"Unknown ID")) | Q21: =IF(A21="","",SUM(E21:P21)) | R21: =IF(A21="","",IFERROR(INDEX(Team!$K$5:$K$64,MATCH(A21,Team!$A$5:$A$64,0)),0)) | S21: =IF(A21="","",Q21*R21)
B22: =IF(A22="","",IFERROR(INDEX(Team!$B$5:$B$64,MATCH(A22,Team!$A$5:$A$64,0)),"Not in Team")) | D22: =IF(C22="","",IFERROR(INDEX(Projects!$B$5:$B$54,MATCH(C22,Projects!$A$5:$A$54,0)),"Unknown ID")) | Q22: =IF(A22="","",SUM(E22:P22)) | R22: =IF(A22="","",IFERROR(INDEX(Team!$K$5:$K$64,MATCH(A22,Team!$A$5:$A$64,0)),0)) | S22: =IF(A22="","",Q22*R22)
B23: =IF(A23="","",IFERROR(INDEX(Team!$B$5:$B$64,MATCH(A23,Team!$A$5:$A$64,0)),"Not in Team")) | D23: =IF(C23="","",IFERROR(INDEX(Projects!$B$5:$B$54,MATCH(C23,Projects!$A$5:$A$54,0)),"Unknown ID")) | Q23: =IF(A23="","",SUM(E23:P23)) | R23: =IF(A23="","",IFERROR(INDEX(Team!$K$5:$K$64,MATCH(A23,Team!$A$5:$A$64,0)),0)) | S23: =IF(A23="","",Q23*R23)
B24: =IF(A24="","",IFERROR(INDEX(Team!$B$5:$B$64,MATCH(A24,Team!$A$5:$A$64,0)),"Not in Team")) | D24: =IF(C24="","",IFERROR(INDEX(Projects!$B$5:$B$54,MATCH(C24,Projects!$A$5:$A$54,0)),"Unknown ID")) | Q24: =IF(A24="","",SUM(E24:P24)) | R24: =IF(A24="","",IFERROR(INDEX(Team!$K$5:$K$64,MATCH(A24,Team!$A$5:$A$64,0)),0)) | S24: =IF(A24="","",Q24*R24)
B25: =IF(A25="","",IFERROR(INDEX(Team!$B$5:$B$64,MATCH(A25,Team!$A$5:$A$64,0)),"Not in Team")) | D25: =IF(C25="","",IFERROR(INDEX(Projects!$B$5:$B$54,MATCH(C25,Projects!$A$5:$A$54,0)),"Unknown ID")) | Q25: =IF(A25="","",SUM(E25:P25)) | R25: =IF(A25="","",IFERROR(INDEX(Team!$K$5:$K$64,MATCH(A25,Team!$A$5:$A$64,0)),0)) | S25: =IF(A25="","",Q25*R25)
B26: =IF(A26="","",IFERROR(INDEX(Team!$B$5:$B$64,MATCH(A26,Team!$A$5:$A$64,0)),"Not in Team")) | D26: =IF(C26="","",IFERROR(INDEX(Projects!$B$5:$B$54,MATCH(C26,Projects!$A$5:$A$54,0)),"Unknown ID")) | Q26: =IF(A26="","",SUM(E26:P26)) | R26: =IF(A26="","",IFERROR(INDEX(Team!$K$5:$K$64,MATCH(A26,Team!$A$5:$A$64,0)),0)) | S26: =IF(A26="","",Q26*R26)
B27: =IF(A27="","",IFERROR(INDEX(Team!$B$5:$B$64,MATCH(A27,Team!$A$5:$A$64,0)),"Not in Team")) | D27: =IF(C27="","",IFERROR(INDEX(Projects!$B$5:$B$54,MATCH(C27,Projects!$A$5:$A$54,0)),"Unknown ID")) | Q27: =IF(A27="","",SUM(E27:P27)) | R27: =IF(A27="","",IFERROR(INDEX(Team!$K$5:$K$64,MATCH(A27,Team!$A$5:$A$64,0)),0)) | S27: =IF(A27="","",Q27*R27)
... B204: =IF(A204="","",IFERROR(INDEX(Team!$B$5:$B$64,MATCH(A204,Team!$A$5:$A$64,0)),"Not in Team")) | D204: =IF(C204="","",IFERROR(INDEX(Projects!$B$5:$B$54,MATCH(C204,Projects!$A$5:$A$54,0)),"Unknown ID")) | Q204: =IF(A204="","",SUM(E204:P204)) | R204: =IF(A204="","",IFERROR(INDEX(Team!$K$5:$K$64,MATCH(A204,Team!$A$5:$A$64,0)),0)) | S204: =IF(A204="","",Q204*R204)

Sheet Capacity
A1: Capacity & Utilization
A2: Fully calculated — no inputs. Red = over-allocated (>100%), amber = under 50%.
A4: Utilization (allocated ÷ capacity)
A5: Name | B5: Role | C5: Type | D5: =Settings!$A$8 -> 46388 | E5: =Settings!$A$9 -> 46419 | F5: =Settings!$A$10 -> 46447 | G5: =Settings!$A$11 -> 46478 | H5: =Settings!$A$12 -> 46508 | I5: =Settings!$A$13 -> 46539 | J5: =Settings!$A$14 -> 46569 | K5: =Settings!$A$15 -> 46600 | L5: =Settings!$A$16 -> 46631 | M5: =Settings!$A$17 -> 46661 | N5: =Settings!$A$18 -> 46692 | O5: =Settings!$A$19 -> 46722 | P5: Peak month | Q5: Annual | S5: 999% = work allocated in a month the person isn't available (before start / after end date).
A6: =IF(Team!$A5="","",Team!$A5) -> Tech Lead 1 | B6: =IF(Team!$A5="","",Team!$B5) -> Tech Lead | C6: =IF(Team!$A5="","",Team!$C5) -> FTE | D6: =IF($A6="","",IF(N(D70)=0,IF(N(D134)>0,9.99,""),D134/D70)) -> 1.0961538 | E6: =IF($A6="","",IF(N(E70)=0,IF(N(E134)>0,9.99,""),E134/E70)) -> 1.0961538 | F6: =IF($A6="","",IF(N(F70)=0,IF(N(F134)>0,9.99,""),F134/F70)) -> 1.352459 | G6: =IF($A6="","",IF(N(G70)=0,IF(N(G134)>0,9.99,""),G134/G70)) -> 1.352459 | H6: =IF($A6="","",IF(N(H70)=0,IF(N(H134)>0,9.99,""),H134/H70)) -> 1.0909091 | I6: =IF($A6="","",IF(N(I70)=0,IF(N(I134)>0,9.99,""),I134/I70)) -> 1.0862069 | J6: =IF($A6="","",IF(N(J70)=0,IF(N(J134)>0,9.99,""),J134/J70)) -> 1.0862069 | K6: =IF($A6="","",IF(N(K70)=0,IF(N(K134)>0,9.99,""),K134/K70)) -> 1.0819672 | ... O6: =IF($A6="","",IF(N(O70)=0,IF(N(O134)>0,9.99,""),O134/O70)) -> 0.81147541 | P6: =IF($A6="","",MAX(D6:O6)) -> 1.352459 | Q6: =IF(OR($A6="",N(P70)=0),"",P134/P70) -> 1.0419117
