Workbook

Sheet Start Here
B2: Portfolio Planner
B3: One row per project. Weekly columns across the year, grouped into four 13-week quarters.
B6: How it works
B7: 1. Set the start date | C7: On the Setup tab, enter the Monday that week 1 of your plan begins. Every date, quarter band and Gantt bar in the workbook shifts to match.
B8: 2. List your people | C8: Also on Setup: names and roles. These feed the Lead dropdown and the People Load tab.
B9: 3. Enter projects | C9: On Year Plan, fill the shaded columns: project, program, lead, team, status, start and end dates. The bar draws itself.
B10: 4. Read the quarter | C10: Quarter View shows 13 weeks at a time. Change the quarter number in the yellow cell to flip between Q1-Q4. Nothing else to touch.
B11: 5. Check the load | C11: People Load counts how many projects each person is on, week by week. Amber means two at once, red means three or more.
B13: What to edit
B14: Shaded cells | C14: Every cell you type into is shaded pale yellow. Everything else is a formula - leave it alone and it stays correct.
B15: Adding rows | C15: Insert rows inside the existing block (between the first and last project rows) so the formatting and formulas carry over.
B16: More people | C16: Add names in the Setup list and copy the last row of People Load down.
B18: Bar colours
B19: Not started | C19: Scoped but no work yet.
B20: On track | C20: Will land on the committed date.
B21: At risk | C21: Date is threatened; a decision or help is needed.
B22: Off track | C22: Date has moved or will move. Escalated.
B23: Complete | C23: Delivered to production.
B25: Worth knowing
B26: Quarters | C26: Quarters here are 13-week blocks counted from your start date, so they line up with sprints rather than with calendar month ends.
B27: Team names | C27: Type team members exactly as they appear in the Setup list, separated by commas. People Load matches on that spelling.
B28: Circulating it | C28: Nothing links to an outside file, so the workbook travels intact over email or SharePoint.

Sheet Setup
B2: Setup
B3: Change these and the whole workbook follows.
B5: Plan title | C5: Engineering Portfolio 2026-27
B6: Week 1 starts (Monday) | C6: 46272 | D6: 52 weeks are drawn from here
B9: People | E9: Lists
B10: Name | C10: Role | E10: Status | F10: Program / portfolio
B11: Priya Nathan | C11: Tech lead | E11: Not started | F11: Modernization
B12: Marcus Bell | C12: Senior engineer | E12: On track | F12: Regulatory
B13: Dana Okafor | C13: Senior engineer | E13: At risk | F13: Growth
B14: Ravi Menon | C14: Engineer | E14: Off track | F14: Platform / infra
B15: Ellen Vargas | C15: Engineer | E15: Complete | F15: Run the business
B16: Tom Whitfield | C16: SDET
B17: Grace Lin | C17: UX | E17: Fixed list - shared with the colour rules.
B18: Omar Haddad | C18: Engineer

Sheet Year Plan
A1: =Setup!C5 -> Engineering Portfolio 2026-27
A2: Yearly view - one row per project, one column per week
L3: =PlanStart -> 46272 | M3: =L3+7 -> 46279 | N3: =M3+7 -> 46286 | O3: =N3+7 -> 46293 | P3: =O3+7 -> 46300 | Q3: =P3+7 -> 46307 | R3: =Q3+7 -> 46314 | S3: =R3+7 -> 46321 | T3: =S3+7 -> 46328 | ... BK3: =BJ3+7 -> 46629
L4: Q1 | Y4: Q2 | AL4: Q3 | AY4: Q4
L5: =TEXT(L3,"mmm") -> Sep | M5: =TEXT(M3,"mmm") -> Sep | N5: =TEXT(N3,"mmm") -> Sep | O5: =TEXT(O3,"mmm") -> Sep | P5: =TEXT(P3,"mmm") -> Oct | Q5: =TEXT(Q3,"mmm") -> Oct | R5: =TEXT(R3,"mmm") -> Oct | S5: =TEXT(S3,"mmm") -> Oct | ... BK5: =TEXT(BK3,"mmm") -> Aug
A6: # | B6: Project | C6: Program | D6: Lead | E6: Team (comma separated) | F6: FTE | G6: Status | H6: Start | I6: End | J6: % done | K6: Notes | L6: W1 | M6: W2 | N6: W3 | O6: W4 | P6: W5 | Q6: W6 | R6: W7 | S6: W8 | T6: W9 | U6: W10 | V6: W11 | W6: W12 | X6: W13 | Y6: W14 | Z6: W15 | AA6: W16 | AB6: W17 | AC6: W18 | AD6: W19 | AE6: W20 | AF6: W21 | AG6: W22 | AH6: W23 | AI6: W24 | AJ6: W25 | AK6: W26 | AL6: W27 | AM6: W28 | AN6: W29 | AO6: W30 | AP6: W31 | AQ6: W32 | AR6: W33 | AS6: W34 | AT6: W35 | AU6: W36 | AV6: W37 | AW6: W38 | AX6: W39 | AY6: W40 | AZ6: W41 | BA6: W42 | BB6: W43 | BC6: W44 | BD6: W45 | BE6: W46 | BF6: W47 | BG6: W48 | BH6: W49 | BI6: W50 | BJ6: W51 | BK6: W52
A7: =IF(B7="","",COUNTA($B$7:B7)) -> 1 | B7: RepApp modernization - remaining 55% | C7: Modernization | D7: Priya Nathan | E7: Priya Nathan, Marcus Bell, Dana Okafor, Tom Whitfield | F7: 4 | G7: At risk | H7: =PlanStart+0 -> 46272 | I7: =PlanStart+179 -> 46451 | J7: 0.45 | K7: Strangler migration to Angular; scope cut to check contribution first | L7: =IF(OR($B7="",$H7="",$I7=""),"",IF(AND(L$3+6>=$H7,L$3<=$I7),1,"")) -> 1 | M7: =IF(OR($B7="",$H7="",$I7=""),"",IF(AND(M$3+6>=$H7,M$3<=$I7),1,"")) -> 1 | N7: =IF(OR($B7="",$H7="",$I7=""),"",IF(AND(N$3+6>=$H7,N$3<=$I7),1,"")) -> 1 | O7: =IF(OR($B7="",$H7="",$I7=""),"",IF(AND(O$3+6>=$H7,O$3<=$I7),1,"")) -> 1 | P7: =IF(OR($B7="",$H7="",$I7=""),"",IF(AND(P$3+6>=$H7,P$3<=$I7),1,"")) -> 1 | Q7: =IF(OR($B7="",$H7="",$I7=""),"",IF(AND(Q$3+6>=$H7,Q$3<=$I7),1,"")) -> 1 | R7: =IF(OR($B7="",$H7="",$I7=""),"",IF(AND(R$3+6>=$H7,R$3<=$I7),1,"")) -> 1 | S7: =IF(OR($B7="",$H7="",$I7=""),"",IF(AND(S$3+6>=$H7,S$3<=$I7),1,"")) -> 1 | ... BK7: =IF(OR($B7="",$H7="",$I7=""),"",IF(AND(BK$3+6>=$H7,BK$3<=$I7),1,"")) | BM7: =IF($E7="",",,",","&SUBSTITUTE($E7," ","")&",") -> ,PriyaNathan,MarcusBell,DanaOkafor,TomWhitfield,
A8: =IF(B8="","",COUNTA($B$7:B8)) -> 2 | B8: RepApp backend API hardening | C8: Modernization | D8: Marcus Bell | E8: Marcus Bell, Ravi Menon | F8: 2 | G8: On track | H8: =PlanStart+0 -> 46272 | I8: =PlanStart+88 -> 46360 | J8: 0.6 | K8: Owner left; rebuild API knowledge and docs | L8: =IF(OR($B8="",$H8="",$I8=""),"",IF(AND(L$3+6>=$H8,L$3<=$I8),1,"")) -> 1 | M8: =IF(OR($B8="",$H8="",$I8=""),"",IF(AND(M$3+6>=$H8,M$3<=$I8),1,"")) -> 1 | N8: =IF(OR($B8="",$H8="",$I8=""),"",IF(AND(N$3+6>=$H8,N$3<=$I8),1,"")) -> 1 | O8: =IF(OR($B8="",$H8="",$I8=""),"",IF(AND(O$3+6>=$H8,O$3<=$I8),1,"")) -> 1 | P8: =IF(OR($B8="",$H8="",$I8=""),"",IF(AND(P$3+6>=$H8,P$3<=$I8),1,"")) -> 1 | Q8: =IF(OR($B8="",$H8="",$I8=""),"",IF(AND(Q$3+6>=$H8,Q$3<=$I8),1,"")) -> 1 | R8: =IF(OR($B8="",$H8="",$I8=""),"",IF(AND(R$3+6>=$H8,R$3<=$I8),1,"")) -> 1 | S8: =IF(OR($B8="",$H8="",$I8=""),"",IF(AND(S$3+6>=$H8,S$3<=$I8),1,"")) -> 1 | ... BK8: =IF(OR($B8="",$H8="",$I8=""),"",IF(AND(BK$3+6>=$H8,BK$3<=$I8),1,"")) | BM8: =IF($E8="",",,",","&SUBSTITUTE($E8," ","")&",") -> ,MarcusBell,RaviMenon,
A9: =IF(B9="","",COUNTA($B$7:B9)) -> 3 | B9: Application portfolio dashboard | C9: Run the business | D9: Dana Okafor | E9: Dana Okafor, Ellen Vargas | F9: 1.5 | G9: On track | H9: =PlanStart+14 -> 46286 | I9: =PlanStart+74 -> 46346 | J9: 0.7 | K9: Excel inventory feeding Power BI for the manager group | L9: =IF(OR($B9="",$H9="",$I9=""),"",IF(AND(L$3+6>=$H9,L$3<=$I9),1,"")) | M9: =IF(OR($B9="",$H9="",$I9=""),"",IF(AND(M$3+6>=$H9,M$3<=$I9),1,"")) | N9: =IF(OR($B9="",$H9="",$I9=""),"",IF(AND(N$3+6>=$H9,N$3<=$I9),1,"")) -> 1 | O9: =IF(OR($B9="",$H9="",$I9=""),"",IF(AND(O$3+6>=$H9,O$3<=$I9),1,"")) -> 1 | P9: =IF(OR($B9="",$H9="",$I9=""),"",IF(AND(P$3+6>=$H9,P$3<=$I9),1,"")) -> 1 | Q9: =IF(OR($B9="",$H9="",$I9=""),"",IF(AND(Q$3+6>=$H9,Q$3<=$I9),1,"")) -> 1 | R9: =IF(OR($B9="",$H9="",$I9=""),"",IF(AND(R$3+6>=$H9,R$3<=$I9),1,"")) -> 1 | S9: =IF(OR($B9="",$H9="",$I9=""),"",IF(AND(S$3+6>=$H9,S$3<=$I9),1,"")) -> 1 | ... BK9: =IF(OR($B9="",$H9="",$I9=""),"",IF(AND(BK$3+6>=$H9,BK$3<=$I9),1,"")) | BM9: =IF($E9="",",,",","&SUBSTITUTE($E9," ","")&",") -> ,DanaOkafor,EllenVargas,
A10: =IF(B10="","",COUNTA($B$7:B10)) -> 4 | B10: Rep chat assistant - discovery | C10: Growth | D10: Grace Lin | E10: Grace Lin, Omar Haddad | F10: 1 | G10: Not started | H10: =PlanStart+98 -> 46370 | I10: =PlanStart+214 -> 46486 | J10: 0 | K10: Ontology layer and in-app chat for donor flows | L10: =IF(OR($B10="",$H10="",$I10=""),"",IF(AND(L$3+6>=$H10,L$3<=$I10),1,"")) | M10: =IF(OR($B10="",$H10="",$I10=""),"",IF(AND(M$3+6>=$H10,M$3<=$I10),1,"")) | N10: =IF(OR($B10="",$H10="",$I10=""),"",IF(AND(N$3+6>=$H10,N$3<=$I10),1,"")) | O10: =IF(OR($B10="",$H10="",$I10=""),"",IF(AND(O$3+6>=$H10,O$3<=$I10),1,"")) | P10: =IF(OR($B10="",$H10="",$I10=""),"",IF(AND(P$3+6>=$H10,P$3<=$I10),1,"")) | Q10: =IF(OR($B10="",$H10="",$I10=""),"",IF(AND(Q$3+6>=$H10,Q$3<=$I10),1,"")) | R10: =IF(OR($B10="",$H10="",$I10=""),"",IF(AND(R$3+6>=$H10,R$3<=$I10),1,"")) | S10: =IF(OR($B10="",$H10="",$I10=""),"",IF(AND(S$3+6>=$H10,S$3<=$I10),1,"")) | ... BK10: =IF(OR($B10="",$H10="",$I10=""),"",IF(AND(BK$3+6>=$H10,BK$3<=$I10),1,"")) | BM10: =IF($E10="",",,",","&SUBSTITUTE($E10," ","")&",") -> ,GraceLin,OmarHaddad,
A11: =IF(B11="","",COUNTA($B$7:B11)) -> 5 | B11: Quality gate remediation | C11: Platform / infra | D11: Tom Whitfield | E11: Tom Whitfield, Ravi Menon | F11: 1 | G11: On track | H11: =PlanStart+0 -> 46272 | I11: =PlanStart+144 -> 46416 | J11: 0.3 | K11: Sonar findings and CI/CD build stability | L11: =IF(OR($B11="",$H11="",$I11=""),"",IF(AND(L$3+6>=$H11,L$3<=$I11),1,"")) -> 1 | M11: =IF(OR($B11="",$H11="",$I11=""),"",IF(AND(M$3+6>=$H11,M$3<=$I11),1,"")) -> 1 | N11: =IF(OR($B11="",$H11="",$I11=""),"",IF(AND(N$3+6>=$H11,N$3<=$I11),1,"")) -> 1 | O11: =IF(OR($B11="",$H11="",$I11=""),"",IF(AND(O$3+6>=$H11,O$3<=$I11),1,"")) -> 1 | P11: =IF(OR($B11="",$H11="",$I11=""),"",IF(AND(P$3+6>=$H11,P$3<=$I11),1,"")) -> 1 | Q11: =IF(OR($B11="",$H11="",$I11=""),"",IF(AND(Q$3+6>=$H11,Q$3<=$I11),1,"")) -> 1 | R11: =IF(OR($B11="",$H11="",$I11=""),"",IF(AND(R$3+6>=$H11,R$3<=$I11),1,"")) -> 1 | S11: =IF(OR($B11="",$H11="",$I11=""),"",IF(AND(S$3+6>=$H11,S$3<=$I11),1,"")) -> 1 | ... BK11: =IF(OR($B11="",$H11="",$I11=""),"",IF(AND(BK$3+6>=$H11,BK$3<=$I11),1,"")) | BM11: =IF($E11="",",,",","&SUBSTITUTE($E11," ","")&",") -> ,TomWhitfield,RaviMenon,
A12: =IF(B12="","",COUNTA($B$7:B12)) -> 6 | B12: Sample row - delete me | C12: Regulatory | D12: Ellen Vargas | E12: Ellen Vargas, Omar Haddad | F12: 0.5 | G12: Complete | H12: =PlanStart+0 -> 46272 | I12: =PlanStart+46 -> 46318 | J12: 1 | K12: Shows the format the workbook expects | L12: =IF(OR($B12="",$H12="",$I12=""),"",IF(AND(L$3+6>=$H12,L$3<=$I12),1,"")) -> 1 | M12: =IF(OR($B12="",$H12="",$I12=""),"",IF(AND(M$3+6>=$H12,M$3<=$I12),1,"")) -> 1 | N12: =IF(OR($B12="",$H12="",$I12=""),"",IF(AND(N$3+6>=$H12,N$3<=$I12),1,"")) -> 1 | O12: =IF(OR($B12="",$H12="",$I12=""),"",IF(AND(O$3+6>=$H12,O$3<=$I12),1,"")) -> 1 | P12: =IF(OR($B12="",$H12="",$I12=""),"",IF(AND(P$3+6>=$H12,P$3<=$I12),1,"")) -> 1 | Q12: =IF(OR($B12="",$H12="",$I12=""),"",IF(AND(Q$3+6>=$H12,Q$3<=$I12),1,"")) -> 1 | R12: =IF(OR($B12="",$H12="",$I12=""),"",IF(AND(R$3+6>=$H12,R$3<=$I12),1,"")) -> 1 | S12: =IF(OR($B12="",$H12="",$I12=""),"",IF(AND(S$3+6>=$H12,S$3<=$I12),1,"")) | ... BK12: =IF(OR($B12="",$H12="",$I12=""),"",IF(AND(BK$3+6>=$H12,BK$3<=$I12),1,"")) | BM12: =IF($E12="",",,",","&SUBSTITUTE($E12," ","")&",") -> ,EllenVargas,OmarHaddad,
A13: =IF(B13="","",COUNTA($B$7:B13)) | L13: =IF(OR($B13="",$H13="",$I13=""),"",IF(AND(L$3+6>=$H13,L$3<=$I13),1,"")) | M13: =IF(OR($B13="",$H13="",$I13=""),"",IF(AND(M$3+6>=$H13,M$3<=$I13),1,"")) | N13: =IF(OR($B13="",$H13="",$I13=""),"",IF(AND(N$3+6>=$H13,N$3<=$I13),1,"")) | O13: =IF(OR($B13="",$H13="",$I13=""),"",IF(AND(O$3+6>=$H13,O$3<=$I13),1,"")) | P13: =IF(OR($B13="",$H13="",$I13=""),"",IF(AND(P$3+6>=$H13,P$3<=$I13),1,"")) | Q13: =IF(OR($B13="",$H13="",$I13=""),"",IF(AND(Q$3+6>=$H13,Q$3<=$I13),1,"")) | R13: =IF(OR($B13="",$H13="",$I13=""),"",IF(AND(R$3+6>=$H13,R$3<=$I13),1,"")) | S13: =IF(OR($B13="",$H13="",$I13=""),"",IF(AND(S$3+6>=$H13,S$3<=$I13),1,"")) | ... BK13: =IF(OR($B13="",$H13="",$I13=""),"",IF(AND(BK$3+6>=$H13,BK$3<=$I13),1,"")) | BM13: =IF($E13="",",,",","&SUBSTITUTE($E13," ","")&",") -> ,,
A14: =IF(B14="","",COUNTA($B$7:B14)) | L14: =IF(OR($B14="",$H14="",$I14=""),"",IF(AND(L$3+6>=$H14,L$3<=$I14),1,"")) | M14: =IF(OR($B14="",$H14="",$I14=""),"",IF(AND(M$3+6>=$H14,M$3<=$I14),1,"")) | N14: =IF(OR($B14="",$H14="",$I14=""),"",IF(AND(N$3+6>=$H14,N$3<=$I14),1,"")) | O14: =IF(OR($B14="",$H14="",$I14=""),"",IF(AND(O$3+6>=$H14,O$3<=$I14),1,"")) | P14: =IF(OR($B14="",$H14="",$I14=""),"",IF(AND(P$3+6>=$H14,P$3<=$I14),1,"")) | Q14: =IF(OR($B14="",$H14="",$I14=""),"",IF(AND(Q$3+6>=$H14,Q$3<=$I14),1,"")) | R14: =IF(OR($B14="",$H14="",$I14=""),"",IF(AND(R$3+6>=$H14,R$3<=$I14),1,"")) | S14: =IF(OR($B14="",$H14="",$I14=""),"",IF(AND(S$3+6>=$H14,S$3<=$I14),1,"")) | ... BK14: =IF(OR($B14="",$H14="",$I14=""),"",IF(AND(BK$3+6>=$H14,BK$3<=$I14),1,"")) | BM14: =IF($E14="",",,",","&SUBSTITUTE($E14," ","")&",") -> ,,
A15: =IF(B15="","",COUNTA($B$7:B15)) | L15: =IF(OR($B15="",$H15="",$I15=""),"",IF(AND(L$3+6>=$H15,L$3<=$I15),1,"")) | M15: =IF(OR($B15="",$H15="",$I15=""),"",IF(AND(M$3+6>=$H15,M$3<=$I15),1,"")) | N15: =IF(OR($B15="",$H15="",$I15=""),"",IF(AND(N$3+6>=$H15,N$3<=$I15),1,"")) | O15: =IF(OR($B15="",$H15="",$I15=""),"",IF(AND(O$3+6>=$H15,O$3<=$I15),1,"")) | P15: =IF(OR($B15="",$H15="",$I15=""),"",IF(AND(P$3+6>=$H15,P$3<=$I15),1,"")) | Q15: =IF(OR($B15="",$H15="",$I15=""),"",IF(AND(Q$3+6>=$H15,Q$3<=$I15),1,"")) | R15: =IF(OR($B15="",$H15="",$I15=""),"",IF(AND(R$3+6>=$H15,R$3<=$I15),1,"")) | S15: =IF(OR($B15="",$H15="",$I15=""),"",IF(AND(S$3+6>=$H15,S$3<=$I15),1,"")) | ... BK15: =IF(OR($B15="",$H15="",$I15=""),"",IF(AND(BK$3+6>=$H15,BK$3<=$I15),1,"")) | BM15: =IF($E15="",",,",","&SUBSTITUTE($E15," ","")&",") -> ,,
A16: =IF(B16="","",COUNTA($B$7:B16)) | L16: =IF(OR($B16="",$H16="",$I16=""),"",IF(AND(L$3+6>=$H16,L$3<=$I16),1,"")) | M16: =IF(OR($B16="",$H16="",$I16=""),"",IF(AND(M$3+6>=$H16,M$3<=$I16),1,"")) | N16: =IF(OR($B16="",$H16="",$I16=""),"",IF(AND(N$3+6>=$H16,N$3<=$I16),1,"")) | O16: =IF(OR($B16="",$H16="",$I16=""),"",IF(AND(O$3+6>=$H16,O$3<=$I16),1,"")) | P16: =IF(OR($B16="",$H16="",$I16=""),"",IF(AND(P$3+6>=$H16,P$3<=$I16),1,"")) | Q16: =IF(OR($B16="",$H16="",$I16=""),"",IF(AND(Q$3+6>=$H16,Q$3<=$I16),1,"")) | R16: =IF(OR($B16="",$H16="",$I16=""),"",IF(AND(R$3+6>=$H16,R$3<=$I16),1,"")) | S16: =IF(OR($B16="",$H16="",$I16=""),"",IF(AND(S$3+6>=$H16,S$3<=$I16),1,"")) | ... BK16: =IF(OR($B16="",$H16="",$I16=""),"",IF(AND(BK$3+6>=$H16,BK$3<=$I16),1,"")) | BM16: =IF($E16="",",,",","&SUBSTITUTE($E16," ","")&",") -> ,,
A17: =IF(B17="","",COUNTA($B$7:B17)) | L17: =IF(OR($B17="",$H17="",$I17=""),"",IF(AND(L$3+6>=$H17,L$3<=$I17),1,"")) | M17: =IF(OR($B17="",$H17="",$I17=""),"",IF(AND(M$3+6>=$H17,M$3<=$I17),1,"")) | N17: =IF(OR($B17="",$H17="",$I17=""),"",IF(AND(N$3+6>=$H17,N$3<=$I17),1,"")) | O17: =IF(OR($B17="",$H17="",$I17=""),"",IF(AND(O$3+6>=$H17,O$3<=$I17),1,"")) | P17: =IF(OR($B17="",$H17="",$I17=""),"",IF(AND(P$3+6>=$H17,P$3<=$I17),1,"")) | Q17: =IF(OR($B17="",$H17="",$I17=""),"",IF(AND(Q$3+6>=$H17,Q$3<=$I17),1,"")) | R17: =IF(OR($B17="",$H17="",$I17=""),"",IF(AND(R$3+6>=$H17,R$3<=$I17),1,"")) | S17: =IF(OR($B17="",$H17="",$I17=""),"",IF(AND(S$3+6>=$H17,S$3<=$I17),1,"")) | ... BK17: =IF(OR($B17="",$H17="",$I17=""),"",IF(AND(BK$3+6>=$H17,BK$3<=$I17),1,"")) | BM17: =IF($E17="",",,",","&SUBSTITUTE($E17," ","")&",") -> ,,
A18: =IF(B18="","",COUNTA($B$7:B18)) | L18: =IF(OR($B18="",$H18="",$I18=""),"",IF(AND(L$3+6>=$H18,L$3<=$I18),1,"")) | M18: =IF(OR($B18="",$H18="",$I18=""),"",IF(AND(M$3+6>=$H18,M$3<=$I18),1,"")) | N18: =IF(OR($B18="",$H18="",$I18=""),"",IF(AND(N$3+6>=$H18,N$3<=$I18),1,"")) | O18: =IF(OR($B18="",$H18="",$I18=""),"",IF(AND(O$3+6>=$H18,O$3<=$I18),1,"")) | P18: =IF(OR($B18="",$H18="",$I18=""),"",IF(AND(P$3+6>=$H18,P$3<=$I18),1,"")) | Q18: =IF(OR($B18="",$H18="",$I18=""),"",IF(AND(Q$3+6>=$H18,Q$3<=$I18),1,"")) | R18: =IF(OR($B18="",$H18="",$I18=""),"",IF(AND(R$3+6>=$H18,R$3<=$I18),1,"")) | S18: =IF(OR($B18="",$H18="",$I18=""),"",IF(AND(S$3+6>=$H18,S$3<=$I18),1,"")) | ... BK18: =IF(OR($B18="",$H18="",$I18=""),"",IF(AND(BK$3+6>=$H18,BK$3<=$I18),1,"")) | BM18: =IF($E18="",",,",","&SUBSTITUTE($E18," ","")&",") -> ,,
A19: =IF(B19="","",COUNTA($B$7:B19)) | L19: =IF(OR($B19="",$H19="",$I19=""),"",IF(AND(L$3+6>=$H19,L$3<=$I19),1,"")) | M19: =IF(OR($B19="",$H19="",$I19=""),"",IF(AND(M$3+6>=$H19,M$3<=$I19),1,"")) | N19: =IF(OR($B19="",$H19="",$I19=""),"",IF(AND(N$3+6>=$H19,N$3<=$I19),1,"")) | O19: =IF(OR($B19="",$H19="",$I19=""),"",IF(AND(O$3+6>=$H19,O$3<=$I19),1,"")) | P19: =IF(OR($B19="",$H19="",$I19=""),"",IF(AND(P$3+6>=$H19,P$3<=$I19),1,"")) | Q19: =IF(OR($B19="",$H19="",$I19=""),"",IF(AND(Q$3+6>=$H19,Q$3<=$I19),1,"")) | R19: =IF(OR($B19="",$H19="",$I19=""),"",IF(AND(R$3+6>=$H19,R$3<=$I19),1,"")) | S19: =IF(OR($B19="",$H19="",$I19=""),"",IF(AND(S$3+6>=$H19,S$3<=$I19),1,"")) | ... BK19: =IF(OR($B19="",$H19="",$I19=""),"",IF(AND(BK$3+6>=$H19,BK$3<=$I19),1,"")) | BM19: =IF($E19="",",,",","&SUBSTITUTE($E19," ","")&",") -> ,,
A20: =IF(B20="","",COUNTA($B$7:B20)) | L20: =IF(OR($B20="",$H20="",$I20=""),"",IF(AND(L$3+6>=$H20,L$3<=$I20),1,"")) | M20: =IF(OR($B20="",$H20="",$I20=""),"",IF(AND(M$3+6>=$H20,M$3<=$I20),1,"")) | N20: =IF(OR($B20="",$H20="",$I20=""),"",IF(AND(N$3+6>=$H20,N$3<=$I20),1,"")) | O20: =IF(OR($B20="",$H20="",$I20=""),"",IF(AND(O$3+6>=$H20,O$3<=$I20),1,"")) | P20: =IF(OR($B20="",$H20="",$I20=""),"",IF(AND(P$3+6>=$H20,P$3<=$I20),1,"")) | Q20: =IF(OR($B20="",$H20="",$I20=""),"",IF(AND(Q$3+6>=$H20,Q$3<=$I20),1,"")) | R20: =IF(OR($B20="",$H20="",$I20=""),"",IF(AND(R$3+6>=$H20,R$3<=$I20),1,"")) | S20: =IF(OR($B20="",$H20="",$I20=""),"",IF(AND(S$3+6>=$H20,S$3<=$I20),1,"")) | ... BK20: =IF(OR($B20="",$H20="",$I20=""),"",IF(AND(BK$3+6>=$H20,BK$3<=$I20),1,"")) | BM20: =IF($E20="",",,",","&SUBSTITUTE($E20," ","")&",") -> ,,
A21: =IF(B21="","",COUNTA($B$7:B21)) | L21: =IF(OR($B21="",$H21="",$I21=""),"",IF(AND(L$3+6>=$H21,L$3<=$I21),1,"")) | M21: =IF(OR($B21="",$H21="",$I21=""),"",IF(AND(M$3+6>=$H21,M$3<=$I21),1,"")) | N21: =IF(OR($B21="",$H21="",$I21=""),"",IF(AND(N$3+6>=$H21,N$3<=$I21),1,"")) | O21: =IF(OR($B21="",$H21="",$I21=""),"",IF(AND(O$3+6>=$H21,O$3<=$I21),1,"")) | P21: =IF(OR($B21="",$H21="",$I21=""),"",IF(AND(P$3+6>=$H21,P$3<=$I21),1,"")) | Q21: =IF(OR($B21="",$H21="",$I21=""),"",IF(AND(Q$3+6>=$H21,Q$3<=$I21),1,"")) | R21: =IF(OR($B21="",$H21="",$I21=""),"",IF(AND(R$3+6>=$H21,R$3<=$I21),1,"")) | S21: =IF(OR($B21="",$H21="",$I21=""),"",IF(AND(S$3+6>=$H21,S$3<=$I21),1,"")) | ... BK21: =IF(OR($B21="",$H21="",$I21=""),"",IF(AND(BK$3+6>=$H21,BK$3<=$I21),1,"")) | BM21: =IF($E21="",",,",","&SUBSTITUTE($E21," ","")&",") -> ,,
A22: =IF(B22="","",COUNTA($B$7:B22)) | L22: =IF(OR($B22="",$H22="",$I22=""),"",IF(AND(L$3+6>=$H22,L$3<=$I22),1,"")) | M22: =IF(OR($B22="",$H22="",$I22=""),"",IF(AND(M$3+6>=$H22,M$3<=$I22),1,"")) | N22: =IF(OR($B22="",$H22="",$I22=""),"",IF(AND(N$3+6>=$H22,N$3<=$I22),1,"")) | O22: =IF(OR($B22="",$H22="",$I22=""),"",IF(AND(O$3+6>=$H22,O$3<=$I22),1,"")) | P22: =IF(OR($B22="",$H22="",$I22=""),"",IF(AND(P$3+6>=$H22,P$3<=$I22),1,"")) | Q22: =IF(OR($B22="",$H22="",$I22=""),"",IF(AND(Q$3+6>=$H22,Q$3<=$I22),1,"")) | R22: =IF(OR($B22="",$H22="",$I22=""),"",IF(AND(R$3+6>=$H22,R$3<=$I22),1,"")) | S22: =IF(OR($B22="",$H22="",$I22=""),"",IF(AND(S$3+6>=$H22,S$3<=$I22),1,"")) | ... BK22: =IF(OR($B22="",$H22="",$I22=""),"",IF(AND(BK$3+6>=$H22,BK$3<=$I22),1,"")) | BM22: =IF($E22="",",,",","&SUBSTITUTE($E22," ","")&",") -> ,,
A23: =IF(B23="","",COUNTA($B$7:B23)) | L23: =IF(OR($B23="",$H23="",$I23=""),"",IF(AND(L$3+6>=$H23,L$3<=$I23),1,"")) | M23: =IF(OR($B23="",$H23="",$I23=""),"",IF(AND(M$3+6>=$H23,M$3<=$I23),1,"")) | N23: =IF(OR($B23="",$H23="",$I23=""),"",IF(AND(N$3+6>=$H23,N$3<=$I23),1,"")) | O23: =IF(OR($B23="",$H23="",$I23=""),"",IF(AND(O$3+6>=$H23,O$3<=$I23),1,"")) | P23: =IF(OR($B23="",$H23="",$I23=""),"",IF(AND(P$3+6>=$H23,P$3<=$I23),1,"")) | Q23: =IF(OR($B23="",$H23="",$I23=""),"",IF(AND(Q$3+6>=$H23,Q$3<=$I23),1,"")) | R23: =IF(OR($B23="",$H23="",$I23=""),"",IF(AND(R$3+6>=$H23,R$3<=$I23),1,"")) | S23: =IF(OR($B23="",$H23="",$I23=""),"",IF(AND(S$3+6>=$H23,S$3<=$I23),1,"")) | ... BK23: =IF(OR($B23="",$H23="",$I23=""),"",IF(AND(BK$3+6>=$H23,BK$3<=$I23),1,"")) | BM23: =IF($E23="",",,",","&SUBSTITUTE($E23," ","")&",") -> ,,
A24: =IF(B24="","",COUNTA($B$7:B24)) | L24: =IF(OR($B24="",$H24="",$I24=""),"",IF(AND(L$3+6>=$H24,L$3<=$I24),1,"")) | M24: =IF(OR($B24="",$H24="",$I24=""),"",IF(AND(M$3+6>=$H24,M$3<=$I24),1,"")) | N24: =IF(OR($B24="",$H24="",$I24=""),"",IF(AND(N$3+6>=$H24,N$3<=$I24),1,"")) | O24: =IF(OR($B24="",$H24="",$I24=""),"",IF(AND(O$3+6>=$H24,O$3<=$I24),1,"")) | P24: =IF(OR($B24="",$H24="",$I24=""),"",IF(AND(P$3+6>=$H24,P$3<=$I24),1,"")) | Q24: =IF(OR($B24="",$H24="",$I24=""),"",IF(AND(Q$3+6>=$H24,Q$3<=$I24),1,"")) | R24: =IF(OR($B24="",$H24="",$I24=""),"",IF(AND(R$3+6>=$H24,R$3<=$I24),1,"")) | S24: =IF(OR($B24="",$H24="",$I24=""),"",IF(AND(S$3+6>=$H24,S$3<=$I24),1,"")) | ... BK24: =IF(OR($B24="",$H24="",$I24=""),"",IF(AND(BK$3+6>=$H24,BK$3<=$I24),1,"")) | BM24: =IF($E24="",",,",","&SUBSTITUTE($E24," ","")&",") -> ,,
... A46: =IF(B46="","",COUNTA($B$7:B46)) | L46: =IF(OR($B46="",$H46="",$I46=""),"",IF(AND(L$3+6>=$H46,L$3<=$I46),1,"")) | M46: =IF(OR($B46="",$H46="",$I46=""),"",IF(AND(M$3+6>=$H46,M$3<=$I46),1,"")) | N46: =IF(OR($B46="",$H46="",$I46=""),"",IF(AND(N$3+6>=$H46,N$3<=$I46),1,"")) | O46: =IF(OR($B46="",$H46="",$I46=""),"",IF(AND(O$3+6>=$H46,O$3<=$I46),1,"")) | P46: =IF(OR($B46="",$H46="",$I46=""),"",IF(AND(P$3+6>=$H46,P$3<=$I46),1,"")) | Q46: =IF(OR($B46="",$H46="",$I46=""),"",IF(AND(Q$3+6>=$H46,Q$3<=$I46),1,"")) | R46: =IF(OR($B46="",$H46="",$I46=""),"",IF(AND(R$3+6>=$H46,R$3<=$I46),1,"")) | S46: =IF(OR($B46="",$H46="",$I46=""),"",IF(AND(S$3+6>=$H46,S$3<=$I46),1,"")) | ... BK46: =IF(OR($B46="",$H46="",$I46=""),"",IF(AND(BK$3+6>=$H46,BK$3<=$I46),1,"")) | BM46: =IF($E46="",",,",","&SUBSTITUTE($E46," ","")&",") -> ,,
A48: Active projects | C48: =COUNTIFS($G$7:$G$46,"On track")+COUNTIFS($G$7:$G$46,"At risk")+COUNTIFS($G$7:$G$46,"Off track") -> 4 | D48: At risk or off track | F48: =COUNTIFS($G$7:$G$46,"At risk")+COUNTIFS($G$7:$G$46,"Off track") -> 1 | G48: Total FTE booked | H48: =SUM($F$7:$F$46) -> 10

Sheet Quarter View
A1: =Setup!C5 -> Engineering Portfolio 2026-27
A2: Quarter | B2: 1 | C2: ="Weeks "&(($B$2-1)*13+1)&" to "&($B$2*13)&" | "&TEXT(INDEX('Year Plan'!$L$3:$BK$3,($B$2-1)*13+1),"dd mmm yyyy")&" - "&TEXT(INDEX('Year Plan'!$L$3:$BK$3,$B$2*13)+6,"dd mmm yyyy") -> Weeks 1 to 13 | 07 Sep 2026 - 06 Dec 2026
H3: =INDEX('Year Plan'!$L$3:$BK$3,($B$2-1)*13+H$5) -> 46272 | I3: =INDEX('Year Plan'!$L$3:$BK$3,($B$2-1)*13+I$5) -> 46279 | J3: =INDEX('Year Plan'!$L$3:$BK$3,($B$2-1)*13+J$5) -> 46286 | K3: =INDEX('Year Plan'!$L$3:$BK$3,($B$2-1)*13+K$5) -> 46293 | L3: =INDEX('Year Plan'!$L$3:$BK$3,($B$2-1)*13+L$5) -> 46300 | M3: =INDEX('Year Plan'!$L$3:$BK$3,($B$2-1)*13+M$5) -> 46307 | N3: =INDEX('Year Plan'!$L$3:$BK$3,($B$2-1)*13+N$5) -> 46314 | O3: =INDEX('Year Plan'!$L$3:$BK$3,($B$2-1)*13+O$5) -> 46321 | ... T3: =INDEX('Year Plan'!$L$3:$BK$3,($B$2-1)*13+T$5) -> 46356
H5: 1 | I5: 2 | J5: 3 | K5: 4 | L5: 5 | M5: 6 | N5: 7 | O5: 8 | P5: 9 | Q5: 10 | R5: 11 | S5: 12 | T5: 13
A6: Project | B6: Lead | C6: Team | D6: Status | E6: Start | F6: End | G6: % done | H6: ="W"&(($B$2-1)*13+H$5) -> W1 | I6: ="W"&(($B$2-1)*13+I$5) -> W2 | J6: ="W"&(($B$2-1)*13+J$5) -> W3 | K6: ="W"&(($B$2-1)*13+K$5) -> W4 | L6: ="W"&(($B$2-1)*13+L$5) -> W5 | M6: ="W"&(($B$2-1)*13+M$5) -> W6 | N6: ="W"&(($B$2-1)*13+N$5) -> W7 | O6: ="W"&(($B$2-1)*13+O$5) -> W8 | ... T6: ="W"&(($B$2-1)*13+T$5) -> W13
A7: =IF('Year Plan'!$B7="","",'Year Plan'!$B7) -> RepApp modernization - remaining 55% | B7: =IF('Year Plan'!$B7="","",'Year Plan'!$D7) -> Priya Nathan | C7: =IF('Year Plan'!$B7="","",'Year Plan'!$E7) -> Priya Nathan, Marcus Bell, Dana Okafor, Tom Whitfield | D7: =IF('Year Plan'!$B7="","",'Year Plan'!$G7) -> At risk | E7: =IF('Year Plan'!$B7="","",'Year Plan'!$H7) -> 46272 | F7: =IF('Year Plan'!$B7="","",'Year Plan'!$I7) -> 46451 | G7: =IF('Year Plan'!$B7="","",'Year Plan'!$J7) -> 0.45 | H7: =IF($A7="","",IF(INDEX('Year Plan'!$L7:$BK7,($B$2-1)*13+H$5)=1,1,"")) -> 1 | I7: =IF($A7="","",IF(INDEX('Year Plan'!$L7:$BK7,($B$2-1)*13+I$5)=1,1,"")) -> 1 | J7: =IF($A7="","",IF(INDEX('Year Plan'!$L7:$BK7,($B$2-1)*13+J$5)=1,1,"")) -> 1 | K7: =IF($A7="","",IF(INDEX('Year Plan'!$L7:$BK7,($B$2-1)*13+K$5)=1,1,"")) -> 1 | L7: =IF($A7="","",IF(INDEX('Year Plan'!$L7:$BK7,($B$2-1)*13+L$5)=1,1,"")) -> 1 | M7: =IF($A7="","",IF(INDEX('Year Plan'!$L7:$BK7,($B$2-1)*13+M$5)=1,1,"")) -> 1 | N7: =IF($A7="","",IF(INDEX('Year Plan'!$L7:$BK7,($B$2-1)*13+N$5)=1,1,"")) -> 1 | O7: =IF($A7="","",IF(INDEX('Year Plan'!$L7:$BK7,($B$2-1)*13+O$5)=1,1,"")) -> 1 | ... T7: =IF($A7="","",IF(INDEX('Year Plan'!$L7:$BK7,($B$2-1)*13+T$5)=1,1,"")) -> 1
A8: =IF('Year Plan'!$B8="","",'Year Plan'!$B8) -> RepApp backend API hardening | B8: =IF('Year Plan'!$B8="","",'Year Plan'!$D8) -> Marcus Bell | C8: =IF('Year Plan'!$B8="","",'Year Plan'!$E8) -> Marcus Bell, Ravi Menon | D8: =IF('Year Plan'!$B8="","",'Year Plan'!$G8) -> On track | E8: =IF('Year Plan'!$B8="","",'Year Plan'!$H8) -> 46272 | F8: =IF('Year Plan'!$B8="","",'Year Plan'!$I8) -> 46360 | G8: =IF('Year Plan'!$B8="","",'Year Plan'!$J8) -> 0.6 | H8: =IF($A8="","",IF(INDEX('Year Plan'!$L8:$BK8,($B$2-1)*13+H$5)=1,1,"")) -> 1 | I8: =IF($A8="","",IF(INDEX('Year Plan'!$L8:$BK8,($B$2-1)*13+I$5)=1,1,"")) -> 1 | J8: =IF($A8="","",IF(INDEX('Year Plan'!$L8:$BK8,($B$2-1)*13+J$5)=1,1,"")) -> 1 | K8: =IF($A8="","",IF(INDEX('Year Plan'!$L8:$BK8,($B$2-1)*13+K$5)=1,1,"")) -> 1 | L8: =IF($A8="","",IF(INDEX('Year Plan'!$L8:$BK8,($B$2-1)*13+L$5)=1,1,"")) -> 1 | M8: =IF($A8="","",IF(INDEX('Year Plan'!$L8:$BK8,($B$2-1)*13+M$5)=1,1,"")) -> 1 | N8: =IF($A8="","",IF(INDEX('Year Plan'!$L8:$BK8,($B$2-1)*13+N$5)=1,1,"")) -> 1 | O8: =IF($A8="","",IF(INDEX('Year Plan'!$L8:$BK8,($B$2-1)*13+O$5)=1,1,"")) -> 1 | ... T8: =IF($A8="","",IF(INDEX('Year Plan'!$L8:$BK8,($B$2-1)*13+T$5)=1,1,"")) -> 1
A9: =IF('Year Plan'!$B9="","",'Year Plan'!$B9) -> Application portfolio dashboard | B9: =IF('Year Plan'!$B9="","",'Year Plan'!$D9) -> Dana Okafor | C9: =IF('Year Plan'!$B9="","",'Year Plan'!$E9) -> Dana Okafor, Ellen Vargas | D9: =IF('Year Plan'!$B9="","",'Year Plan'!$G9) -> On track | E9: =IF('Year Plan'!$B9="","",'Year Plan'!$H9) -> 46286 | F9: =IF('Year Plan'!$B9="","",'Year Plan'!$I9) -> 46346 | G9: =IF('Year Plan'!$B9="","",'Year Plan'!$J9) -> 0.7 | H9: =IF($A9="","",IF(INDEX('Year Plan'!$L9:$BK9,($B$2-1)*13+H$5)=1,1,"")) | I9: =IF($A9="","",IF(INDEX('Year Plan'!$L9:$BK9,($B$2-1)*13+I$5)=1,1,"")) | J9: =IF($A9="","",IF(INDEX('Year Plan'!$L9:$BK9,($B$2-1)*13+J$5)=1,1,"")) -> 1 | K9: =IF($A9="","",IF(INDEX('Year Plan'!$L9:$BK9,($B$2-1)*13+K$5)=1,1,"")) -> 1 | L9: =IF($A9="","",IF(INDEX('Year Plan'!$L9:$BK9,($B$2-1)*13+L$5)=1,1,"")) -> 1 | M9: =IF($A9="","",IF(INDEX('Year Plan'!$L9:$BK9,($B$2-1)*13+M$5)=1,1,"")) -> 1 | N9: =IF($A9="","",IF(INDEX('Year Plan'!$L9:$BK9,($B$2-1)*13+N$5)=1,1,"")) -> 1 | O9: =IF($A9="","",IF(INDEX('Year Plan'!$L9:$BK9,($B$2-1)*13+O$5)=1,1,"")) -> 1 | ... T9: =IF($A9="","",IF(INDEX('Year Plan'!$L9:$BK9,($B$2-1)*13+T$5)=1,1,""))
A10: =IF('Year Plan'!$B10="","",'Year Plan'!$B10) -> Rep chat assistant - discovery | B10: =IF('Year Plan'!$B10="","",'Year Plan'!$D10) -> Grace Lin | C10: =IF('Year Plan'!$B10="","",'Year Plan'!$E10) -> Grace Lin, Omar Haddad | D10: =IF('Year Plan'!$B10="","",'Year Plan'!$G10) -> Not started | E10: =IF('Year Plan'!$B10="","",'Year Plan'!$H10) -> 46370 | F10: =IF('Year Plan'!$B10="","",'Year Plan'!$I10) -> 46486 | G10: =IF('Year Plan'!$B10="","",'Year Plan'!$J10) -> 0 | H10: =IF($A10="","",IF(INDEX('Year Plan'!$L10:$BK10,($B$2-1)*13+H$5)=1,1,"")) | I10: =IF($A10="","",IF(INDEX('Year Plan'!$L10:$BK10,($B$2-1)*13+I$5)=1,1,"")) | J10: =IF($A10="","",IF(INDEX('Year Plan'!$L10:$BK10,($B$2-1)*13+J$5)=1,1,"")) | K10: =IF($A10="","",IF(INDEX('Year Plan'!$L10:$BK10,($B$2-1)*13+K$5)=1,1,"")) | L10: =IF($A10="","",IF(INDEX('Year Plan'!$L10:$BK10,($B$2-1)*13+L$5)=1,1,"")) | M10: =IF($A10="","",IF(INDEX('Year Plan'!$L10:$BK10,($B$2-1)*13+M$5)=1,1,"")) | N10: =IF($A10="","",IF(INDEX('Year Plan'!$L10:$BK10,($B$2-1)*13+N$5)=1,1,"")) | O10: =IF($A10="","",IF(INDEX('Year Plan'!$L10:$BK10,($B$2-1)*13+O$5)=1,1,"")) | ... T10: =IF($A10="","",IF(INDEX('Year Plan'!$L10:$BK10,($B$2-1)*13+T$5)=1,1,""))
A11: =IF('Year Plan'!$B11="","",'Year Plan'!$B11) -> Quality gate remediation | B11: =IF('Year Plan'!$B11="","",'Year Plan'!$D11) -> Tom Whitfield | C11: =IF('Year Plan'!$B11="","",'Year Plan'!$E11) -> Tom Whitfield, Ravi Menon | D11: =IF('Year Plan'!$B11="","",'Year Plan'!$G11) -> On track | E11: =IF('Year Plan'!$B11="","",'Year Plan'!$H11) -> 46272 | F11: =IF('Year Plan'!$B11="","",'Year Plan'!$I11) -> 46416 | G11: =IF('Year Plan'!$B11="","",'Year Plan'!$J11) -> 0.3 | H11: =IF($A11="","",IF(INDEX('Year Plan'!$L11:$BK11,($B$2-1)*13+H$5)=1,1,"")) -> 1 | I11: =IF($A11="","",IF(INDEX('Year Plan'!$L11:$BK11,($B$2-1)*13+I$5)=1,1,"")) -> 1 | J11: =IF($A11="","",IF(INDEX('Year Plan'!$L11:$BK11,($B$2-1)*13+J$5)=1,1,"")) -> 1 | K11: =IF($A11="","",IF(INDEX('Year Plan'!$L11:$BK11,($B$2-1)*13+K$5)=1,1,"")) -> 1 | L11: =IF($A11="","",IF(INDEX('Year Plan'!$L11:$BK11,($B$2-1)*13+L$5)=1,1,"")) -> 1 | M11: =IF($A11="","",IF(INDEX('Year Plan'!$L11:$BK11,($B$2-1)*13+M$5)=1,1,"")) -> 1 | N11: =IF($A11="","",IF(INDEX('Year Plan'!$L11:$BK11,($B$2-1)*13+N$5)=1,1,"")) -> 1 | O11: =IF($A11="","",IF(INDEX('Year Plan'!$L11:$BK11,($B$2-1)*13+O$5)=1,1,"")) -> 1 | ... T11: =IF($A11="","",IF(INDEX('Year Plan'!$L11:$BK11,($B$2-1)*13+T$5)=1,1,"")) -> 1
A12: =IF('Year Plan'!$B12="","",'Year Plan'!$B12) -> Sample row - delete me | B12: =IF('Year Plan'!$B12="","",'Year Plan'!$D12) -> Ellen Vargas | C12: =IF('Year Plan'!$B12="","",'Year Plan'!$E12) -> Ellen Vargas, Omar Haddad | D12: =IF('Year Plan'!$B12="","",'Year Plan'!$G12) -> Complete | E12: =IF('Year Plan'!$B12="","",'Year Plan'!$H12) -> 46272 | F12: =IF('Year Plan'!$B12="","",'Year Plan'!$I12) -> 46318 | G12: =IF('Year Plan'!$B12="","",'Year Plan'!$J12) -> 1 | H12: =IF($A12="","",IF(INDEX('Year Plan'!$L12:$BK12,($B$2-1)*13+H$5)=1,1,"")) -> 1 | I12: =IF($A12="","",IF(INDEX('Year Plan'!$L12:$BK12,($B$2-1)*13+I$5)=1,1,"")) -> 1 | J12: =IF($A12="","",IF(INDEX('Year Plan'!$L12:$BK12,($B$2-1)*13+J$5)=1,1,"")) -> 1 | K12: =IF($A12="","",IF(INDEX('Year Plan'!$L12:$BK12,($B$2-1)*13+K$5)=1,1,"")) -> 1 | L12: =IF($A12="","",IF(INDEX('Year Plan'!$L12:$BK12,($B$2-1)*13+L$5)=1,1,"")) -> 1 | M12: =IF($A12="","",IF(INDEX('Year Plan'!$L12:$BK12,($B$2-1)*13+M$5)=1,1,"")) -> 1 | N12: =IF($A12="","",IF(INDEX('Year Plan'!$L12:$BK12,($B$2-1)*13+N$5)=1,1,"")) -> 1 | O12: =IF($A12="","",IF(INDEX('Year Plan'!$L12:$BK12,($B$2-1)*13+O$5)=1,1,"")) | ... T12: =IF($A12="","",IF(INDEX('Year Plan'!$L12:$BK12,($B$2-1)*13+T$5)=1,1,""))
A13: =IF('Year Plan'!$B13="","",'Year Plan'!$B13) | B13: =IF('Year Plan'!$B13="","",'Year Plan'!$D13) | C13: =IF('Year Plan'!$B13="","",'Year Plan'!$E13) | D13: =IF('Year Plan'!$B13="","",'Year Plan'!$G13) | E13: =IF('Year Plan'!$B13="","",'Year Plan'!$H13) | F13: =IF('Year Plan'!$B13="","",'Year Plan'!$I13) | G13: =IF('Year Plan'!$B13="","",'Year Plan'!$J13) | H13: =IF($A13="","",IF(INDEX('Year Plan'!$L13:$BK13,($B$2-1)*13+H$5)=1,1,"")) | I13: =IF($A13="","",IF(INDEX('Year Plan'!$L13:$BK13,($B$2-1)*13+I$5)=1,1,"")) | J13: =IF($A13="","",IF(INDEX('Year Plan'!$L13:$BK13,($B$2-1)*13+J$5)=1,1,"")) | K13: =IF($A13="","",IF(INDEX('Year Plan'!$L13:$BK13,($B$2-1)*13+K$5)=1,1,"")) | L13: =IF($A13="","",IF(INDEX('Year Plan'!$L13:$BK13,($B$2-1)*13+L$5)=1,1,"")) | M13: =IF($A13="","",IF(INDEX('Year Plan'!$L13:$BK13,($B$2-1)*13+M$5)=1,1,"")) | N13: =IF($A13="","",IF(INDEX('Year Plan'!$L13:$BK13,($B$2-1)*13+N$5)=1,1,"")) | O13: =IF($A13="","",IF(INDEX('Year Plan'!$L13:$BK13,($B$2-1)*13+O$5)=1,1,"")) | ... T13: =IF($A13="","",IF(INDEX('Year Plan'!$L13:$BK13,($B$2-1)*13+T$5)=1,1,""))
A14: =IF('Year Plan'!$B14="","",'Year Plan'!$B14) | B14: =IF('Year Plan'!$B14="","",'Year Plan'!$D14) | C14: =IF('Year Plan'!$B14="","",'Year Plan'!$E14) | D14: =IF('Year Plan'!$B14="","",'Year Plan'!$G14) | E14: =IF('Year Plan'!$B14="","",'Year Plan'!$H14) | F14: =IF('Year Plan'!$B14="","",'Year Plan'!$I14) | G14: =IF('Year Plan'!$B14="","",'Year Plan'!$J14) | H14: =IF($A14="","",IF(INDEX('Year Plan'!$L14:$BK14,($B$2-1)*13+H$5)=1,1,"")) | I14: =IF($A14="","",IF(INDEX('Year Plan'!$L14:$BK14,($B$2-1)*13+I$5)=1,1,"")) | J14: =IF($A14="","",IF(INDEX('Year Plan'!$L14:$BK14,($B$2-1)*13+J$5)=1,1,"")) | K14: =IF($A14="","",IF(INDEX('Year Plan'!$L14:$BK14,($B$2-1)*13+K$5)=1,1,"")) | L14: =IF($A14="","",IF(INDEX('Year Plan'!$L14:$BK14,($B$2-1)*13+L$5)=1,1,"")) | M14: =IF($A14="","",IF(INDEX('Year Plan'!$L14:$BK14,($B$2-1)*13+M$5)=1,1,"")) | N14: =IF($A14="","",IF(INDEX('Year Plan'!$L14:$BK14,($B$2-1)*13+N$5)=1,1,"")) | O14: =IF($A14="","",IF(INDEX('Year Plan'!$L14:$BK14,($B$2-1)*13+O$5)=1,1,"")) | ... T14: =IF($A14="","",IF(INDEX('Year Plan'!$L14:$BK14,($B$2-1)*13+T$5)=1,1,""))
A15: =IF('Year Plan'!$B15="","",'Year Plan'!$B15) | B15: =IF('Year Plan'!$B15="","",'Year Plan'!$D15) | C15: =IF('Year Plan'!$B15="","",'Year Plan'!$E15) | D15: =IF('Year Plan'!$B15="","",'Year Plan'!$G15) | E15: =IF('Year Plan'!$B15="","",'Year Plan'!$H15) | F15: =IF('Year Plan'!$B15="","",'Year Plan'!$I15) | G15: =IF('Year Plan'!$B15="","",'Year Plan'!$J15) | H15: =IF($A15="","",IF(INDEX('Year Plan'!$L15:$BK15,($B$2-1)*13+H$5)=1,1,"")) | I15: =IF($A15="","",IF(INDEX('Year Plan'!$L15:$BK15,($B$2-1)*13+I$5)=1,1,"")) | J15: =IF($A15="","",IF(INDEX('Year Plan'!$L15:$BK15,($B$2-1)*13+J$5)=1,1,"")) | K15: =IF($A15="","",IF(INDEX('Year Plan'!$L15:$BK15,($B$2-1)*13+K$5)=1,1,"")) | L15: =IF($A15="","",IF(INDEX('Year Plan'!$L15:$BK15,($B$2-1)*13+L$5)=1,1,"")) | M15: =IF($A15="","",IF(INDEX('Year Plan'!$L15:$BK15,($B$2-1)*13+M$5)=1,1,"")) | N15: =IF($A15="","",IF(INDEX('Year Plan'!$L15:$BK15,($B$2-1)*13+N$5)=1,1,"")) | O15: =IF($A15="","",IF(INDEX('Year Plan'!$L15:$BK15,($B$2-1)*13+O$5)=1,1,"")) | ... T15: =IF($A15="","",IF(INDEX('Year Plan'!$L15:$BK15,($B$2-1)*13+T$5)=1,1,""))
A16: =IF('Year Plan'!$B16="","",'Year Plan'!$B16) | B16: =IF('Year Plan'!$B16="","",'Year Plan'!$D16) | C16: =IF('Year Plan'!$B16="","",'Year Plan'!$E16) | D16: =IF('Year Plan'!$B16="","",'Year Plan'!$G16) | E16: =IF('Year Plan'!$B16="","",'Year Plan'!$H16) | F16: =IF('Year Plan'!$B16="","",'Year Plan'!$I16) | G16: =IF('Year Plan'!$B16="","",'Year Plan'!$J16) | H16: =IF($A16="","",IF(INDEX('Year Plan'!$L16:$BK16,($B$2-1)*13+H$5)=1,1,"")) | I16: =IF($A16="","",IF(INDEX('Year Plan'!$L16:$BK16,($B$2-1)*13+I$5)=1,1,"")) | J16: =IF($A16="","",IF(INDEX('Year Plan'!$L16:$BK16,($B$2-1)*13+J$5)=1,1,"")) | K16: =IF($A16="","",IF(INDEX('Year Plan'!$L16:$BK16,($B$2-1)*13+K$5)=1,1,"")) | L16: =IF($A16="","",IF(INDEX('Year Plan'!$L16:$BK16,($B$2-1)*13+L$5)=1,1,"")) | M16: =IF($A16="","",IF(INDEX('Year Plan'!$L16:$BK16,($B$2-1)*13+M$5)=1,1,"")) | N16: =IF($A16="","",IF(INDEX('Year Plan'!$L16:$BK16,($B$2-1)*13+N$5)=1,1,"")) | O16: =IF($A16="","",IF(INDEX('Year Plan'!$L16:$BK16,($B$2-1)*13+O$5)=1,1,"")) | ... T16: =IF($A16="","",IF(INDEX('Year Plan'!$L16:$BK16,($B$2-1)*13+T$5)=1,1,""))
A17: =IF('Year Plan'!$B17="","",'Year Plan'!$B17) | B17: =IF('Year Plan'!$B17="","",'Year Plan'!$D17) | C17: =IF('Year Plan'!$B17="","",'Year Plan'!$E17) | D17: =IF('Year Plan'!$B17="","",'Year Plan'!$G17) | E17: =IF('Year Plan'!$B17="","",'Year Plan'!$H17) | F17: =IF('Year Plan'!$B17="","",'Year Plan'!$I17) | G17: =IF('Year Plan'!$B17="","",'Year Plan'!$J17) | H17: =IF($A17="","",IF(INDEX('Year Plan'!$L17:$BK17,($B$2-1)*13+H$5)=1,1,"")) | I17: =IF($A17="","",IF(INDEX('Year Plan'!$L17:$BK17,($B$2-1)*13+I$5)=1,1,"")) | J17: =IF($A17="","",IF(INDEX('Year Plan'!$L17:$BK17,($B$2-1)*13+J$5)=1,1,"")) | K17: =IF($A17="","",IF(INDEX('Year Plan'!$L17:$BK17,($B$2-1)*13+K$5)=1,1,"")) | L17: =IF($A17="","",IF(INDEX('Year Plan'!$L17:$BK17,($B$2-1)*13+L$5)=1,1,"")) | M17: =IF($A17="","",IF(INDEX('Year Plan'!$L17:$BK17,($B$2-1)*13+M$5)=1,1,"")) | N17: =IF($A17="","",IF(INDEX('Year Plan'!$L17:$BK17,($B$2-1)*13+N$5)=1,1,"")) | O17: =IF($A17="","",IF(INDEX('Year Plan'!$L17:$BK17,($B$2-1)*13+O$5)=1,1,"")) | ... T17: =IF($A17="","",IF(INDEX('Year Plan'!$L17:$BK17,($B$2-1)*13+T$5)=1,1,""))
A18: =IF('Year Plan'!$B18="","",'Year Plan'!$B18) | B18: =IF('Year Plan'!$B18="","",'Year Plan'!$D18) | C18: =IF('Year Plan'!$B18="","",'Year Plan'!$E18) | D18: =IF('Year Plan'!$B18="","",'Year Plan'!$G18) | E18: =IF('Year Plan'!$B18="","",'Year Plan'!$H18) | F18: =IF('Year Plan'!$B18="","",'Year Plan'!$I18) | G18: =IF('Year Plan'!$B18="","",'Year Plan'!$J18) | H18: =IF($A18="","",IF(INDEX('Year Plan'!$L18:$BK18,($B$2-1)*13+H$5)=1,1,"")) | I18: =IF($A18="","",IF(INDEX('Year Plan'!$L18:$BK18,($B$2-1)*13+I$5)=1,1,"")) | J18: =IF($A18="","",IF(INDEX('Year Plan'!$L18:$BK18,($B$2-1)*13+J$5)=1,1,"")) | K18: =IF($A18="","",IF(INDEX('Year Plan'!$L18:$BK18,($B$2-1)*13+K$5)=1,1,"")) | L18: =IF($A18="","",IF(INDEX('Year Plan'!$L18:$BK18,($B$2-1)*13+L$5)=1,1,"")) | M18: =IF($A18="","",IF(INDEX('Year Plan'!$L18:$BK18,($B$2-1)*13+M$5)=1,1,"")) | N18: =IF($A18="","",IF(INDEX('Year Plan'!$L18:$BK18,($B$2-1)*13+N$5)=1,1,"")) | O18: =IF($A18="","",IF(INDEX('Year Plan'!$L18:$BK18,($B$2-1)*13+O$5)=1,1,"")) | ... T18: =IF($A18="","",IF(INDEX('Year Plan'!$L18:$BK18,($B$2-1)*13+T$5)=1,1,""))
... A46: =IF('Year Plan'!$B46="","",'Year Plan'!$B46) | B46: =IF('Year Plan'!$B46="","",'Year Plan'!$D46) | C46: =IF('Year Plan'!$B46="","",'Year Plan'!$E46) | D46: =IF('Year Plan'!$B46="","",'Year Plan'!$G46) | E46: =IF('Year Plan'!$B46="","",'Year Plan'!$H46) | F46: =IF('Year Plan'!$B46="","",'Year Plan'!$I46) | G46: =IF('Year Plan'!$B46="","",'Year Plan'!$J46) | H46: =IF($A46="","",IF(INDEX('Year Plan'!$L46:$BK46,($B$2-1)*13+H$5)=1,1,"")) | I46: =IF($A46="","",IF(INDEX('Year Plan'!$L46:$BK46,($B$2-1)*13+I$5)=1,1,"")) | J46: =IF($A46="","",IF(INDEX('Year Plan'!$L46:$BK46,($B$2-1)*13+J$5)=1,1,"")) | K46: =IF($A46="","",IF(INDEX('Year Plan'!$L46:$BK46,($B$2-1)*13+K$5)=1,1,"")) | L46: =IF($A46="","",IF(INDEX('Year Plan'!$L46:$BK46,($B$2-1)*13+L$5)=1,1,"")) | M46: =IF($A46="","",IF(INDEX('Year Plan'!$L46:$BK46,($B$2-1)*13+M$5)=1,1,"")) | N46: =IF($A46="","",IF(INDEX('Year Plan'!$L46:$BK46,($B$2-1)*13+N$5)=1,1,"")) | O46: =IF($A46="","",IF(INDEX('Year Plan'!$L46:$BK46,($B$2-1)*13+O$5)=1,1,"")) | ... T46: =IF($A46="","",IF(INDEX('Year Plan'!$L46:$BK46,($B$2-1)*13+T$5)=1,1,""))

Sheet People Load
A1: Who is on what, week by week
A2: Counts concurrent projects per person. Two at once is amber, three or more is red.
D3: ='Year Plan'!L3 -> 46272 | E3: ='Year Plan'!M3 -> 46279 | F3: ='Year Plan'!N3 -> 46286 | G3: ='Year Plan'!O3 -> 46293 | H3: ='Year Plan'!P3 -> 46300 | I3: ='Year Plan'!Q3 -> 46307 | J3: ='Year Plan'!R3 -> 46314 | K3: ='Year Plan'!S3 -> 46321 | ... BC3: ='Year Plan'!BK3 -> 46629
D4: Q1 | Q4: Q2 | AD4: Q3 | AQ4: Q4
A6: Person | B6: Role | C6: Projects | D6: W1 | E6: W2 | F6: W3 | G6: W4 | H6: W5 | I6: W6 | J6: W7 | K6: W8 | L6: W9 | M6: W10 | N6: W11 | O6: W12 | P6: W13 | Q6: W14 | R6: W15 | S6: W16 | T6: W17 | U6: W18 | V6: W19 | W6: W20 | X6: W21 | Y6: W22 | Z6: W23 | AA6: W24 | AB6: W25 | AC6: W26 | AD6: W27 | AE6: W28 | AF6: W29 | AG6: W30 | AH6: W31 | AI6: W32 | AJ6: W33 | AK6: W34 | AL6: W35 | AM6: W36 | AN6: W37 | AO6: W38 | AP6: W39 | AQ6: W40 | AR6: W41 | AS6: W42 | AT6: W43 | AU6: W44 | AV6: W45 | AW6: W46 | AX6: W47 | AY6: W48 | AZ6: W49 | BA6: W50 | BB6: W51 | BC6: W52
A7: =IF(Setup!$B$11="","",Setup!$B$11) -> Priya Nathan | B7: =IF(Setup!$B$11="","",Setup!$C$11) -> Tech lead | C7: =IF($A7="","",SUMPRODUCT(--ISNUMBER(SEARCH(","&SUBSTITUTE($A7," ","")&",",'Year Plan'!$BM$7:$BM$46)))) -> 1 | D7: =IF($A7="","",SUMPRODUCT(--ISNUMBER(SEARCH(","&SUBSTITUTE($A7," ","")&",",'Year Plan'!$BM$7:$BM$46)),--('Year Plan'!$H$7:$H$46<>""),--('Year Plan'!$H$7:$H$46<=D$3+6),--('Year Plan'!$I$7:$I$46>=D$3))) -> 1 | E7: =IF($A7="","",SUMPRODUCT(--ISNUMBER(SEARCH(","&SUBSTITUTE($A7," ","")&",",'Year Plan'!$BM$7:$BM$46)),--('Year Plan'!$H$7:$H$46<>""),--('Year Plan'!$H$7:$H$46<=E$3+6),--('Year Plan'!$I$7:$I$46>=E$3))) -> 1 | F7: =IF($A7="","",SUMPRODUCT(--ISNUMBER(SEARCH(","&SUBSTITUTE($A7," ","")&",",'Year Plan'!$BM$7:$BM$46)),--('Year Plan'!$H$7:$H$46<>""),--('Year Plan'!$H$7:$H$46<=F$3+6),--('Year Plan'!$I$7:$I$46>=F$3))) -> 1 | G7: =IF($A7="","",SUMPRODUCT(--ISNUMBER(SEARCH(","&SUBSTITUTE($A7," ","")&",",'Year Plan'!$BM$7:$BM$46)),--('Year Plan'!$H$7:$H$46<>""),--('Year Plan'!$H$7:$H$46<=G$3+6),--('Year Plan'!$I$7:$I$46>=G$3))) -> 1 | H7: =IF($A7="","",SUMPRODUCT(--ISNUMBER(SEARCH(","&SUBSTITUTE($A7," ","")&",",'Year Plan'!$BM$7:$BM$46)),--('Year Plan'!$H$7:$H$46<>""),--('Year Plan'!$H$7:$H$46<=H$3+6),--('Year Plan'!$I$7:$I$46>=H$3))) -> 1 | I7: =IF($A7="","",SUMPRODUCT(--ISNUMBER(SEARCH(","&SUBSTITUTE($A7," ","")&",",'Year Plan'!$BM$7:$BM$46)),--('Year Plan'!$H$7:$H$46<>""),--('Year Plan'!$H$7:$H$46<=I$3+6),--('Year Plan'!$I$7:$I$46>=I$3))) -> 1 | J7: =IF($A7="","",SUMPRODUCT(--ISNUMBER(SEARCH(","&SUBSTITUTE($A7," ","")&",",'Year Plan'!$BM$7:$BM$46)),--('Year Plan'!$H$7:$H$46<>""),--('Year Plan'!$H$7:$H$46<=J$3+6),--('Year Plan'!$I$7:$I$46>=J$3))) -> 1 | K7: =IF($A7="","",SUMPRODUCT(--ISNUMBER(SEARCH(","&SUBSTITUTE($A7," ","")&",",'Year Plan'!$BM$7:$BM$46)),--('Year Plan'!$H$7:$H$46<>""),--('Year Plan'!$H$7:$H$46<=K$3+6),--('Year Plan'!$I$7:$I$46>=K$3))) -> 1 | ... BC7: =IF($A7="","",SUMPRODUCT(--ISNUMBER(SEARCH(","&SUBSTITUTE($A7," ","")&",",'Year Plan'!$BM$7:$BM$46)),--('Year Plan'!$H$7:$H$46<>""),--('Year Plan'!$H$7:$H$46<=BC$3+6),--('Year Plan'!$I$7:$I$46>=BC$3))) -> 0
A8: =IF(Setup!$B$12="","",Setup!$B$12) -> Marcus Bell | B8: =IF(Setup!$B$12="","",Setup!$C$12) -> Senior engineer | C8: =IF($A8="","",SUMPRODUCT(--ISNUMBER(SEARCH(","&SUBSTITUTE($A8," ","")&",",'Year Plan'!$BM$7:$BM$46)))) -> 2 | D8: =IF($A8="","",SUMPRODUCT(--ISNUMBER(SEARCH(","&SUBSTITUTE($A8," ","")&",",'Year Plan'!$BM$7:$BM$46)),--('Year Plan'!$H$7:$H$46<>""),--('Year Plan'!$H$7:$H$46<=D$3+6),--('Year Plan'!$I$7:$I$46>=D$3))) -> 2 | E8: =IF($A8="","",SUMPRODUCT(--ISNUMBER(SEARCH(","&SUBSTITUTE($A8," ","")&",",'Year Plan'!$BM$7:$BM$46)),--('Year Plan'!$H$7:$H$46<>""),--('Year Plan'!$H$7:$H$46<=E$3+6),--('Year Plan'!$I$7:$I$46>=E$3))) -> 2 | F8: =IF($A8="","",SUMPRODUCT(--ISNUMBER(SEARCH(","&SUBSTITUTE($A8," ","")&",",'Year Plan'!$BM$7:$BM$46)),--('Year Plan'!$H$7:$H$46<>""),--('Year Plan'!$H$7:$H$46<=F$3+6),--('Year Plan'!$I$7:$I$46>=F$3))) -> 2 | G8: =IF($A8="","",SUMPRODUCT(--ISNUMBER(SEARCH(","&SUBSTITUTE($A8," ","")&",",'Year Plan'!$BM$7:$BM$46)),--('Year Plan'!$H$7:$H$46<>""),--('Year Plan'!$H$7:$H$46<=G$3+6),--('Year Plan'!$I$7:$I$46>=G$3))) -> 2 | H8: =IF($A8="","",SUMPRODUCT(--ISNUMBER(SEARCH(","&SUBSTITUTE($A8," ","")&",",'Year Plan'!$BM$7:$BM$46)),--('Year Plan'!$H$7:$H$46<>""),--('Year Plan'!$H$7:$H$46<=H$3+6),--('Year Plan'!$I$7:$I$46>=H$3))) -> 2 | I8: =IF($A8="","",SUMPRODUCT(--ISNUMBER(SEARCH(","&SUBSTITUTE($A8," ","")&",",'Year Plan'!$BM$7:$BM$46)),--('Year Plan'!$H$7:$H$46<>""),--('Year Plan'!$H$7:$H$46<=I$3+6),--('Year Plan'!$I$7:$I$46>=I$3))) -> 2 | J8: =IF($A8="","",SUMPRODUCT(--ISNUMBER(SEARCH(","&SUBSTITUTE($A8," ","")&",",'Year Plan'!$BM$7:$BM$46)),--('Year Plan'!$H$7:$H$46<>""),--('Year Plan'!$H$7:$H$46<=J$3+6),--('Year Plan'!$I$7:$I$46>=J$3))) -> 2 | K8: =IF($A8="","",SUMPRODUCT(--ISNUMBER(SEARCH(","&SUBSTITUTE($A8," ","")&",",'Year Plan'!$BM$7:$BM$46)),--('Year Plan'!$H$7:$H$46<>""),--('Year Plan'!$H$7:$H$46<=K$3+6),--('Year Plan'!$I$7:$I$46>=K$3))) -> 2 | ... BC8: =IF($A8="","",SUMPRODUCT(--ISNUMBER(SEARCH(","&SUBSTITUTE($A8," ","")&",",'Year Plan'!$BM$7:$BM$46)),--('Year Plan'!$H$7:$H$46<>""),--('Year Plan'!$H$7:$H$46<=BC$3+6),--('Year Plan'!$I$7:$I$46>=BC$3))) -> 0
A9: =IF(Setup!$B$13="","",Setup!$B$13) -> Dana Okafor | B9: =IF(Setup!$B$13="","",Setup!$C$13) -> Senior engineer | C9: =IF($A9="","",SUMPRODUCT(--ISNUMBER(SEARCH(","&SUBSTITUTE($A9," ","")&",",'Year Plan'!$BM$7:$BM$46)))) -> 2 | D9: =IF($A9="","",SUMPRODUCT(--ISNUMBER(SEARCH(","&SUBSTITUTE($A9," ","")&",",'Year Plan'!$BM$7:$BM$46)),--('Year Plan'!$H$7:$H$46<>""),--('Year Plan'!$H$7:$H$46<=D$3+6),--('Year Plan'!$I$7:$I$46>=D$3))) -> 1 | E9: =IF($A9="","",SUMPRODUCT(--ISNUMBER(SEARCH(","&SUBSTITUTE($A9," ","")&",",'Year Plan'!$BM$7:$BM$46)),--('Year Plan'!$H$7:$H$46<>""),--('Year Plan'!$H$7:$H$46<=E$3+6),--('Year Plan'!$I$7:$I$46>=E$3))) -> 1 | F9: =IF($A9="","",SUMPRODUCT(--ISNUMBER(SEARCH(","&SUBSTITUTE($A9," ","")&",",'Year Plan'!$BM$7:$BM$46)),--('Year Plan'!$H$7:$H$46<>""),--('Year Plan'!$H$7:$H$46<=F$3+6),--('Year Plan'!$I$7:$I$46>=F$3))) -> 2 | G9: =IF($A9="","",SUMPRODUCT(--ISNUMBER(SEARCH(","&SUBSTITUTE($A9," ","")&",",'Year Plan'!$BM$7:$BM$46)),--('Year Plan'!$H$7:$H$46<>""),--('Year Plan'!$H$7:$H$46<=G$3+6),--('Year Plan'!$I$7:$I$46>=G$3))) -> 2 | H9: =IF($A9="","",SUMPRODUCT(--ISNUMBER(SEARCH(","&SUBSTITUTE($A9," ","")&",",'Year Plan'!$BM$7:$BM$46)),--('Year Plan'!$H$7:$H$46<>""),--('Year Plan'!$H$7:$H$46<=H$3+6),--('Year Plan'!$I$7:$I$46>=H$3))) -> 2 | I9: =IF($A9="","",SUMPRODUCT(--ISNUMBER(SEARCH(","&SUBSTITUTE($A9," ","")&",",'Year Plan'!$BM$7:$BM$46)),--('Year Plan'!$H$7:$H$46<>""),--('Year Plan'!$H$7:$H$46<=I$3+6),--('Year Plan'!$I$7:$I$46>=I$3))) -> 2 | J9: =IF($A9="","",SUMPRODUCT(--ISNUMBER(SEARCH(","&SUBSTITUTE($A9," ","")&",",'Year Plan'!$BM$7:$BM$46)),--('Year Plan'!$H$7:$H$46<>""),--('Year Plan'!$H$7:$H$46<=J$3+6),--('Year Plan'!$I$7:$I$46>=J$3))) -> 2 | K9: =IF($A9="","",SUMPRODUCT(--ISNUMBER(SEARCH(","&SUBSTITUTE($A9," ","")&",",'Year Plan'!$BM$7:$BM$46)),--('Year Plan'!$H$7:$H$46<>""),--('Year Plan'!$H$7:$H$46<=K$3+6),--('Year Plan'!$I$7:$I$46>=K$3))) -> 2 | ... BC9: =IF($A9="","",SUMPRODUCT(--ISNUMBER(SEARCH(","&SUBSTITUTE($A9," ","")&",",'Year Plan'!$BM$7:$BM$46)),--('Year Plan'!$H$7:$H$46<>""),--('Year Plan'!$H$7:$H$46<=BC$3+6),--('Year Plan'!$I$7:$I$46>=BC$3))) -> 0
A10: =IF(Setup!$B$14="","",Setup!$B$14) -> Ravi Menon | B10: =IF(Setup!$B$14="","",Setup!$C$14) -> Engineer | C10: =IF($A10="","",SUMPRODUCT(--ISNUMBER(SEARCH(","&SUBSTITUTE($A10," ","")&",",'Year Plan'!$BM$7:$BM$46)))) -> 2 | D10: =IF($A10="","",SUMPRODUCT(--ISNUMBER(SEARCH(","&SUBSTITUTE($A10," ","")&",",'Year Plan'!$BM$7:$BM$46)),--('Year Plan'!$H$7:$H$46<>""),--('Year Plan'!$H$7:$H$46<=D$3+6),--('Year Plan'!$I$7:$I$46>=D$3))) -> 2 | E10: =IF($A10="","",SUMPRODUCT(--ISNUMBER(SEARCH(","&SUBSTITUTE($A10," ","")&",",'Year Plan'!$BM$7:$BM$46)),--('Year Plan'!$H$7:$H$46<>""),--('Year Plan'!$H$7:$H$46<=E$3+6),--('Year Plan'!$I$7:$I$46>=E$3))) -> 2 | F10: =IF($A10="","",SUMPRODUCT(--ISNUMBER(SEARCH(","&SUBSTITUTE($A10," ","")&",",'Year Plan'!$BM$7:$BM$46)),--('Year Plan'!$H$7:$H$46<>""),--('Year Plan'!$H$7:$H$46<=F$3+6),--('Year Plan'!$I$7:$I$46>=F$3))) -> 2 | G10: =IF($A10="","",SUMPRODUCT(--ISNUMBER(SEARCH(","&SUBSTITUTE($A10," ","")&",",'Year Plan'!$BM$7:$BM$46)),--('Year Plan'!$H$7:$H$46<>""),--('Year Plan'!$H$7:$H$46<=G$3+6),--('Year Plan'!$I$7:$I$46>=G$3))) -> 2 | H10: =IF($A10="","",SUMPRODUCT(--ISNUMBER(SEARCH(","&SUBSTITUTE($A10," ","")&",",'Year Plan'!$BM$7:$BM$46)),--('Year Plan'!$H$7:$H$46<>""),--('Year Plan'!$H$7:$H$46<=H$3+6),--('Year Plan'!$I$7:$I$46>=H$3))) -> 2 | I10: =IF($A10="","",SUMPRODUCT(--ISNUMBER(SEARCH(","&SUBSTITUTE($A10," ","")&",",'Year Plan'!$BM$7:$BM$46)),--('Year Plan'!$H$7:$H$46<>""),--('Year Plan'!$H$7:$H$46<=I$3+6),--('Year Plan'!$I$7:$I$46>=I$3))) -> 2 | J10: =IF($A10="","",SUMPRODUCT(--ISNUMBER(SEARCH(","&SUBSTITUTE($A10," ","")&",",'Year Plan'!$BM$7:$BM$46)),--('Year Plan'!$H$7:$H$46<>""),--('Year Plan'!$H$7:$H$46<=J$3+6),--('Year Plan'!$I$7:$I$46>=J$3))) -> 2 | K10: =IF($A10="","",SUMPRODUCT(--ISNUMBER(SEARCH(","&SUBSTITUTE($A10," ","")&",",'Year Plan'!$BM$7:$BM$46)),--('Year Plan'!$H$7:$H$46<>""),--('Year Plan'!$H$7:$H$46<=K$3+6),--('Year Plan'!$I$7:$I$46>=K$3))) -> 2 | ... BC10: =IF($A10="","",SUMPRODUCT(--ISNUMBER(SEARCH(","&SUBSTITUTE($A10," ","")&",",'Year Plan'!$BM$7:$BM$46)),--('Year Plan'!$H$7:$H$46<>""),--('Year Plan'!$H$7:$H$46<=BC$3+6),--('Year Plan'!$I$7:$I$46>=BC$3))) -> 0
A11: =IF(Setup!$B$15="","",Setup!$B$15) -> Ellen Vargas | B11: =IF(Setup!$B$15="","",Setup!$C$15) -> Engineer | C11: =IF($A11="","",SUMPRODUCT(--ISNUMBER(SEARCH(","&SUBSTITUTE($A11," ","")&",",'Year Plan'!$BM$7:$BM$46)))) -> 2 | D11: =IF($A11="","",SUMPRODUCT(--ISNUMBER(SEARCH(","&SUBSTITUTE($A11," ","")&",",'Year Plan'!$BM$7:$BM$46)),--('Year Plan'!$H$7:$H$46<>""),--('Year Plan'!$H$7:$H$46<=D$3+6),--('Year Plan'!$I$7:$I$46>=D$3))) -> 1 | E11: =IF($A11="","",SUMPRODUCT(--ISNUMBER(SEARCH(","&SUBSTITUTE($A11," ","")&",",'Year Plan'!$BM$7:$BM$46)),--('Year Plan'!$H$7:$H$46<>""),--('Year Plan'!$H$7:$H$46<=E$3+6),--('Year Plan'!$I$7:$I$46>=E$3))) -> 1 | F11: =IF($A11="","",SUMPRODUCT(--ISNUMBER(SEARCH(","&SUBSTITUTE($A11," ","")&",",'Year Plan'!$BM$7:$BM$46)),--('Year Plan'!$H$7:$H$46<>""),--('Year Plan'!$H$7:$H$46<=F$3+6),--('Year Plan'!$I$7:$I$46>=F$3))) -> 2 | G11: =IF($A11="","",SUMPRODUCT(--ISNUMBER(SEARCH(","&SUBSTITUTE($A11," ","")&",",'Year Plan'!$BM$7:$BM$46)),--('Year Plan'!$H$7:$H$46<>""),--('Year Plan'!$H$7:$H$46<=G$3+6),--('Year Plan'!$I$7:$I$46>=G$3))) -> 2 | H11: =IF($A11="","",SUMPRODUCT(--ISNUMBER(SEARCH(","&SUBSTITUTE($A11," ","")&",",'Year Plan'!$BM$7:$BM$46)),--('Year Plan'!$H$7:$H$46<>""),--('Year Plan'!$H$7:$H$46<=H$3+6),--('Year Plan'!$I$7:$I$46>=H$3))) -> 2 | I11: =IF($A11="","",SUMPRODUCT(--ISNUMBER(SEARCH(","&SUBSTITUTE($A11," ","")&",",'Year Plan'!$BM$7:$BM$46)),--('Year Plan'!$H$7:$H$46<>""),--('Year Plan'!$H$7:$H$46<=I$3+6),--('Year Plan'!$I$7:$I$46>=I$3))) -> 2 | J11: =IF($A11="","",SUMPRODUCT(--ISNUMBER(SEARCH(","&SUBSTITUTE($A11," ","")&",",'Year Plan'!$BM$7:$BM$46)),--('Year Plan'!$H$7:$H$46<>""),--('Year Plan'!$H$7:$H$46<=J$3+6),--('Year Plan'!$I$7:$I$46>=J$3))) -> 2 | K11: =IF($A11="","",SUMPRODUCT(--ISNUMBER(SEARCH(","&SUBSTITUTE($A11," ","")&",",'Year Plan'!$BM$7:$BM$46)),--('Year Plan'!$H$7:$H$46<>""),--('Year Plan'!$H$7:$H$46<=K$3+6),--('Year Plan'!$I$7:$I$46>=K$3))) -> 1 | ... BC11: =IF($A11="","",SUMPRODUCT(--ISNUMBER(SEARCH(","&SUBSTITUTE($A11," ","")&",",'Year Plan'!$BM$7:$BM$46)),--('Year Plan'!$H$7:$H$46<>""),--('Year Plan'!$H$7:$H$46<=BC$3+6),--('Year Plan'!$I$7:$I$46>=BC$3))) -> 0
A12: =IF(Setup!$B$16="","",Setup!$B$16) -> Tom Whitfield | B12: =IF(Setup!$B$16="","",Setup!$C$16) -> SDET | C12: =IF($A12="","",SUMPRODUCT(--ISNUMBER(SEARCH(","&SUBSTITUTE($A12," ","")&",",'Year Plan'!$BM$7:$BM$46)))) -> 2 | D12: =IF($A12="","",SUMPRODUCT(--ISNUMBER(SEARCH(","&SUBSTITUTE($A12," ","")&",",'Year Plan'!$BM$7:$BM$46)),--('Year Plan'!$H$7:$H$46<>""),--('Year Plan'!$H$7:$H$46<=D$3+6),--('Year Plan'!$I$7:$I$46>=D$3))) -> 2 | E12: =IF($A12="","",SUMPRODUCT(--ISNUMBER(SEARCH(","&SUBSTITUTE($A12," ","")&",",'Year Plan'!$BM$7:$BM$46)),--('Year Plan'!$H$7:$H$46<>""),--('Year Plan'!$H$7:$H$46<=E$3+6),--('Year Plan'!$I$7:$I$46>=E$3))) -> 2 | F12: =IF($A12="","",SUMPRODUCT(--ISNUMBER(SEARCH(","&SUBSTITUTE($A12," ","")&",",'Year Plan'!$BM$7:$BM$46)),--('Year Plan'!$H$7:$H$46<>""),--('Year Plan'!$H$7:$H$46<=F$3+6),--('Year Plan'!$I$7:$I$46>=F$3))) -> 2 | G12: =IF($A12="","",SUMPRODUCT(--ISNUMBER(SEARCH(","&SUBSTITUTE($A12," ","")&",",'Year Plan'!$BM$7:$BM$46)),--('Year Plan'!$H$7:$H$46<>""),--('Year Plan'!$H$7:$H$46<=G$3+6),--('Year Plan'!$I$7:$I$46>=G$3))) -> 2 | H12: =IF($A12="","",SUMPRODUCT(--ISNUMBER(SEARCH(","&SUBSTITUTE($A12," ","")&",",'Year Plan'!$BM$7:$BM$46)),--('Year Plan'!$H$7:$H$46<>""),--('Year Plan'!$H$7:$H$46<=H$3+6),--('Year Plan'!$I$7:$I$46>=H$3))) -> 2 | I12: =IF($A12="","",SUMPRODUCT(--ISNUMBER(SEARCH(","&SUBSTITUTE($A12," ","")&",",'Year Plan'!$BM$7:$BM$46)),--('Year Plan'!$H$7:$H$46<>""),--('Year Plan'!$H$7:$H$46<=I$3+6),--('Year Plan'!$I$7:$I$46>=I$3))) -> 2 | J12: =IF($A12="","",SUMPRODUCT(--ISNUMBER(SEARCH(","&SUBSTITUTE($A12," ","")&",",'Year Plan'!$BM$7:$BM$46)),--('Year Plan'!$H$7:$H$46<>""),--('Year Plan'!$H$7:$H$46<=J$3+6),--('Year Plan'!$I$7:$I$46>=J$3))) -> 2 | K12: =IF($A12="","",SUMPRODUCT(--ISNUMBER(SEARCH(","&SUBSTITUTE($A12," ","")&",",'Year Plan'!$BM$7:$BM$46)),--('Year Plan'!$H$7:$H$46<>""),--('Year Plan'!$H$7:$H$46<=K$3+6),--('Year Plan'!$I$7:$I$46>=K$3))) -> 2 | ... BC12: =IF($A12="","",SUMPRODUCT(--ISNUMBER(SEARCH(","&SUBSTITUTE($A12," ","")&",",'Year Plan'!$BM$7:$BM$46)),--('Year Plan'!$H$7:$H$46<>""),--('Year Plan'!$H$7:$H$46<=BC$3+6),--('Year Plan'!$I$7:$I$46>=BC$3))) -> 0
A13: =IF(Setup!$B$17="","",Setup!$B$17) -> Grace Lin | B13: =IF(Setup!$B$17="","",Setup!$C$17) -> UX | C13: =IF($A13="","",SUMPRODUCT(--ISNUMBER(SEARCH(","&SUBSTITUTE($A13," ","")&",",'Year Plan'!$BM$7:$BM$46)))) -> 1 | D13: =IF($A13="","",SUMPRODUCT(--ISNUMBER(SEARCH(","&SUBSTITUTE($A13," ","")&",",'Year Plan'!$BM$7:$BM$46)),--('Year Plan'!$H$7:$H$46<>""),--('Year Plan'!$H$7:$H$46<=D$3+6),--('Year Plan'!$I$7:$I$46>=D$3))) -> 0 | E13: =IF($A13="","",SUMPRODUCT(--ISNUMBER(SEARCH(","&SUBSTITUTE($A13," ","")&",",'Year Plan'!$BM$7:$BM$46)),--('Year Plan'!$H$7:$H$46<>""),--('Year Plan'!$H$7:$H$46<=E$3+6),--('Year Plan'!$I$7:$I$46>=E$3))) -> 0 | F13: =IF($A13="","",SUMPRODUCT(--ISNUMBER(SEARCH(","&SUBSTITUTE($A13," ","")&",",'Year Plan'!$BM$7:$BM$46)),--('Year Plan'!$H$7:$H$46<>""),--('Year Plan'!$H$7:$H$46<=F$3+6),--('Year Plan'!$I$7:$I$46>=F$3))) -> 0 | G13: =IF($A13="","",SUMPRODUCT(--ISNUMBER(SEARCH(","&SUBSTITUTE($A13," ","")&",",'Year Plan'!$BM$7:$BM$46)),--('Year Plan'!$H$7:$H$46<>""),--('Year Plan'!$H$7:$H$46<=G$3+6),--('Year Plan'!$I$7:$I$46>=G$3))) -> 0 | H13: =IF($A13="","",SUMPRODUCT(--ISNUMBER(SEARCH(","&SUBSTITUTE($A13," ","")&",",'Year Plan'!$BM$7:$BM$46)),--('Year Plan'!$H$7:$H$46<>""),--('Year Plan'!$H$7:$H$46<=H$3+6),--('Year Plan'!$I$7:$I$46>=H$3))) -> 0 | I13: =IF($A13="","",SUMPRODUCT(--ISNUMBER(SEARCH(","&SUBSTITUTE($A13," ","")&",",'Year Plan'!$BM$7:$BM$46)),--('Year Plan'!$H$7:$H$46<>""),--('Year Plan'!$H$7:$H$46<=I$3+6),--('Year Plan'!$I$7:$I$46>=I$3))) -> 0 | J13: =IF($A13="","",SUMPRODUCT(--ISNUMBER(SEARCH(","&SUBSTITUTE($A13," ","")&",",'Year Plan'!$BM$7:$BM$46)),--('Year Plan'!$H$7:$H$46<>""),--('Year Plan'!$H$7:$H$46<=J$3+6),--('Year Plan'!$I$7:$I$46>=J$3))) -> 0 | K13: =IF($A13="","",SUMPRODUCT(--ISNUMBER(SEARCH(","&SUBSTITUTE($A13," ","")&",",'Year Plan'!$BM$7:$BM$46)),--('Year Plan'!$H$7:$H$46<>""),--('Year Plan'!$H$7:$H$46<=K$3+6),--('Year Plan'!$I$7:$I$46>=K$3))) -> 0 | ... BC13: =IF($A13="","",SUMPRODUCT(--ISNUMBER(SEARCH(","&SUBSTITUTE($A13," ","")&",",'Year Plan'!$BM$7:$BM$46)),--('Year Plan'!$H$7:$H$46<>""),--('Year Plan'!$H$7:$H$46<=BC$3+6),--('Year Plan'!$I$7:$I$46>=BC$3))) -> 0
A14: =IF(Setup!$B$18="","",Setup!$B$18) -> Omar Haddad | B14: =IF(Setup!$B$18="","",Setup!$C$18) -> Engineer | C14: =IF($A14="","",SUMPRODUCT(--ISNUMBER(SEARCH(","&SUBSTITUTE($A14," ","")&",",'Year Plan'!$BM$7:$BM$46)))) -> 2 | D14: =IF($A14="","",SUMPRODUCT(--ISNUMBER(SEARCH(","&SUBSTITUTE($A14," ","")&",",'Year Plan'!$BM$7:$BM$46)),--('Year Plan'!$H$7:$H$46<>""),--('Year Plan'!$H$7:$H$46<=D$3+6),--('Year Plan'!$I$7:$I$46>=D$3))) -> 1 | E14: =IF($A14="","",SUMPRODUCT(--ISNUMBER(SEARCH(","&SUBSTITUTE($A14," ","")&",",'Year Plan'!$BM$7:$BM$46)),--('Year Plan'!$H$7:$H$46<>""),--('Year Plan'!$H$7:$H$46<=E$3+6),--('Year Plan'!$I$7:$I$46>=E$3))) -> 1 | F14: =IF($A14="","",SUMPRODUCT(--ISNUMBER(SEARCH(","&SUBSTITUTE($A14," ","")&",",'Year Plan'!$BM$7:$BM$46)),--('Year Plan'!$H$7:$H$46<>""),--('Year Plan'!$H$7:$H$46<=F$3+6),--('Year Plan'!$I$7:$I$46>=F$3))) -> 1 | G14: =IF($A14="","",SUMPRODUCT(--ISNUMBER(SEARCH(","&SUBSTITUTE($A14," ","")&",",'Year Plan'!$BM$7:$BM$46)),--('Year Plan'!$H$7:$H$46<>""),--('Year Plan'!$H$7:$H$46<=G$3+6),--('Year Plan'!$I$7:$I$46>=G$3))) -> 1 | H14: =IF($A14="","",SUMPRODUCT(--ISNUMBER(SEARCH(","&SUBSTITUTE($A14," ","")&",",'Year Plan'!$BM$7:$BM$46)),--('Year Plan'!$H$7:$H$46<>""),--('Year Plan'!$H$7:$H$46<=H$3+6),--('Year Plan'!$I$7:$I$46>=H$3))) -> 1 | I14: =IF($A14="","",SUMPRODUCT(--ISNUMBER(SEARCH(","&SUBSTITUTE($A14," ","")&",",'Year Plan'!$BM$7:$BM$46)),--('Year Plan'!$H$7:$H$46<>""),--('Year Plan'!$H$7:$H$46<=I$3+6),--('Year Plan'!$I$7:$I$46>=I$3))) -> 1 | J14: =IF($A14="","",SUMPRODUCT(--ISNUMBER(SEARCH(","&SUBSTITUTE($A14," ","")&",",'Year Plan'!$BM$7:$BM$46)),--('Year Plan'!$H$7:$H$46<>""),--('Year Plan'!$H$7:$H$46<=J$3+6),--('Year Plan'!$I$7:$I$46>=J$3))) -> 1 | K14: =IF($A14="","",SUMPRODUCT(--ISNUMBER(SEARCH(","&SUBSTITUTE($A14," ","")&",",'Year Plan'!$BM$7:$BM$46)),--('Year Plan'!$H$7:$H$46<>""),--('Year Plan'!$H$7:$H$46<=K$3+6),--('Year Plan'!$I$7:$I$46>=K$3))) -> 0 | ... BC14: =IF($A14="","",SUMPRODUCT(--ISNUMBER(SEARCH(","&SUBSTITUTE($A14," ","")&",",'Year Plan'!$BM$7:$BM$46)),--('Year Plan'!$H$7:$H$46<>""),--('Year Plan'!$H$7:$H$46<=BC$3+6),--('Year Plan'!$I$7:$I$46>=BC$3))) -> 0
A15: =IF(Setup!$B$19="","",Setup!$B$19) | B15: =IF(Setup!$B$19="","",Setup!$C$19) | C15: =IF($A15="","",SUMPRODUCT(--ISNUMBER(SEARCH(","&SUBSTITUTE($A15," ","")&",",'Year Plan'!$BM$7:$BM$46)))) | D15: =IF($A15="","",SUMPRODUCT(--ISNUMBER(SEARCH(","&SUBSTITUTE($A15," ","")&",",'Year Plan'!$BM$7:$BM$46)),--('Year Plan'!$H$7:$H$46<>""),--('Year Plan'!$H$7:$H$46<=D$3+6),--('Year Plan'!$I$7:$I$46>=D$3))) | E15: =IF($A15="","",SUMPRODUCT(--ISNUMBER(SEARCH(","&SUBSTITUTE($A15," ","")&",",'Year Plan'!$BM$7:$BM$46)),--('Year Plan'!$H$7:$H$46<>""),--('Year Plan'!$H$7:$H$46<=E$3+6),--('Year Plan'!$I$7:$I$46>=E$3))) | F15: =IF($A15="","",SUMPRODUCT(--ISNUMBER(SEARCH(","&SUBSTITUTE($A15," ","")&",",'Year Plan'!$BM$7:$BM$46)),--('Year Plan'!$H$7:$H$46<>""),--('Year Plan'!$H$7:$H$46<=F$3+6),--('Year Plan'!$I$7:$I$46>=F$3))) | G15: =IF($A15="","",SUMPRODUCT(--ISNUMBER(SEARCH(","&SUBSTITUTE($A15," ","")&",",'Year Plan'!$BM$7:$BM$46)),--('Year Plan'!$H$7:$H$46<>""),--('Year Plan'!$H$7:$H$46<=G$3+6),--('Year Plan'!$I$7:$I$46>=G$3))) | H15: =IF($A15="","",SUMPRODUCT(--ISNUMBER(SEARCH(","&SUBSTITUTE($A15," ","")&",",'Year Plan'!$BM$7:$BM$46)),--('Year Plan'!$H$7:$H$46<>""),--('Year Plan'!$H$7:$H$46<=H$3+6),--('Year Plan'!$I$7:$I$46>=H$3))) | I15: =IF($A15="","",SUMPRODUCT(--ISNUMBER(SEARCH(","&SUBSTITUTE($A15," ","")&",",'Year Plan'!$BM$7:$BM$46)),--('Year Plan'!$H$7:$H$46<>""),--('Year Plan'!$H$7:$H$46<=I$3+6),--('Year Plan'!$I$7:$I$46>=I$3))) | J15: =IF($A15="","",SUMPRODUCT(--ISNUMBER(SEARCH(","&SUBSTITUTE($A15," ","")&",",'Year Plan'!$BM$7:$BM$46)),--('Year Plan'!$H$7:$H$46<>""),--('Year Plan'!$H$7:$H$46<=J$3+6),--('Year Plan'!$I$7:$I$46>=J$3))) | K15: =IF($A15="","",SUMPRODUCT(--ISNUMBER(SEARCH(","&SUBSTITUTE($A15," ","")&",",'Year Plan'!$BM$7:$BM$46)),--('Year Plan'!$H$7:$H$46<>""),--('Year Plan'!$H$7:$H$46<=K$3+6),--('Year Plan'!$I$7:$I$46>=K$3))) | ... BC15: =IF($A15="","",SUMPRODUCT(--ISNUMBER(SEARCH(","&SUBSTITUTE($A15," ","")&",",'Year Plan'!$BM$7:$BM$46)),--('Year Plan'!$H$7:$H$46<>""),--('Year Plan'!$H$7:$H$46<=BC$3+6),--('Year Plan'!$I$7:$I$46>=BC$3)))
