Workbook

Sheet README
C2: How to use this workbook
C4: 1. Replace the sample data
C5: The 'App Inventory' sheet has the 18 column headers in place and no data.
C6: Paste your export starting at row 2, keeping the column order shown.
C7: Formulas read rows 2 to 1000, so anything you paste inside that range is picked up automatically.
C9: 2. Maintain the manager list
C10: On 'Dashboard', cells B11:B20 are the only cells you type into. They are shaded yellow with blue text.
C11: The name must match the Dev Manager spelling in App Inventory exactly, or the row returns zero.
C12: Ten rows are available. Leave unused rows blank; they stay empty on their own.
C14: 3. Check the cross-tab headers
C15: The three cross-tab blocks count against the text in their own header cells (Production, Concept, and so on).
C16: If a new App Stage or App Type appears in your data, retype a header to match it and the column follows.
... C41: whole numbers with 0 rather than blank or N/A where there is nothing to report.

Sheet App Inventory
A1: S.No | B1: App Id | C1: App Name | D1: App Stage | E1: Dev Manager | F1: App Type | G1: Platform | H1: Sonar quality gate | I1: Sonar last analysis | J1: TLM Status | K1: TLM EOL Date | L1: Days to TLM Target | M1: Codeql Warning | N1: Codeql Error | O1: MEND Critical | P1: MEND Medium | Q1: Secret Scanning | R1: Automation coverage

Sheet Dashboard
B2: Application Portfolio Dashboard
B3: Grouped by Dev Manager. All figures recalculate live from the App Inventory sheet.
B5: Total Apps | D5: Apps w/ Findings | F5: Total Findings | H5: Secrets Exposed | J5: Approaching EOL | L5: EOL <= 90 Days
B6: =COUNTIF('App Inventory'!$E$2:$E$1000,"<>") -> 0 | D6: =SUMPRODUCT(('App Inventory'!$E$2:$E$1000<>"")*((N('App Inventory'!$O$2:$O$1000)>0)+(N('App Inventory'!$P$2:$P$1000)>0)+(N('App Inventory'!$N$2:$N$1000)>0)+(N('App Inventory'!$Q$2:$Q$1000)>0)>0)) -> 0 | F6: =SUM('App Inventory'!$O$2:$O$1000)+SUM('App Inventory'!$P$2:$P$1000)+SUM('App Inventory'!$N$2:$N$1000)+SUM('App Inventory'!$Q$2:$Q$1000) -> 0 | H6: =SUM('App Inventory'!$Q$2:$Q$1000) -> 0 | J6: =COUNTIF('App Inventory'!$J$2:$J$1000,"Approaching EOL") -> 0 | L6: =COUNTIFS('App Inventory'!$L$2:$L$1000,"<=90",'App Inventory'!$L$2:$L$1000,">0") -> 0
B9: Findings and Risk by Manager
B10: Dev Manager | C10: Total Apps | D10: Apps w/ Findings | E10: MEND Critical | F10: MEND Medium | G10: CodeQL Errors | H10: CodeQL Warnings | I10: Secret Scanning | J10: Approaching EOL | K10: EOL <= 90d | L10: Sonar Failing
C11: =IF($B11="","",COUNTIF('App Inventory'!$E$2:$E$1000,$B11)) | D11: =IF($B11="","",SUMPRODUCT(('App Inventory'!$E$2:$E$1000=$B11)*((N('App Inventory'!$O$2:$O$1000)>0)+(N('App Inventory'!$P$2:$P$1000)>0)+(N('App Inventory'!$N$2:$N$1000)>0)+(N('App Inventory'!$Q$2:$Q$1000)>0)>0))) | E11: =IF($B11="","",SUMIF('App Inventory'!$E$2:$E$1000,$B11,'App Inventory'!$O$2:$O$1000)) | F11: =IF($B11="","",SUMIF('App Inventory'!$E$2:$E$1000,$B11,'App Inventory'!$P$2:$P$1000)) | G11: =IF($B11="","",SUMIF('App Inventory'!$E$2:$E$1000,$B11,'App Inventory'!$N$2:$N$1000)) | H11: =IF($B11="","",SUMIF('App Inventory'!$E$2:$E$1000,$B11,'App Inventory'!$M$2:$M$1000)) | I11: =IF($B11="","",SUMIF('App Inventory'!$E$2:$E$1000,$B11,'App Inventory'!$Q$2:$Q$1000)) | J11: =IF($B11="","",COUNTIFS('App Inventory'!$E$2:$E$1000,$B11,'App Inventory'!$J$2:$J$1000,"Approaching EOL")) | K11: =IF($B11="","",COUNTIFS('App Inventory'!$E$2:$E$1000,$B11,'App Inventory'!$L$2:$L$1000,"<=90",'App Inventory'!$L$2:$L$1000,">0")) | L11: =IF($B11="","",COUNTIFS('App Inventory'!$E$2:$E$1000,$B11,'App Inventory'!$H$2:$H$1000,"<>Passed",'App Inventory'!$H$2:$H$1000,"<>"))
C12: =IF($B12="","",COUNTIF('App Inventory'!$E$2:$E$1000,$B12)) | D12: =IF($B12="","",SUMPRODUCT(('App Inventory'!$E$2:$E$1000=$B12)*((N('App Inventory'!$O$2:$O$1000)>0)+(N('App Inventory'!$P$2:$P$1000)>0)+(N('App Inventory'!$N$2:$N$1000)>0)+(N('App Inventory'!$Q$2:$Q$1000)>0)>0))) | E12: =IF($B12="","",SUMIF('App Inventory'!$E$2:$E$1000,$B12,'App Inventory'!$O$2:$O$1000)) | F12: =IF($B12="","",SUMIF('App Inventory'!$E$2:$E$1000,$B12,'App Inventory'!$P$2:$P$1000)) | G12: =IF($B12="","",SUMIF('App Inventory'!$E$2:$E$1000,$B12,'App Inventory'!$N$2:$N$1000)) | H12: =IF($B12="","",SUMIF('App Inventory'!$E$2:$E$1000,$B12,'App Inventory'!$M$2:$M$1000)) | I12: =IF($B12="","",SUMIF('App Inventory'!$E$2:$E$1000,$B12,'App Inventory'!$Q$2:$Q$1000)) | J12: =IF($B12="","",COUNTIFS('App Inventory'!$E$2:$E$1000,$B12,'App Inventory'!$J$2:$J$1000,"Approaching EOL")) | K12: =IF($B12="","",COUNTIFS('App Inventory'!$E$2:$E$1000,$B12,'App Inventory'!$L$2:$L$1000,"<=90",'App Inventory'!$L$2:$L$1000,">0")) | L12: =IF($B12="","",COUNTIFS('App Inventory'!$E$2:$E$1000,$B12,'App Inventory'!$H$2:$H$1000,"<>Passed",'App Inventory'!$H$2:$H$1000,"<>"))
C13: =IF($B13="","",COUNTIF('App Inventory'!$E$2:$E$1000,$B13)) | D13: =IF($B13="","",SUMPRODUCT(('App Inventory'!$E$2:$E$1000=$B13)*((N('App Inventory'!$O$2:$O$1000)>0)+(N('App Inventory'!$P$2:$P$1000)>0)+(N('App Inventory'!$N$2:$N$1000)>0)+(N('App Inventory'!$Q$2:$Q$1000)>0)>0))) | E13: =IF($B13="","",SUMIF('App Inventory'!$E$2:$E$1000,$B13,'App Inventory'!$O$2:$O$1000)) | F13: =IF($B13="","",SUMIF('App Inventory'!$E$2:$E$1000,$B13,'App Inventory'!$P$2:$P$1000)) | G13: =IF($B13="","",SUMIF('App Inventory'!$E$2:$E$1000,$B13,'App Inventory'!$N$2:$N$1000)) | H13: =IF($B13="","",SUMIF('App Inventory'!$E$2:$E$1000,$B13,'App Inventory'!$M$2:$M$1000)) | I13: =IF($B13="","",SUMIF('App Inventory'!$E$2:$E$1000,$B13,'App Inventory'!$Q$2:$Q$1000)) | J13: =IF($B13="","",COUNTIFS('App Inventory'!$E$2:$E$1000,$B13,'App Inventory'!$J$2:$J$1000,"Approaching EOL")) | K13: =IF($B13="","",COUNTIFS('App Inventory'!$E$2:$E$1000,$B13,'App Inventory'!$L$2:$L$1000,"<=90",'App Inventory'!$L$2:$L$1000,">0")) | L13: =IF($B13="","",COUNTIFS('App Inventory'!$E$2:$E$1000,$B13,'App Inventory'!$H$2:$H$1000,"<>Passed",'App Inventory'!$H$2:$H$1000,"<>"))
C14: =IF($B14="","",COUNTIF('App Inventory'!$E$2:$E$1000,$B14)) | D14: =IF($B14="","",SUMPRODUCT(('App Inventory'!$E$2:$E$1000=$B14)*((N('App Inventory'!$O$2:$O$1000)>0)+(N('App Inventory'!$P$2:$P$1000)>0)+(N('App Inventory'!$N$2:$N$1000)>0)+(N('App Inventory'!$Q$2:$Q$1000)>0)>0))) | E14: =IF($B14="","",SUMIF('App Inventory'!$E$2:$E$1000,$B14,'App Inventory'!$O$2:$O$1000)) | F14: =IF($B14="","",SUMIF('App Inventory'!$E$2:$E$1000,$B14,'App Inventory'!$P$2:$P$1000)) | G14: =IF($B14="","",SUMIF('App Inventory'!$E$2:$E$1000,$B14,'App Inventory'!$N$2:$N$1000)) | H14: =IF($B14="","",SUMIF('App Inventory'!$E$2:$E$1000,$B14,'App Inventory'!$M$2:$M$1000)) | I14: =IF($B14="","",SUMIF('App Inventory'!$E$2:$E$1000,$B14,'App Inventory'!$Q$2:$Q$1000)) | J14: =IF($B14="","",COUNTIFS('App Inventory'!$E$2:$E$1000,$B14,'App Inventory'!$J$2:$J$1000,"Approaching EOL")) | K14: =IF($B14="","",COUNTIFS('App Inventory'!$E$2:$E$1000,$B14,'App Inventory'!$L$2:$L$1000,"<=90",'App Inventory'!$L$2:$L$1000,">0")) | L14: =IF($B14="","",COUNTIFS('App Inventory'!$E$2:$E$1000,$B14,'App Inventory'!$H$2:$H$1000,"<>Passed",'App Inventory'!$H$2:$H$1000,"<>"))
C15: =IF($B15="","",COUNTIF('App Inventory'!$E$2:$E$1000,$B15)) | D15: =IF($B15="","",SUMPRODUCT(('App Inventory'!$E$2:$E$1000=$B15)*((N('App Inventory'!$O$2:$O$1000)>0)+(N('App Inventory'!$P$2:$P$1000)>0)+(N('App Inventory'!$N$2:$N$1000)>0)+(N('App Inventory'!$Q$2:$Q$1000)>0)>0))) | E15: =IF($B15="","",SUMIF('App Inventory'!$E$2:$E$1000,$B15,'App Inventory'!$O$2:$O$1000)) | F15: =IF($B15="","",SUMIF('App Inventory'!$E$2:$E$1000,$B15,'App Inventory'!$P$2:$P$1000)) | G15: =IF($B15="","",SUMIF('App Inventory'!$E$2:$E$1000,$B15,'App Inventory'!$N$2:$N$1000)) | H15: =IF($B15="","",SUMIF('App Inventory'!$E$2:$E$1000,$B15,'App Inventory'!$M$2:$M$1000)) | I15: =IF($B15="","",SUMIF('App Inventory'!$E$2:$E$1000,$B15,'App Inventory'!$Q$2:$Q$1000)) | J15: =IF($B15="","",COUNTIFS('App Inventory'!$E$2:$E$1000,$B15,'App Inventory'!$J$2:$J$1000,"Approaching EOL")) | K15: =IF($B15="","",COUNTIFS('App Inventory'!$E$2:$E$1000,$B15,'App Inventory'!$L$2:$L$1000,"<=90",'App Inventory'!$L$2:$L$1000,">0")) | L15: =IF($B15="","",COUNTIFS('App Inventory'!$E$2:$E$1000,$B15,'App Inventory'!$H$2:$H$1000,"<>Passed",'App Inventory'!$H$2:$H$1000,"<>"))
C16: =IF($B16="","",COUNTIF('App Inventory'!$E$2:$E$1000,$B16)) | D16: =IF($B16="","",SUMPRODUCT(('App Inventory'!$E$2:$E$1000=$B16)*((N('App Inventory'!$O$2:$O$1000)>0)+(N('App Inventory'!$P$2:$P$1000)>0)+(N('App Inventory'!$N$2:$N$1000)>0)+(N('App Inventory'!$Q$2:$Q$1000)>0)>0))) | E16: =IF($B16="","",SUMIF('App Inventory'!$E$2:$E$1000,$B16,'App Inventory'!$O$2:$O$1000)) | F16: =IF($B16="","",SUMIF('App Inventory'!$E$2:$E$1000,$B16,'App Inventory'!$P$2:$P$1000)) | G16: =IF($B16="","",SUMIF('App Inventory'!$E$2:$E$1000,$B16,'App Inventory'!$N$2:$N$1000)) | H16: =IF($B16="","",SUMIF('App Inventory'!$E$2:$E$1000,$B16,'App Inventory'!$M$2:$M$1000)) | I16: =IF($B16="","",SUMIF('App Inventory'!$E$2:$E$1000,$B16,'App Inventory'!$Q$2:$Q$1000)) | J16: =IF($B16="","",COUNTIFS('App Inventory'!$E$2:$E$1000,$B16,'App Inventory'!$J$2:$J$1000,"Approaching EOL")) | K16: =IF($B16="","",COUNTIFS('App Inventory'!$E$2:$E$1000,$B16,'App Inventory'!$L$2:$L$1000,"<=90",'App Inventory'!$L$2:$L$1000,">0")) | L16: =IF($B16="","",COUNTIFS('App Inventory'!$E$2:$E$1000,$B16,'App Inventory'!$H$2:$H$1000,"<>Passed",'App Inventory'!$H$2:$H$1000,"<>"))
C17: =IF($B17="","",COUNTIF('App Inventory'!$E$2:$E$1000,$B17)) | D17: =IF($B17="","",SUMPRODUCT(('App Inventory'!$E$2:$E$1000=$B17)*((N('App Inventory'!$O$2:$O$1000)>0)+(N('App Inventory'!$P$2:$P$1000)>0)+(N('App Inventory'!$N$2:$N$1000)>0)+(N('App Inventory'!$Q$2:$Q$1000)>0)>0))) | E17: =IF($B17="","",SUMIF('App Inventory'!$E$2:$E$1000,$B17,'App Inventory'!$O$2:$O$1000)) | F17: =IF($B17="","",SUMIF('App Inventory'!$E$2:$E$1000,$B17,'App Inventory'!$P$2:$P$1000)) | G17: =IF($B17="","",SUMIF('App Inventory'!$E$2:$E$1000,$B17,'App Inventory'!$N$2:$N$1000)) | H17: =IF($B17="","",SUMIF('App Inventory'!$E$2:$E$1000,$B17,'App Inventory'!$M$2:$M$1000)) | I17: =IF($B17="","",SUMIF('App Inventory'!$E$2:$E$1000,$B17,'App Inventory'!$Q$2:$Q$1000)) | J17: =IF($B17="","",COUNTIFS('App Inventory'!$E$2:$E$1000,$B17,'App Inventory'!$J$2:$J$1000,"Approaching EOL")) | K17: =IF($B17="","",COUNTIFS('App Inventory'!$E$2:$E$1000,$B17,'App Inventory'!$L$2:$L$1000,"<=90",'App Inventory'!$L$2:$L$1000,">0")) | L17: =IF($B17="","",COUNTIFS('App Inventory'!$E$2:$E$1000,$B17,'App Inventory'!$H$2:$H$1000,"<>Passed",'App Inventory'!$H$2:$H$1000,"<>"))
C18: =IF($B18="","",COUNTIF('App Inventory'!$E$2:$E$1000,$B18)) | D18: =IF($B18="","",SUMPRODUCT(('App Inventory'!$E$2:$E$1000=$B18)*((N('App Inventory'!$O$2:$O$1000)>0)+(N('App Inventory'!$P$2:$P$1000)>0)+(N('App Inventory'!$N$2:$N$1000)>0)+(N('App Inventory'!$Q$2:$Q$1000)>0)>0))) | E18: =IF($B18="","",SUMIF('App Inventory'!$E$2:$E$1000,$B18,'App Inventory'!$O$2:$O$1000)) | F18: =IF($B18="","",SUMIF('App Inventory'!$E$2:$E$1000,$B18,'App Inventory'!$P$2:$P$1000)) | G18: =IF($B18="","",SUMIF('App Inventory'!$E$2:$E$1000,$B18,'App Inventory'!$N$2:$N$1000)) | H18: =IF($B18="","",SUMIF('App Inventory'!$E$2:$E$1000,$B18,'App Inventory'!$M$2:$M$1000)) | I18: =IF($B18="","",SUMIF('App Inventory'!$E$2:$E$1000,$B18,'App Inventory'!$Q$2:$Q$1000)) | J18: =IF($B18="","",COUNTIFS('App Inventory'!$E$2:$E$1000,$B18,'App Inventory'!$J$2:$J$1000,"Approaching EOL")) | K18: =IF($B18="","",COUNTIFS('App Inventory'!$E$2:$E$1000,$B18,'App Inventory'!$L$2:$L$1000,"<=90",'App Inventory'!$L$2:$L$1000,">0")) | L18: =IF($B18="","",COUNTIFS('App Inventory'!$E$2:$E$1000,$B18,'App Inventory'!$H$2:$H$1000,"<>Passed",'App Inventory'!$H$2:$H$1000,"<>"))
C19: =IF($B19="","",COUNTIF('App Inventory'!$E$2:$E$1000,$B19)) | D19: =IF($B19="","",SUMPRODUCT(('App Inventory'!$E$2:$E$1000=$B19)*((N('App Inventory'!$O$2:$O$1000)>0)+(N('App Inventory'!$P$2:$P$1000)>0)+(N('App Inventory'!$N$2:$N$1000)>0)+(N('App Inventory'!$Q$2:$Q$1000)>0)>0))) | E19: =IF($B19="","",SUMIF('App Inventory'!$E$2:$E$1000,$B19,'App Inventory'!$O$2:$O$1000)) | F19: =IF($B19="","",SUMIF('App Inventory'!$E$2:$E$1000,$B19,'App Inventory'!$P$2:$P$1000)) | G19: =IF($B19="","",SUMIF('App Inventory'!$E$2:$E$1000,$B19,'App Inventory'!$N$2:$N$1000)) | H19: =IF($B19="","",SUMIF('App Inventory'!$E$2:$E$1000,$B19,'App Inventory'!$M$2:$M$1000)) | I19: =IF($B19="","",SUMIF('App Inventory'!$E$2:$E$1000,$B19,'App Inventory'!$Q$2:$Q$1000)) | J19: =IF($B19="","",COUNTIFS('App Inventory'!$E$2:$E$1000,$B19,'App Inventory'!$J$2:$J$1000,"Approaching EOL")) | K19: =IF($B19="","",COUNTIFS('App Inventory'!$E$2:$E$1000,$B19,'App Inventory'!$L$2:$L$1000,"<=90",'App Inventory'!$L$2:$L$1000,">0")) | L19: =IF($B19="","",COUNTIFS('App Inventory'!$E$2:$E$1000,$B19,'App Inventory'!$H$2:$H$1000,"<>Passed",'App Inventory'!$H$2:$H$1000,"<>"))
C20: =IF($B20="","",COUNTIF('App Inventory'!$E$2:$E$1000,$B20)) | D20: =IF($B20="","",SUMPRODUCT(('App Inventory'!$E$2:$E$1000=$B20)*((N('App Inventory'!$O$2:$O$1000)>0)+(N('App Inventory'!$P$2:$P$1000)>0)+(N('App Inventory'!$N$2:$N$1000)>0)+(N('App Inventory'!$Q$2:$Q$1000)>0)>0))) | E20: =IF($B20="","",SUMIF('App Inventory'!$E$2:$E$1000,$B20,'App Inventory'!$O$2:$O$1000)) | F20: =IF($B20="","",SUMIF('App Inventory'!$E$2:$E$1000,$B20,'App Inventory'!$P$2:$P$1000)) | G20: =IF($B20="","",SUMIF('App Inventory'!$E$2:$E$1000,$B20,'App Inventory'!$N$2:$N$1000)) | H20: =IF($B20="","",SUMIF('App Inventory'!$E$2:$E$1000,$B20,'App Inventory'!$M$2:$M$1000)) | I20: =IF($B20="","",SUMIF('App Inventory'!$E$2:$E$1000,$B20,'App Inventory'!$Q$2:$Q$1000)) | J20: =IF($B20="","",COUNTIFS('App Inventory'!$E$2:$E$1000,$B20,'App Inventory'!$J$2:$J$1000,"Approaching EOL")) | K20: =IF($B20="","",COUNTIFS('App Inventory'!$E$2:$E$1000,$B20,'App Inventory'!$L$2:$L$1000,"<=90",'App Inventory'!$L$2:$L$1000,">0")) | L20: =IF($B20="","",COUNTIFS('App Inventory'!$E$2:$E$1000,$B20,'App Inventory'!$H$2:$H$1000,"<>Passed",'App Inventory'!$H$2:$H$1000,"<>"))
B21: TOTAL | C21: =SUM(C11:C20) -> 0 | D21: =SUM(D11:D20) -> 0 | E21: =SUM(E11:E20) -> 0 | F21: =SUM(F11:F20) -> 0 | G21: =SUM(G11:G20) -> 0 | H21: =SUM(H11:H20) -> 0 | I21: =SUM(I11:I20) -> 0 | J21: =SUM(J11:J20) -> 0 | ... L21: =SUM(L11:L20) -> 0
B24: Apps by Manager and App Stage
B25: Dev Manager | C25: Production | D25: Acquisition/Development | E25: Concept | F25: Total
B26: =IF($B11="","",$B11) | C26: =IF($B11="","",COUNTIFS('App Inventory'!$E$2:$E$1000,$B11,'App Inventory'!$D$2:$D$1000,"Production")) | D26: =IF($B11="","",COUNTIFS('App Inventory'!$E$2:$E$1000,$B11,'App Inventory'!$D$2:$D$1000,"Acquisition/Development")) | E26: =IF($B11="","",COUNTIFS('App Inventory'!$E$2:$E$1000,$B11,'App Inventory'!$D$2:$D$1000,"Concept")) | F26: =IF($B11="","",SUM(C26:E26))
B27: =IF($B12="","",$B12) | C27: =IF($B12="","",COUNTIFS('App Inventory'!$E$2:$E$1000,$B12,'App Inventory'!$D$2:$D$1000,"Production")) | D27: =IF($B12="","",COUNTIFS('App Inventory'!$E$2:$E$1000,$B12,'App Inventory'!$D$2:$D$1000,"Acquisition/Development")) | E27: =IF($B12="","",COUNTIFS('App Inventory'!$E$2:$E$1000,$B12,'App Inventory'!$D$2:$D$1000,"Concept")) | F27: =IF($B12="","",SUM(C27:E27))
B28: =IF($B13="","",$B13) | C28: =IF($B13="","",COUNTIFS('App Inventory'!$E$2:$E$1000,$B13,'App Inventory'!$D$2:$D$1000,"Production")) | D28: =IF($B13="","",COUNTIFS('App Inventory'!$E$2:$E$1000,$B13,'App Inventory'!$D$2:$D$1000,"Acquisition/Development")) | E28: =IF($B13="","",COUNTIFS('App Inventory'!$E$2:$E$1000,$B13,'App Inventory'!$D$2:$D$1000,"Concept")) | F28: =IF($B13="","",SUM(C28:E28))
B29: =IF($B14="","",$B14) | C29: =IF($B14="","",COUNTIFS('App Inventory'!$E$2:$E$1000,$B14,'App Inventory'!$D$2:$D$1000,"Production")) | D29: =IF($B14="","",COUNTIFS('App Inventory'!$E$2:$E$1000,$B14,'App Inventory'!$D$2:$D$1000,"Acquisition/Development")) | E29: =IF($B14="","",COUNTIFS('App Inventory'!$E$2:$E$1000,$B14,'App Inventory'!$D$2:$D$1000,"Concept")) | F29: =IF($B14="","",SUM(C29:E29))
B30: =IF($B15="","",$B15) | C30: =IF($B15="","",COUNTIFS('App Inventory'!$E$2:$E$1000,$B15,'App Inventory'!$D$2:$D$1000,"Production")) | D30: =IF($B15="","",COUNTIFS('App Inventory'!$E$2:$E$1000,$B15,'App Inventory'!$D$2:$D$1000,"Acquisition/Development")) | E30: =IF($B15="","",COUNTIFS('App Inventory'!$E$2:$E$1000,$B15,'App Inventory'!$D$2:$D$1000,"Concept")) | F30: =IF($B15="","",SUM(C30:E30))
B31: =IF($B16="","",$B16) | C31: =IF($B16="","",COUNTIFS('App Inventory'!$E$2:$E$1000,$B16,'App Inventory'!$D$2:$D$1000,"Production")) | D31: =IF($B16="","",COUNTIFS('App Inventory'!$E$2:$E$1000,$B16,'App Inventory'!$D$2:$D$1000,"Acquisition/Development")) | E31: =IF($B16="","",COUNTIFS('App Inventory'!$E$2:$E$1000,$B16,'App Inventory'!$D$2:$D$1000,"Concept")) | F31: =IF($B16="","",SUM(C31:E31))
B32: =IF($B17="","",$B17) | C32: =IF($B17="","",COUNTIFS('App Inventory'!$E$2:$E$1000,$B17,'App Inventory'!$D$2:$D$1000,"Production")) | D32: =IF($B17="","",COUNTIFS('App Inventory'!$E$2:$E$1000,$B17,'App Inventory'!$D$2:$D$1000,"Acquisition/Development")) | E32: =IF($B17="","",COUNTIFS('App Inventory'!$E$2:$E$1000,$B17,'App Inventory'!$D$2:$D$1000,"Concept")) | F32: =IF($B17="","",SUM(C32:E32))
B33: =IF($B18="","",$B18) | C33: =IF($B18="","",COUNTIFS('App Inventory'!$E$2:$E$1000,$B18,'App Inventory'!$D$2:$D$1000,"Production")) | D33: =IF($B18="","",COUNTIFS('App Inventory'!$E$2:$E$1000,$B18,'App Inventory'!$D$2:$D$1000,"Acquisition/Development")) | E33: =IF($B18="","",COUNTIFS('App Inventory'!$E$2:$E$1000,$B18,'App Inventory'!$D$2:$D$1000,"Concept")) | F33: =IF($B18="","",SUM(C33:E33))
B34: =IF($B19="","",$B19) | C34: =IF($B19="","",COUNTIFS('App Inventory'!$E$2:$E$1000,$B19,'App Inventory'!$D$2:$D$1000,"Production")) | D34: =IF($B19="","",COUNTIFS('App Inventory'!$E$2:$E$1000,$B19,'App Inventory'!$D$2:$D$1000,"Acquisition/Development")) | E34: =IF($B19="","",COUNTIFS('App Inventory'!$E$2:$E$1000,$B19,'App Inventory'!$D$2:$D$1000,"Concept")) | F34: =IF($B19="","",SUM(C34:E34))
B35: =IF($B20="","",$B20) | C35: =IF($B20="","",COUNTIFS('App Inventory'!$E$2:$E$1000,$B20,'App Inventory'!$D$2:$D$1000,"Production")) | D35: =IF($B20="","",COUNTIFS('App Inventory'!$E$2:$E$1000,$B20,'App Inventory'!$D$2:$D$1000,"Acquisition/Development")) | E35: =IF($B20="","",COUNTIFS('App Inventory'!$E$2:$E$1000,$B20,'App Inventory'!$D$2:$D$1000,"Concept")) | F35: =IF($B20="","",SUM(C35:E35))
B38: Apps by Manager and TLM Status
B39: Dev Manager | C39: Current | D39: Approaching EOL | E39: Total
B40: =IF($B11="","",$B11) | C40: =IF($B11="","",COUNTIFS('App Inventory'!$E$2:$E$1000,$B11,'App Inventory'!$J$2:$J$1000,"Current")) | D40: =IF($B11="","",COUNTIFS('App Inventory'!$E$2:$E$1000,$B11,'App Inventory'!$J$2:$J$1000,"Approaching EOL")) | E40: =IF($B11="","",SUM(C40:D40))
B41: =IF($B12="","",$B12) | C41: =IF($B12="","",COUNTIFS('App Inventory'!$E$2:$E$1000,$B12,'App Inventory'!$J$2:$J$1000,"Current")) | D41: =IF($B12="","",COUNTIFS('App Inventory'!$E$2:$E$1000,$B12,'App Inventory'!$J$2:$J$1000,"Approaching EOL")) | E41: =IF($B12="","",SUM(C41:D41))
B42: =IF($B13="","",$B13) | C42: =IF($B13="","",COUNTIFS('App Inventory'!$E$2:$E$1000,$B13,'App Inventory'!$J$2:$J$1000,"Current")) | D42: =IF($B13="","",COUNTIFS('App Inventory'!$E$2:$E$1000,$B13,'App Inventory'!$J$2:$J$1000,"Approaching EOL")) | E42: =IF($B13="","",SUM(C42:D42))
B43: =IF($B14="","",$B14) | C43: =IF($B14="","",COUNTIFS('App Inventory'!$E$2:$E$1000,$B14,'App Inventory'!$J$2:$J$1000,"Current")) | D43: =IF($B14="","",COUNTIFS('App Inventory'!$E$2:$E$1000,$B14,'App Inventory'!$J$2:$J$1000,"Approaching EOL")) | E43: =IF($B14="","",SUM(C43:D43))
B44: =IF($B15="","",$B15) | C44: =IF($B15="","",COUNTIFS('App Inventory'!$E$2:$E$1000,$B15,'App Inventory'!$J$2:$J$1000,"Current")) | D44: =IF($B15="","",COUNTIFS('App Inventory'!$E$2:$E$1000,$B15,'App Inventory'!$J$2:$J$1000,"Approaching EOL")) | E44: =IF($B15="","",SUM(C44:D44))
B45: =IF($B16="","",$B16) | C45: =IF($B16="","",COUNTIFS('App Inventory'!$E$2:$E$1000,$B16,'App Inventory'!$J$2:$J$1000,"Current")) | D45: =IF($B16="","",COUNTIFS('App Inventory'!$E$2:$E$1000,$B16,'App Inventory'!$J$2:$J$1000,"Approaching EOL")) | E45: =IF($B16="","",SUM(C45:D45))
B46: =IF($B17="","",$B17) | C46: =IF($B17="","",COUNTIFS('App Inventory'!$E$2:$E$1000,$B17,'App Inventory'!$J$2:$J$1000,"Current")) | D46: =IF($B17="","",COUNTIFS('App Inventory'!$E$2:$E$1000,$B17,'App Inventory'!$J$2:$J$1000,"Approaching EOL")) | E46: =IF($B17="","",SUM(C46:D46))
B47: =IF($B18="","",$B18) | C47: =IF($B18="","",COUNTIFS('App Inventory'!$E$2:$E$1000,$B18,'App Inventory'!$J$2:$J$1000,"Current")) | D47: =IF($B18="","",COUNTIFS('App Inventory'!$E$2:$E$1000,$B18,'App Inventory'!$J$2:$J$1000,"Approaching EOL")) | E47: =IF($B18="","",SUM(C47:D47))
B48: =IF($B19="","",$B19) | C48: =IF($B19="","",COUNTIFS('App Inventory'!$E$2:$E$1000,$B19,'App Inventory'!$J$2:$J$1000,"Current")) | D48: =IF($B19="","",COUNTIFS('App Inventory'!$E$2:$E$1000,$B19,'App Inventory'!$J$2:$J$1000,"Approaching EOL")) | E48: =IF($B19="","",SUM(C48:D48))
...
